<<<<<<< HEAD
2023-12-29 20:14:25,681 - ERROR - An exception occurred: get artist_ids, album_ids, track_ids lists
2023-12-29 20:14:25,681 - ERROR - An exception occurred: Load data into DB
2023-12-29 20:14:53,609 - ERROR - An exception occurred: get artist_ids, album_ids, track_ids lists
2023-12-29 20:14:53,609 - ERROR - An exception occurred: Load data into DB
2023-12-29 20:15:23,292 - INFO - Code executed successfully!
2023-12-29 20:34:52,922 - INFO - Code executed successfully!
2023-12-29 20:44:07,583 - INFO - Code executed successfully!
2023-12-29 20:48:03,842 - INFO - Code executed successfully!
2023-12-29 20:55:35,405 - INFO - Code executed successfully!
2023-12-29 20:56:15,777 - INFO - Code executed successfully!
<<<<<<< HEAD
2023-12-30 00:21:30,670 - ERROR - An exception occurred: failed to get Spotify ids (Attempt 1/3)
2023-12-30 00:21:50,902 - ERROR - An exception occurred: failed to get Spotify ids (Attempt 2/3)
2023-12-30 00:22:11,452 - INFO - Code executed successfully!
=======
2023-12-29 22:09:17,545 - ERROR - An exception occurred: get artist_ids, album_ids, track_ids lists
2023-12-29 22:09:17,545 - ERROR - An exception occurred: Load data into DB
2023-12-29 22:33:44,443 - ERROR - An exception occurred: failed to get Spotify ids (Attempt 1/5)
2023-12-29 22:33:49,449 - ERROR - An exception occurred: failed to get Spotify ids (Attempt 2/5)
2023-12-29 22:33:54,450 - ERROR - An exception occurred: failed to get Spotify ids (Attempt 3/5)
2023-12-29 22:33:59,456 - ERROR - An exception occurred: failed to get Spotify ids (Attempt 4/5)
2023-12-29 22:34:04,461 - ERROR - An exception occurred: failed to get Spotify ids (Attempt 5/5)
2023-12-29 22:34:09,467 - ERROR - Failed to get Spotify ids  after 5 attempts.
2023-12-29 22:34:09,467 - ERROR - An exception occurred: Load data into DB
=======

>>>>>>> da35b3cc898d20551a3b7467ca3c9981d8d0d53a
2023-12-30 23:13:22,863 - ERROR - An exception occurred: failed to get Spotify ids (Attempt 1/2)
Traceback (most recent call last):
  File "/opt/hostedtoolcache/Python/3.9.18/x64/lib/python3.9/site-packages/sqlalchemy/engine/base.py", line 145, in __init__
    self._dbapi_connection = engine.raw_connection()
  File "/opt/hostedtoolcache/Python/3.9.18/x64/lib/python3.9/site-packages/sqlalchemy/engine/base.py", line 3293, in raw_connection
    return self.pool.connect()
  File "/opt/hostedtoolcache/Python/3.9.18/x64/lib/python3.9/site-packages/sqlalchemy/pool/base.py", line 452, in connect
    return _ConnectionFairy._checkout(self)
  File "/opt/hostedtoolcache/Python/3.9.18/x64/lib/python3.9/site-packages/sqlalchemy/pool/base.py", line 1269, in _checkout
    fairy = _ConnectionRecord.checkout(pool)
  File "/opt/hostedtoolcache/Python/3.9.18/x64/lib/python3.9/site-packages/sqlalchemy/pool/base.py", line 716, in checkout
    rec = pool._do_get()
  File "/opt/hostedtoolcache/Python/3.9.18/x64/lib/python3.9/site-packages/sqlalchemy/pool/impl.py", line 170, in _do_get
    self._dec_overflow()
  File "/opt/hostedtoolcache/Python/3.9.18/x64/lib/python3.9/site-packages/sqlalchemy/util/langhelpers.py", line 146, in __exit__
    raise exc_value.with_traceback(exc_tb)
  File "/opt/hostedtoolcache/Python/3.9.18/x64/lib/python3.9/site-packages/sqlalchemy/pool/impl.py", line 167, in _do_get
    return self._create_connection()
  File "/opt/hostedtoolcache/Python/3.9.18/x64/lib/python3.9/site-packages/sqlalchemy/pool/base.py", line 393, in _create_connection
    return _ConnectionRecord(self)
  File "/opt/hostedtoolcache/Python/3.9.18/x64/lib/python3.9/site-packages/sqlalchemy/pool/base.py", line 678, in __init__
    self.__connect()
  File "/opt/hostedtoolcache/Python/3.9.18/x64/lib/python3.9/site-packages/sqlalchemy/pool/base.py", line 903, in __connect
    pool.logger.debug("Error on connect(): %s", e)
  File "/opt/hostedtoolcache/Python/3.9.18/x64/lib/python3.9/site-packages/sqlalchemy/util/langhelpers.py", line 146, in __exit__
    raise exc_value.with_traceback(exc_tb)
  File "/opt/hostedtoolcache/Python/3.9.18/x64/lib/python3.9/site-packages/sqlalchemy/pool/base.py", line 898, in __connect
    self.dbapi_connection = connection = pool._invoke_creator(self)
  File "/opt/hostedtoolcache/Python/3.9.18/x64/lib/python3.9/site-packages/sqlalchemy/engine/create.py", line 645, in connect
    return dialect.connect(*cargs, **cparams)
  File "/opt/hostedtoolcache/Python/3.9.18/x64/lib/python3.9/site-packages/sqlalchemy/engine/default.py", line 616, in connect
    return self.loaded_dbapi.connect(*cargs, **cparams)
pyodbc.Error: ('01000', "[01000] [unixODBC][Driver Manager]Can't open lib 'SQL Server Native Client 10.0' : file not found (0) (SQLDriverConnect)")

The above exception was the direct cause of the following exception:

Traceback (most recent call last):
  File "/home/runner/work/spotify_daily_data_updates/spotify_daily_data_updates/main.py", line 69, in get_spotify_ids
    artist_ids = pd.read_sql(query, engine)['artist_id'].to_list()
  File "/opt/hostedtoolcache/Python/3.9.18/x64/lib/python3.9/site-packages/pandas/io/sql.py", line 652, in read_sql
    with pandasSQL_builder(con) as pandas_sql:
  File "/opt/hostedtoolcache/Python/3.9.18/x64/lib/python3.9/site-packages/pandas/io/sql.py", line 851, in pandasSQL_builder
    return SQLDatabase(con, schema, need_transaction)
  File "/opt/hostedtoolcache/Python/3.9.18/x64/lib/python3.9/site-packages/pandas/io/sql.py", line 1576, in __init__
    con = self.exit_stack.enter_context(con.connect())
  File "/opt/hostedtoolcache/Python/3.9.18/x64/lib/python3.9/site-packages/sqlalchemy/engine/base.py", line 3269, in connect
    return self._connection_cls(self)
  File "/opt/hostedtoolcache/Python/3.9.18/x64/lib/python3.9/site-packages/sqlalchemy/engine/base.py", line 147, in __init__
    Connection._handle_dbapi_exception_noconnection(
  File "/opt/hostedtoolcache/Python/3.9.18/x64/lib/python3.9/site-packages/sqlalchemy/engine/base.py", line 2431, in _handle_dbapi_exception_noconnection
    raise sqlalchemy_exception.with_traceback(exc_info[2]) from e
  File "/opt/hostedtoolcache/Python/3.9.18/x64/lib/python3.9/site-packages/sqlalchemy/engine/base.py", line 145, in __init__
    self._dbapi_connection = engine.raw_connection()
  File "/opt/hostedtoolcache/Python/3.9.18/x64/lib/python3.9/site-packages/sqlalchemy/engine/base.py", line 3293, in raw_connection
    return self.pool.connect()
  File "/opt/hostedtoolcache/Python/3.9.18/x64/lib/python3.9/site-packages/sqlalchemy/pool/base.py", line 452, in connect
    return _ConnectionFairy._checkout(self)
  File "/opt/hostedtoolcache/Python/3.9.18/x64/lib/python3.9/site-packages/sqlalchemy/pool/base.py", line 1269, in _checkout
    fairy = _ConnectionRecord.checkout(pool)
  File "/opt/hostedtoolcache/Python/3.9.18/x64/lib/python3.9/site-packages/sqlalchemy/pool/base.py", line 716, in checkout
    rec = pool._do_get()
  File "/opt/hostedtoolcache/Python/3.9.18/x64/lib/python3.9/site-packages/sqlalchemy/pool/impl.py", line 170, in _do_get
    self._dec_overflow()
  File "/opt/hostedtoolcache/Python/3.9.18/x64/lib/python3.9/site-packages/sqlalchemy/util/langhelpers.py", line 146, in __exit__
    raise exc_value.with_traceback(exc_tb)
  File "/opt/hostedtoolcache/Python/3.9.18/x64/lib/python3.9/site-packages/sqlalchemy/pool/impl.py", line 167, in _do_get
    return self._create_connection()
  File "/opt/hostedtoolcache/Python/3.9.18/x64/lib/python3.9/site-packages/sqlalchemy/pool/base.py", line 393, in _create_connection
    return _ConnectionRecord(self)
  File "/opt/hostedtoolcache/Python/3.9.18/x64/lib/python3.9/site-packages/sqlalchemy/pool/base.py", line 678, in __init__
    self.__connect()
  File "/opt/hostedtoolcache/Python/3.9.18/x64/lib/python3.9/site-packages/sqlalchemy/pool/base.py", line 903, in __connect
    pool.logger.debug("Error on connect(): %s", e)
  File "/opt/hostedtoolcache/Python/3.9.18/x64/lib/python3.9/site-packages/sqlalchemy/util/langhelpers.py", line 146, in __exit__
    raise exc_value.with_traceback(exc_tb)
  File "/opt/hostedtoolcache/Python/3.9.18/x64/lib/python3.9/site-packages/sqlalchemy/pool/base.py", line 898, in __connect
    self.dbapi_connection = connection = pool._invoke_creator(self)
  File "/opt/hostedtoolcache/Python/3.9.18/x64/lib/python3.9/site-packages/sqlalchemy/engine/create.py", line 645, in connect
    return dialect.connect(*cargs, **cparams)
  File "/opt/hostedtoolcache/Python/3.9.18/x64/lib/python3.9/site-packages/sqlalchemy/engine/default.py", line 616, in connect
    return self.loaded_dbapi.connect(*cargs, **cparams)
sqlalchemy.exc.DBAPIError: (pyodbc.Error) ('01000', "[01000] [unixODBC][Driver Manager]Can't open lib 'SQL Server Native Client 10.0' : file not found (0) (SQLDriverConnect)")
(Background on this error at: https://sqlalche.me/e/20/dbapi)
2023-12-30 23:13:24,868 - ERROR - An exception occurred: failed to get Spotify ids (Attempt 2/2)
Traceback (most recent call last):
  File "/opt/hostedtoolcache/Python/3.9.18/x64/lib/python3.9/site-packages/sqlalchemy/engine/base.py", line 145, in __init__
    self._dbapi_connection = engine.raw_connection()
  File "/opt/hostedtoolcache/Python/3.9.18/x64/lib/python3.9/site-packages/sqlalchemy/engine/base.py", line 3293, in raw_connection
    return self.pool.connect()
  File "/opt/hostedtoolcache/Python/3.9.18/x64/lib/python3.9/site-packages/sqlalchemy/pool/base.py", line 452, in connect
    return _ConnectionFairy._checkout(self)
  File "/opt/hostedtoolcache/Python/3.9.18/x64/lib/python3.9/site-packages/sqlalchemy/pool/base.py", line 1269, in _checkout
    fairy = _ConnectionRecord.checkout(pool)
  File "/opt/hostedtoolcache/Python/3.9.18/x64/lib/python3.9/site-packages/sqlalchemy/pool/base.py", line 716, in checkout
    rec = pool._do_get()
  File "/opt/hostedtoolcache/Python/3.9.18/x64/lib/python3.9/site-packages/sqlalchemy/pool/impl.py", line 170, in _do_get
    self._dec_overflow()
  File "/opt/hostedtoolcache/Python/3.9.18/x64/lib/python3.9/site-packages/sqlalchemy/util/langhelpers.py", line 146, in __exit__
    raise exc_value.with_traceback(exc_tb)
  File "/opt/hostedtoolcache/Python/3.9.18/x64/lib/python3.9/site-packages/sqlalchemy/pool/impl.py", line 167, in _do_get
    return self._create_connection()
  File "/opt/hostedtoolcache/Python/3.9.18/x64/lib/python3.9/site-packages/sqlalchemy/pool/base.py", line 393, in _create_connection
    return _ConnectionRecord(self)
  File "/opt/hostedtoolcache/Python/3.9.18/x64/lib/python3.9/site-packages/sqlalchemy/pool/base.py", line 678, in __init__
    self.__connect()
  File "/opt/hostedtoolcache/Python/3.9.18/x64/lib/python3.9/site-packages/sqlalchemy/pool/base.py", line 903, in __connect
    pool.logger.debug("Error on connect(): %s", e)
  File "/opt/hostedtoolcache/Python/3.9.18/x64/lib/python3.9/site-packages/sqlalchemy/util/langhelpers.py", line 146, in __exit__
    raise exc_value.with_traceback(exc_tb)
  File "/opt/hostedtoolcache/Python/3.9.18/x64/lib/python3.9/site-packages/sqlalchemy/pool/base.py", line 898, in __connect
    self.dbapi_connection = connection = pool._invoke_creator(self)
  File "/opt/hostedtoolcache/Python/3.9.18/x64/lib/python3.9/site-packages/sqlalchemy/engine/create.py", line 645, in connect
    return dialect.connect(*cargs, **cparams)
  File "/opt/hostedtoolcache/Python/3.9.18/x64/lib/python3.9/site-packages/sqlalchemy/engine/default.py", line 616, in connect
    return self.loaded_dbapi.connect(*cargs, **cparams)
pyodbc.Error: ('01000', "[01000] [unixODBC][Driver Manager]Can't open lib 'SQL Server Native Client 10.0' : file not found (0) (SQLDriverConnect)")

The above exception was the direct cause of the following exception:

Traceback (most recent call last):
  File "/home/runner/work/spotify_daily_data_updates/spotify_daily_data_updates/main.py", line 69, in get_spotify_ids
    artist_ids = pd.read_sql(query, engine)['artist_id'].to_list()
  File "/opt/hostedtoolcache/Python/3.9.18/x64/lib/python3.9/site-packages/pandas/io/sql.py", line 652, in read_sql
    with pandasSQL_builder(con) as pandas_sql:
  File "/opt/hostedtoolcache/Python/3.9.18/x64/lib/python3.9/site-packages/pandas/io/sql.py", line 851, in pandasSQL_builder
    return SQLDatabase(con, schema, need_transaction)
  File "/opt/hostedtoolcache/Python/3.9.18/x64/lib/python3.9/site-packages/pandas/io/sql.py", line 1576, in __init__
    con = self.exit_stack.enter_context(con.connect())
  File "/opt/hostedtoolcache/Python/3.9.18/x64/lib/python3.9/site-packages/sqlalchemy/engine/base.py", line 3269, in connect
    return self._connection_cls(self)
  File "/opt/hostedtoolcache/Python/3.9.18/x64/lib/python3.9/site-packages/sqlalchemy/engine/base.py", line 147, in __init__
    Connection._handle_dbapi_exception_noconnection(
  File "/opt/hostedtoolcache/Python/3.9.18/x64/lib/python3.9/site-packages/sqlalchemy/engine/base.py", line 2431, in _handle_dbapi_exception_noconnection
    raise sqlalchemy_exception.with_traceback(exc_info[2]) from e
  File "/opt/hostedtoolcache/Python/3.9.18/x64/lib/python3.9/site-packages/sqlalchemy/engine/base.py", line 145, in __init__
    self._dbapi_connection = engine.raw_connection()
  File "/opt/hostedtoolcache/Python/3.9.18/x64/lib/python3.9/site-packages/sqlalchemy/engine/base.py", line 3293, in raw_connection
    return self.pool.connect()
  File "/opt/hostedtoolcache/Python/3.9.18/x64/lib/python3.9/site-packages/sqlalchemy/pool/base.py", line 452, in connect
    return _ConnectionFairy._checkout(self)
  File "/opt/hostedtoolcache/Python/3.9.18/x64/lib/python3.9/site-packages/sqlalchemy/pool/base.py", line 1269, in _checkout
    fairy = _ConnectionRecord.checkout(pool)
  File "/opt/hostedtoolcache/Python/3.9.18/x64/lib/python3.9/site-packages/sqlalchemy/pool/base.py", line 716, in checkout
    rec = pool._do_get()
  File "/opt/hostedtoolcache/Python/3.9.18/x64/lib/python3.9/site-packages/sqlalchemy/pool/impl.py", line 170, in _do_get
    self._dec_overflow()
  File "/opt/hostedtoolcache/Python/3.9.18/x64/lib/python3.9/site-packages/sqlalchemy/util/langhelpers.py", line 146, in __exit__
    raise exc_value.with_traceback(exc_tb)
  File "/opt/hostedtoolcache/Python/3.9.18/x64/lib/python3.9/site-packages/sqlalchemy/pool/impl.py", line 167, in _do_get
    return self._create_connection()
  File "/opt/hostedtoolcache/Python/3.9.18/x64/lib/python3.9/site-packages/sqlalchemy/pool/base.py", line 393, in _create_connection
    return _ConnectionRecord(self)
  File "/opt/hostedtoolcache/Python/3.9.18/x64/lib/python3.9/site-packages/sqlalchemy/pool/base.py", line 678, in __init__
    self.__connect()
  File "/opt/hostedtoolcache/Python/3.9.18/x64/lib/python3.9/site-packages/sqlalchemy/pool/base.py", line 903, in __connect
    pool.logger.debug("Error on connect(): %s", e)
  File "/opt/hostedtoolcache/Python/3.9.18/x64/lib/python3.9/site-packages/sqlalchemy/util/langhelpers.py", line 146, in __exit__
    raise exc_value.with_traceback(exc_tb)
  File "/opt/hostedtoolcache/Python/3.9.18/x64/lib/python3.9/site-packages/sqlalchemy/pool/base.py", line 898, in __connect
    self.dbapi_connection = connection = pool._invoke_creator(self)
  File "/opt/hostedtoolcache/Python/3.9.18/x64/lib/python3.9/site-packages/sqlalchemy/engine/create.py", line 645, in connect
    return dialect.connect(*cargs, **cparams)
  File "/opt/hostedtoolcache/Python/3.9.18/x64/lib/python3.9/site-packages/sqlalchemy/engine/default.py", line 616, in connect
    return self.loaded_dbapi.connect(*cargs, **cparams)
sqlalchemy.exc.DBAPIError: (pyodbc.Error) ('01000', "[01000] [unixODBC][Driver Manager]Can't open lib 'SQL Server Native Client 10.0' : file not found (0) (SQLDriverConnect)")
(Background on this error at: https://sqlalche.me/e/20/dbapi)
2023-12-30 23:13:26,870 - ERROR - Failed to get Spotify ids  after 2 attempts.
2023-12-30 23:13:26,871 - ERROR - An exception occurred: Load data into DB
2023-12-30 23:13:26,872 - ERROR - An exception occurred: failed to get Spotify ids (Attempt 1/2)
Traceback (most recent call last):
  File "/opt/hostedtoolcache/Python/3.9.18/x64/lib/python3.9/site-packages/sqlalchemy/engine/base.py", line 145, in __init__
    self._dbapi_connection = engine.raw_connection()
  File "/opt/hostedtoolcache/Python/3.9.18/x64/lib/python3.9/site-packages/sqlalchemy/engine/base.py", line 3293, in raw_connection
    return self.pool.connect()
  File "/opt/hostedtoolcache/Python/3.9.18/x64/lib/python3.9/site-packages/sqlalchemy/pool/base.py", line 452, in connect
    return _ConnectionFairy._checkout(self)
  File "/opt/hostedtoolcache/Python/3.9.18/x64/lib/python3.9/site-packages/sqlalchemy/pool/base.py", line 1269, in _checkout
    fairy = _ConnectionRecord.checkout(pool)
  File "/opt/hostedtoolcache/Python/3.9.18/x64/lib/python3.9/site-packages/sqlalchemy/pool/base.py", line 716, in checkout
    rec = pool._do_get()
  File "/opt/hostedtoolcache/Python/3.9.18/x64/lib/python3.9/site-packages/sqlalchemy/pool/impl.py", line 170, in _do_get
    self._dec_overflow()
  File "/opt/hostedtoolcache/Python/3.9.18/x64/lib/python3.9/site-packages/sqlalchemy/util/langhelpers.py", line 146, in __exit__
    raise exc_value.with_traceback(exc_tb)
  File "/opt/hostedtoolcache/Python/3.9.18/x64/lib/python3.9/site-packages/sqlalchemy/pool/impl.py", line 167, in _do_get
    return self._create_connection()
  File "/opt/hostedtoolcache/Python/3.9.18/x64/lib/python3.9/site-packages/sqlalchemy/pool/base.py", line 393, in _create_connection
    return _ConnectionRecord(self)
  File "/opt/hostedtoolcache/Python/3.9.18/x64/lib/python3.9/site-packages/sqlalchemy/pool/base.py", line 678, in __init__
    self.__connect()
  File "/opt/hostedtoolcache/Python/3.9.18/x64/lib/python3.9/site-packages/sqlalchemy/pool/base.py", line 903, in __connect
    pool.logger.debug("Error on connect(): %s", e)
  File "/opt/hostedtoolcache/Python/3.9.18/x64/lib/python3.9/site-packages/sqlalchemy/util/langhelpers.py", line 146, in __exit__
    raise exc_value.with_traceback(exc_tb)
  File "/opt/hostedtoolcache/Python/3.9.18/x64/lib/python3.9/site-packages/sqlalchemy/pool/base.py", line 898, in __connect
    self.dbapi_connection = connection = pool._invoke_creator(self)
  File "/opt/hostedtoolcache/Python/3.9.18/x64/lib/python3.9/site-packages/sqlalchemy/engine/create.py", line 645, in connect
    return dialect.connect(*cargs, **cparams)
  File "/opt/hostedtoolcache/Python/3.9.18/x64/lib/python3.9/site-packages/sqlalchemy/engine/default.py", line 616, in connect
    return self.loaded_dbapi.connect(*cargs, **cparams)
pyodbc.Error: ('01000', "[01000] [unixODBC][Driver Manager]Can't open lib 'ODBC Driver 18 for SQL Server' : file not found (0) (SQLDriverConnect)")

The above exception was the direct cause of the following exception:

Traceback (most recent call last):
  File "/home/runner/work/spotify_daily_data_updates/spotify_daily_data_updates/main.py", line 220, in get_spotify_ids
    artist_ids = pd.read_sql(query, engine)['artist_id'].to_list()
  File "/opt/hostedtoolcache/Python/3.9.18/x64/lib/python3.9/site-packages/pandas/io/sql.py", line 652, in read_sql
    with pandasSQL_builder(con) as pandas_sql:
  File "/opt/hostedtoolcache/Python/3.9.18/x64/lib/python3.9/site-packages/pandas/io/sql.py", line 851, in pandasSQL_builder
    return SQLDatabase(con, schema, need_transaction)
  File "/opt/hostedtoolcache/Python/3.9.18/x64/lib/python3.9/site-packages/pandas/io/sql.py", line 1576, in __init__
    con = self.exit_stack.enter_context(con.connect())
  File "/opt/hostedtoolcache/Python/3.9.18/x64/lib/python3.9/site-packages/sqlalchemy/engine/base.py", line 3269, in connect
    return self._connection_cls(self)
  File "/opt/hostedtoolcache/Python/3.9.18/x64/lib/python3.9/site-packages/sqlalchemy/engine/base.py", line 147, in __init__
    Connection._handle_dbapi_exception_noconnection(
  File "/opt/hostedtoolcache/Python/3.9.18/x64/lib/python3.9/site-packages/sqlalchemy/engine/base.py", line 2431, in _handle_dbapi_exception_noconnection
    raise sqlalchemy_exception.with_traceback(exc_info[2]) from e
  File "/opt/hostedtoolcache/Python/3.9.18/x64/lib/python3.9/site-packages/sqlalchemy/engine/base.py", line 145, in __init__
    self._dbapi_connection = engine.raw_connection()
  File "/opt/hostedtoolcache/Python/3.9.18/x64/lib/python3.9/site-packages/sqlalchemy/engine/base.py", line 3293, in raw_connection
    return self.pool.connect()
  File "/opt/hostedtoolcache/Python/3.9.18/x64/lib/python3.9/site-packages/sqlalchemy/pool/base.py", line 452, in connect
    return _ConnectionFairy._checkout(self)
  File "/opt/hostedtoolcache/Python/3.9.18/x64/lib/python3.9/site-packages/sqlalchemy/pool/base.py", line 1269, in _checkout
    fairy = _ConnectionRecord.checkout(pool)
  File "/opt/hostedtoolcache/Python/3.9.18/x64/lib/python3.9/site-packages/sqlalchemy/pool/base.py", line 716, in checkout
    rec = pool._do_get()
  File "/opt/hostedtoolcache/Python/3.9.18/x64/lib/python3.9/site-packages/sqlalchemy/pool/impl.py", line 170, in _do_get
    self._dec_overflow()
  File "/opt/hostedtoolcache/Python/3.9.18/x64/lib/python3.9/site-packages/sqlalchemy/util/langhelpers.py", line 146, in __exit__
    raise exc_value.with_traceback(exc_tb)
  File "/opt/hostedtoolcache/Python/3.9.18/x64/lib/python3.9/site-packages/sqlalchemy/pool/impl.py", line 167, in _do_get
    return self._create_connection()
  File "/opt/hostedtoolcache/Python/3.9.18/x64/lib/python3.9/site-packages/sqlalchemy/pool/base.py", line 393, in _create_connection
    return _ConnectionRecord(self)
  File "/opt/hostedtoolcache/Python/3.9.18/x64/lib/python3.9/site-packages/sqlalchemy/pool/base.py", line 678, in __init__
    self.__connect()
  File "/opt/hostedtoolcache/Python/3.9.18/x64/lib/python3.9/site-packages/sqlalchemy/pool/base.py", line 903, in __connect
    pool.logger.debug("Error on connect(): %s", e)
  File "/opt/hostedtoolcache/Python/3.9.18/x64/lib/python3.9/site-packages/sqlalchemy/util/langhelpers.py", line 146, in __exit__
    raise exc_value.with_traceback(exc_tb)
  File "/opt/hostedtoolcache/Python/3.9.18/x64/lib/python3.9/site-packages/sqlalchemy/pool/base.py", line 898, in __connect
    self.dbapi_connection = connection = pool._invoke_creator(self)
  File "/opt/hostedtoolcache/Python/3.9.18/x64/lib/python3.9/site-packages/sqlalchemy/engine/create.py", line 645, in connect
    return dialect.connect(*cargs, **cparams)
  File "/opt/hostedtoolcache/Python/3.9.18/x64/lib/python3.9/site-packages/sqlalchemy/engine/default.py", line 616, in connect
    return self.loaded_dbapi.connect(*cargs, **cparams)
sqlalchemy.exc.DBAPIError: (pyodbc.Error) ('01000', "[01000] [unixODBC][Driver Manager]Can't open lib 'ODBC Driver 18 for SQL Server' : file not found (0) (SQLDriverConnect)")
(Background on this error at: https://sqlalche.me/e/20/dbapi)
2023-12-30 23:13:28,875 - ERROR - An exception occurred: failed to get Spotify ids (Attempt 2/2)
Traceback (most recent call last):
  File "/opt/hostedtoolcache/Python/3.9.18/x64/lib/python3.9/site-packages/sqlalchemy/engine/base.py", line 145, in __init__
    self._dbapi_connection = engine.raw_connection()
  File "/opt/hostedtoolcache/Python/3.9.18/x64/lib/python3.9/site-packages/sqlalchemy/engine/base.py", line 3293, in raw_connection
    return self.pool.connect()
  File "/opt/hostedtoolcache/Python/3.9.18/x64/lib/python3.9/site-packages/sqlalchemy/pool/base.py", line 452, in connect
    return _ConnectionFairy._checkout(self)
  File "/opt/hostedtoolcache/Python/3.9.18/x64/lib/python3.9/site-packages/sqlalchemy/pool/base.py", line 1269, in _checkout
    fairy = _ConnectionRecord.checkout(pool)
  File "/opt/hostedtoolcache/Python/3.9.18/x64/lib/python3.9/site-packages/sqlalchemy/pool/base.py", line 716, in checkout
    rec = pool._do_get()
  File "/opt/hostedtoolcache/Python/3.9.18/x64/lib/python3.9/site-packages/sqlalchemy/pool/impl.py", line 170, in _do_get
    self._dec_overflow()
  File "/opt/hostedtoolcache/Python/3.9.18/x64/lib/python3.9/site-packages/sqlalchemy/util/langhelpers.py", line 146, in __exit__
    raise exc_value.with_traceback(exc_tb)
  File "/opt/hostedtoolcache/Python/3.9.18/x64/lib/python3.9/site-packages/sqlalchemy/pool/impl.py", line 167, in _do_get
    return self._create_connection()
  File "/opt/hostedtoolcache/Python/3.9.18/x64/lib/python3.9/site-packages/sqlalchemy/pool/base.py", line 393, in _create_connection
    return _ConnectionRecord(self)
  File "/opt/hostedtoolcache/Python/3.9.18/x64/lib/python3.9/site-packages/sqlalchemy/pool/base.py", line 678, in __init__
    self.__connect()
  File "/opt/hostedtoolcache/Python/3.9.18/x64/lib/python3.9/site-packages/sqlalchemy/pool/base.py", line 903, in __connect
    pool.logger.debug("Error on connect(): %s", e)
  File "/opt/hostedtoolcache/Python/3.9.18/x64/lib/python3.9/site-packages/sqlalchemy/util/langhelpers.py", line 146, in __exit__
    raise exc_value.with_traceback(exc_tb)
  File "/opt/hostedtoolcache/Python/3.9.18/x64/lib/python3.9/site-packages/sqlalchemy/pool/base.py", line 898, in __connect
    self.dbapi_connection = connection = pool._invoke_creator(self)
  File "/opt/hostedtoolcache/Python/3.9.18/x64/lib/python3.9/site-packages/sqlalchemy/engine/create.py", line 645, in connect
    return dialect.connect(*cargs, **cparams)
  File "/opt/hostedtoolcache/Python/3.9.18/x64/lib/python3.9/site-packages/sqlalchemy/engine/default.py", line 616, in connect
    return self.loaded_dbapi.connect(*cargs, **cparams)
pyodbc.Error: ('01000', "[01000] [unixODBC][Driver Manager]Can't open lib 'ODBC Driver 18 for SQL Server' : file not found (0) (SQLDriverConnect)")

The above exception was the direct cause of the following exception:

Traceback (most recent call last):
  File "/home/runner/work/spotify_daily_data_updates/spotify_daily_data_updates/main.py", line 220, in get_spotify_ids
    artist_ids = pd.read_sql(query, engine)['artist_id'].to_list()
  File "/opt/hostedtoolcache/Python/3.9.18/x64/lib/python3.9/site-packages/pandas/io/sql.py", line 652, in read_sql
    with pandasSQL_builder(con) as pandas_sql:
  File "/opt/hostedtoolcache/Python/3.9.18/x64/lib/python3.9/site-packages/pandas/io/sql.py", line 851, in pandasSQL_builder
    return SQLDatabase(con, schema, need_transaction)
  File "/opt/hostedtoolcache/Python/3.9.18/x64/lib/python3.9/site-packages/pandas/io/sql.py", line 1576, in __init__
    con = self.exit_stack.enter_context(con.connect())
  File "/opt/hostedtoolcache/Python/3.9.18/x64/lib/python3.9/site-packages/sqlalchemy/engine/base.py", line 3269, in connect
    return self._connection_cls(self)
  File "/opt/hostedtoolcache/Python/3.9.18/x64/lib/python3.9/site-packages/sqlalchemy/engine/base.py", line 147, in __init__
    Connection._handle_dbapi_exception_noconnection(
  File "/opt/hostedtoolcache/Python/3.9.18/x64/lib/python3.9/site-packages/sqlalchemy/engine/base.py", line 2431, in _handle_dbapi_exception_noconnection
    raise sqlalchemy_exception.with_traceback(exc_info[2]) from e
  File "/opt/hostedtoolcache/Python/3.9.18/x64/lib/python3.9/site-packages/sqlalchemy/engine/base.py", line 145, in __init__
    self._dbapi_connection = engine.raw_connection()
  File "/opt/hostedtoolcache/Python/3.9.18/x64/lib/python3.9/site-packages/sqlalchemy/engine/base.py", line 3293, in raw_connection
    return self.pool.connect()
  File "/opt/hostedtoolcache/Python/3.9.18/x64/lib/python3.9/site-packages/sqlalchemy/pool/base.py", line 452, in connect
    return _ConnectionFairy._checkout(self)
  File "/opt/hostedtoolcache/Python/3.9.18/x64/lib/python3.9/site-packages/sqlalchemy/pool/base.py", line 1269, in _checkout
    fairy = _ConnectionRecord.checkout(pool)
  File "/opt/hostedtoolcache/Python/3.9.18/x64/lib/python3.9/site-packages/sqlalchemy/pool/base.py", line 716, in checkout
    rec = pool._do_get()
  File "/opt/hostedtoolcache/Python/3.9.18/x64/lib/python3.9/site-packages/sqlalchemy/pool/impl.py", line 170, in _do_get
    self._dec_overflow()
  File "/opt/hostedtoolcache/Python/3.9.18/x64/lib/python3.9/site-packages/sqlalchemy/util/langhelpers.py", line 146, in __exit__
    raise exc_value.with_traceback(exc_tb)
  File "/opt/hostedtoolcache/Python/3.9.18/x64/lib/python3.9/site-packages/sqlalchemy/pool/impl.py", line 167, in _do_get
    return self._create_connection()
  File "/opt/hostedtoolcache/Python/3.9.18/x64/lib/python3.9/site-packages/sqlalchemy/pool/base.py", line 393, in _create_connection
    return _ConnectionRecord(self)
  File "/opt/hostedtoolcache/Python/3.9.18/x64/lib/python3.9/site-packages/sqlalchemy/pool/base.py", line 678, in __init__
    self.__connect()
  File "/opt/hostedtoolcache/Python/3.9.18/x64/lib/python3.9/site-packages/sqlalchemy/pool/base.py", line 903, in __connect
    pool.logger.debug("Error on connect(): %s", e)
  File "/opt/hostedtoolcache/Python/3.9.18/x64/lib/python3.9/site-packages/sqlalchemy/util/langhelpers.py", line 146, in __exit__
    raise exc_value.with_traceback(exc_tb)
  File "/opt/hostedtoolcache/Python/3.9.18/x64/lib/python3.9/site-packages/sqlalchemy/pool/base.py", line 898, in __connect
    self.dbapi_connection = connection = pool._invoke_creator(self)
  File "/opt/hostedtoolcache/Python/3.9.18/x64/lib/python3.9/site-packages/sqlalchemy/engine/create.py", line 645, in connect
    return dialect.connect(*cargs, **cparams)
  File "/opt/hostedtoolcache/Python/3.9.18/x64/lib/python3.9/site-packages/sqlalchemy/engine/default.py", line 616, in connect
    return self.loaded_dbapi.connect(*cargs, **cparams)
sqlalchemy.exc.DBAPIError: (pyodbc.Error) ('01000', "[01000] [unixODBC][Driver Manager]Can't open lib 'ODBC Driver 18 for SQL Server' : file not found (0) (SQLDriverConnect)")
(Background on this error at: https://sqlalche.me/e/20/dbapi)
2023-12-30 23:13:30,877 - ERROR - Failed to get Spotify ids  after 2 attempts.
2023-12-30 23:13:30,877 - ERROR - An exception occurred: Load data into DB
2023-12-30 23:33:12,824 - ERROR - An exception occurred: failed to get Spotify ids (Attempt 1/2)
Traceback (most recent call last):
  File "/opt/hostedtoolcache/Python/3.9.18/x64/lib/python3.9/site-packages/sqlalchemy/engine/base.py", line 145, in __init__
    self._dbapi_connection = engine.raw_connection()
  File "/opt/hostedtoolcache/Python/3.9.18/x64/lib/python3.9/site-packages/sqlalchemy/engine/base.py", line 3293, in raw_connection
    return self.pool.connect()
  File "/opt/hostedtoolcache/Python/3.9.18/x64/lib/python3.9/site-packages/sqlalchemy/pool/base.py", line 452, in connect
    return _ConnectionFairy._checkout(self)
  File "/opt/hostedtoolcache/Python/3.9.18/x64/lib/python3.9/site-packages/sqlalchemy/pool/base.py", line 1269, in _checkout
    fairy = _ConnectionRecord.checkout(pool)
  File "/opt/hostedtoolcache/Python/3.9.18/x64/lib/python3.9/site-packages/sqlalchemy/pool/base.py", line 716, in checkout
    rec = pool._do_get()
  File "/opt/hostedtoolcache/Python/3.9.18/x64/lib/python3.9/site-packages/sqlalchemy/pool/impl.py", line 170, in _do_get
    self._dec_overflow()
  File "/opt/hostedtoolcache/Python/3.9.18/x64/lib/python3.9/site-packages/sqlalchemy/util/langhelpers.py", line 146, in __exit__
    raise exc_value.with_traceback(exc_tb)
  File "/opt/hostedtoolcache/Python/3.9.18/x64/lib/python3.9/site-packages/sqlalchemy/pool/impl.py", line 167, in _do_get
    return self._create_connection()
  File "/opt/hostedtoolcache/Python/3.9.18/x64/lib/python3.9/site-packages/sqlalchemy/pool/base.py", line 393, in _create_connection
    return _ConnectionRecord(self)
  File "/opt/hostedtoolcache/Python/3.9.18/x64/lib/python3.9/site-packages/sqlalchemy/pool/base.py", line 678, in __init__
    self.__connect()
  File "/opt/hostedtoolcache/Python/3.9.18/x64/lib/python3.9/site-packages/sqlalchemy/pool/base.py", line 903, in __connect
    pool.logger.debug("Error on connect(): %s", e)
  File "/opt/hostedtoolcache/Python/3.9.18/x64/lib/python3.9/site-packages/sqlalchemy/util/langhelpers.py", line 146, in __exit__
    raise exc_value.with_traceback(exc_tb)
  File "/opt/hostedtoolcache/Python/3.9.18/x64/lib/python3.9/site-packages/sqlalchemy/pool/base.py", line 898, in __connect
    self.dbapi_connection = connection = pool._invoke_creator(self)
  File "/opt/hostedtoolcache/Python/3.9.18/x64/lib/python3.9/site-packages/sqlalchemy/engine/create.py", line 645, in connect
    return dialect.connect(*cargs, **cparams)
  File "/opt/hostedtoolcache/Python/3.9.18/x64/lib/python3.9/site-packages/sqlalchemy/engine/default.py", line 616, in connect
    return self.loaded_dbapi.connect(*cargs, **cparams)
pyodbc.Error: ('01000', "[01000] [unixODBC][Driver Manager]Can't open lib 'SQL Server Native Client 10.0' : file not found (0) (SQLDriverConnect)")

The above exception was the direct cause of the following exception:

Traceback (most recent call last):
  File "/home/runner/work/spotify_daily_data_updates/spotify_daily_data_updates/main.py", line 69, in get_spotify_ids
    artist_ids = pd.read_sql(query, engine)['artist_id'].to_list()
  File "/opt/hostedtoolcache/Python/3.9.18/x64/lib/python3.9/site-packages/pandas/io/sql.py", line 652, in read_sql
    with pandasSQL_builder(con) as pandas_sql:
  File "/opt/hostedtoolcache/Python/3.9.18/x64/lib/python3.9/site-packages/pandas/io/sql.py", line 851, in pandasSQL_builder
    return SQLDatabase(con, schema, need_transaction)
  File "/opt/hostedtoolcache/Python/3.9.18/x64/lib/python3.9/site-packages/pandas/io/sql.py", line 1576, in __init__
    con = self.exit_stack.enter_context(con.connect())
  File "/opt/hostedtoolcache/Python/3.9.18/x64/lib/python3.9/site-packages/sqlalchemy/engine/base.py", line 3269, in connect
    return self._connection_cls(self)
  File "/opt/hostedtoolcache/Python/3.9.18/x64/lib/python3.9/site-packages/sqlalchemy/engine/base.py", line 147, in __init__
    Connection._handle_dbapi_exception_noconnection(
  File "/opt/hostedtoolcache/Python/3.9.18/x64/lib/python3.9/site-packages/sqlalchemy/engine/base.py", line 2431, in _handle_dbapi_exception_noconnection
    raise sqlalchemy_exception.with_traceback(exc_info[2]) from e
  File "/opt/hostedtoolcache/Python/3.9.18/x64/lib/python3.9/site-packages/sqlalchemy/engine/base.py", line 145, in __init__
    self._dbapi_connection = engine.raw_connection()
  File "/opt/hostedtoolcache/Python/3.9.18/x64/lib/python3.9/site-packages/sqlalchemy/engine/base.py", line 3293, in raw_connection
    return self.pool.connect()
  File "/opt/hostedtoolcache/Python/3.9.18/x64/lib/python3.9/site-packages/sqlalchemy/pool/base.py", line 452, in connect
    return _ConnectionFairy._checkout(self)
  File "/opt/hostedtoolcache/Python/3.9.18/x64/lib/python3.9/site-packages/sqlalchemy/pool/base.py", line 1269, in _checkout
    fairy = _ConnectionRecord.checkout(pool)
  File "/opt/hostedtoolcache/Python/3.9.18/x64/lib/python3.9/site-packages/sqlalchemy/pool/base.py", line 716, in checkout
    rec = pool._do_get()
  File "/opt/hostedtoolcache/Python/3.9.18/x64/lib/python3.9/site-packages/sqlalchemy/pool/impl.py", line 170, in _do_get
    self._dec_overflow()
  File "/opt/hostedtoolcache/Python/3.9.18/x64/lib/python3.9/site-packages/sqlalchemy/util/langhelpers.py", line 146, in __exit__
    raise exc_value.with_traceback(exc_tb)
  File "/opt/hostedtoolcache/Python/3.9.18/x64/lib/python3.9/site-packages/sqlalchemy/pool/impl.py", line 167, in _do_get
    return self._create_connection()
  File "/opt/hostedtoolcache/Python/3.9.18/x64/lib/python3.9/site-packages/sqlalchemy/pool/base.py", line 393, in _create_connection
    return _ConnectionRecord(self)
  File "/opt/hostedtoolcache/Python/3.9.18/x64/lib/python3.9/site-packages/sqlalchemy/pool/base.py", line 678, in __init__
    self.__connect()
  File "/opt/hostedtoolcache/Python/3.9.18/x64/lib/python3.9/site-packages/sqlalchemy/pool/base.py", line 903, in __connect
    pool.logger.debug("Error on connect(): %s", e)
  File "/opt/hostedtoolcache/Python/3.9.18/x64/lib/python3.9/site-packages/sqlalchemy/util/langhelpers.py", line 146, in __exit__
    raise exc_value.with_traceback(exc_tb)
  File "/opt/hostedtoolcache/Python/3.9.18/x64/lib/python3.9/site-packages/sqlalchemy/pool/base.py", line 898, in __connect
    self.dbapi_connection = connection = pool._invoke_creator(self)
  File "/opt/hostedtoolcache/Python/3.9.18/x64/lib/python3.9/site-packages/sqlalchemy/engine/create.py", line 645, in connect
    return dialect.connect(*cargs, **cparams)
  File "/opt/hostedtoolcache/Python/3.9.18/x64/lib/python3.9/site-packages/sqlalchemy/engine/default.py", line 616, in connect
    return self.loaded_dbapi.connect(*cargs, **cparams)
sqlalchemy.exc.DBAPIError: (pyodbc.Error) ('01000', "[01000] [unixODBC][Driver Manager]Can't open lib 'SQL Server Native Client 10.0' : file not found (0) (SQLDriverConnect)")
(Background on this error at: https://sqlalche.me/e/20/dbapi)
2023-12-30 23:33:14,829 - ERROR - An exception occurred: failed to get Spotify ids (Attempt 2/2)
Traceback (most recent call last):
  File "/opt/hostedtoolcache/Python/3.9.18/x64/lib/python3.9/site-packages/sqlalchemy/engine/base.py", line 145, in __init__
    self._dbapi_connection = engine.raw_connection()
  File "/opt/hostedtoolcache/Python/3.9.18/x64/lib/python3.9/site-packages/sqlalchemy/engine/base.py", line 3293, in raw_connection
    return self.pool.connect()
  File "/opt/hostedtoolcache/Python/3.9.18/x64/lib/python3.9/site-packages/sqlalchemy/pool/base.py", line 452, in connect
    return _ConnectionFairy._checkout(self)
  File "/opt/hostedtoolcache/Python/3.9.18/x64/lib/python3.9/site-packages/sqlalchemy/pool/base.py", line 1269, in _checkout
    fairy = _ConnectionRecord.checkout(pool)
  File "/opt/hostedtoolcache/Python/3.9.18/x64/lib/python3.9/site-packages/sqlalchemy/pool/base.py", line 716, in checkout
    rec = pool._do_get()
  File "/opt/hostedtoolcache/Python/3.9.18/x64/lib/python3.9/site-packages/sqlalchemy/pool/impl.py", line 170, in _do_get
    self._dec_overflow()
  File "/opt/hostedtoolcache/Python/3.9.18/x64/lib/python3.9/site-packages/sqlalchemy/util/langhelpers.py", line 146, in __exit__
    raise exc_value.with_traceback(exc_tb)
  File "/opt/hostedtoolcache/Python/3.9.18/x64/lib/python3.9/site-packages/sqlalchemy/pool/impl.py", line 167, in _do_get
    return self._create_connection()
  File "/opt/hostedtoolcache/Python/3.9.18/x64/lib/python3.9/site-packages/sqlalchemy/pool/base.py", line 393, in _create_connection
    return _ConnectionRecord(self)
  File "/opt/hostedtoolcache/Python/3.9.18/x64/lib/python3.9/site-packages/sqlalchemy/pool/base.py", line 678, in __init__
    self.__connect()
  File "/opt/hostedtoolcache/Python/3.9.18/x64/lib/python3.9/site-packages/sqlalchemy/pool/base.py", line 903, in __connect
    pool.logger.debug("Error on connect(): %s", e)
  File "/opt/hostedtoolcache/Python/3.9.18/x64/lib/python3.9/site-packages/sqlalchemy/util/langhelpers.py", line 146, in __exit__
    raise exc_value.with_traceback(exc_tb)
  File "/opt/hostedtoolcache/Python/3.9.18/x64/lib/python3.9/site-packages/sqlalchemy/pool/base.py", line 898, in __connect
    self.dbapi_connection = connection = pool._invoke_creator(self)
  File "/opt/hostedtoolcache/Python/3.9.18/x64/lib/python3.9/site-packages/sqlalchemy/engine/create.py", line 645, in connect
    return dialect.connect(*cargs, **cparams)
  File "/opt/hostedtoolcache/Python/3.9.18/x64/lib/python3.9/site-packages/sqlalchemy/engine/default.py", line 616, in connect
    return self.loaded_dbapi.connect(*cargs, **cparams)
pyodbc.Error: ('01000', "[01000] [unixODBC][Driver Manager]Can't open lib 'SQL Server Native Client 10.0' : file not found (0) (SQLDriverConnect)")

The above exception was the direct cause of the following exception:

Traceback (most recent call last):
  File "/home/runner/work/spotify_daily_data_updates/spotify_daily_data_updates/main.py", line 69, in get_spotify_ids
    artist_ids = pd.read_sql(query, engine)['artist_id'].to_list()
  File "/opt/hostedtoolcache/Python/3.9.18/x64/lib/python3.9/site-packages/pandas/io/sql.py", line 652, in read_sql
    with pandasSQL_builder(con) as pandas_sql:
  File "/opt/hostedtoolcache/Python/3.9.18/x64/lib/python3.9/site-packages/pandas/io/sql.py", line 851, in pandasSQL_builder
    return SQLDatabase(con, schema, need_transaction)
  File "/opt/hostedtoolcache/Python/3.9.18/x64/lib/python3.9/site-packages/pandas/io/sql.py", line 1576, in __init__
    con = self.exit_stack.enter_context(con.connect())
  File "/opt/hostedtoolcache/Python/3.9.18/x64/lib/python3.9/site-packages/sqlalchemy/engine/base.py", line 3269, in connect
    return self._connection_cls(self)
  File "/opt/hostedtoolcache/Python/3.9.18/x64/lib/python3.9/site-packages/sqlalchemy/engine/base.py", line 147, in __init__
    Connection._handle_dbapi_exception_noconnection(
  File "/opt/hostedtoolcache/Python/3.9.18/x64/lib/python3.9/site-packages/sqlalchemy/engine/base.py", line 2431, in _handle_dbapi_exception_noconnection
    raise sqlalchemy_exception.with_traceback(exc_info[2]) from e
  File "/opt/hostedtoolcache/Python/3.9.18/x64/lib/python3.9/site-packages/sqlalchemy/engine/base.py", line 145, in __init__
    self._dbapi_connection = engine.raw_connection()
  File "/opt/hostedtoolcache/Python/3.9.18/x64/lib/python3.9/site-packages/sqlalchemy/engine/base.py", line 3293, in raw_connection
    return self.pool.connect()
  File "/opt/hostedtoolcache/Python/3.9.18/x64/lib/python3.9/site-packages/sqlalchemy/pool/base.py", line 452, in connect
    return _ConnectionFairy._checkout(self)
  File "/opt/hostedtoolcache/Python/3.9.18/x64/lib/python3.9/site-packages/sqlalchemy/pool/base.py", line 1269, in _checkout
    fairy = _ConnectionRecord.checkout(pool)
  File "/opt/hostedtoolcache/Python/3.9.18/x64/lib/python3.9/site-packages/sqlalchemy/pool/base.py", line 716, in checkout
    rec = pool._do_get()
  File "/opt/hostedtoolcache/Python/3.9.18/x64/lib/python3.9/site-packages/sqlalchemy/pool/impl.py", line 170, in _do_get
    self._dec_overflow()
  File "/opt/hostedtoolcache/Python/3.9.18/x64/lib/python3.9/site-packages/sqlalchemy/util/langhelpers.py", line 146, in __exit__
    raise exc_value.with_traceback(exc_tb)
  File "/opt/hostedtoolcache/Python/3.9.18/x64/lib/python3.9/site-packages/sqlalchemy/pool/impl.py", line 167, in _do_get
    return self._create_connection()
  File "/opt/hostedtoolcache/Python/3.9.18/x64/lib/python3.9/site-packages/sqlalchemy/pool/base.py", line 393, in _create_connection
    return _ConnectionRecord(self)
  File "/opt/hostedtoolcache/Python/3.9.18/x64/lib/python3.9/site-packages/sqlalchemy/pool/base.py", line 678, in __init__
    self.__connect()
  File "/opt/hostedtoolcache/Python/3.9.18/x64/lib/python3.9/site-packages/sqlalchemy/pool/base.py", line 903, in __connect
    pool.logger.debug("Error on connect(): %s", e)
  File "/opt/hostedtoolcache/Python/3.9.18/x64/lib/python3.9/site-packages/sqlalchemy/util/langhelpers.py", line 146, in __exit__
    raise exc_value.with_traceback(exc_tb)
  File "/opt/hostedtoolcache/Python/3.9.18/x64/lib/python3.9/site-packages/sqlalchemy/pool/base.py", line 898, in __connect
    self.dbapi_connection = connection = pool._invoke_creator(self)
  File "/opt/hostedtoolcache/Python/3.9.18/x64/lib/python3.9/site-packages/sqlalchemy/engine/create.py", line 645, in connect
    return dialect.connect(*cargs, **cparams)
  File "/opt/hostedtoolcache/Python/3.9.18/x64/lib/python3.9/site-packages/sqlalchemy/engine/default.py", line 616, in connect
    return self.loaded_dbapi.connect(*cargs, **cparams)
sqlalchemy.exc.DBAPIError: (pyodbc.Error) ('01000', "[01000] [unixODBC][Driver Manager]Can't open lib 'SQL Server Native Client 10.0' : file not found (0) (SQLDriverConnect)")
(Background on this error at: https://sqlalche.me/e/20/dbapi)
2023-12-30 23:33:16,832 - ERROR - Failed to get Spotify ids  after 2 attempts.
2023-12-30 23:33:16,832 - ERROR - An exception occurred: Load data into DB
2023-12-30 23:39:17,486 - ERROR - An exception occurred: failed to get Spotify ids (Attempt 1/2)
Traceback (most recent call last):
  File "/opt/hostedtoolcache/Python/3.9.18/x64/lib/python3.9/site-packages/sqlalchemy/engine/base.py", line 145, in __init__
    self._dbapi_connection = engine.raw_connection()
  File "/opt/hostedtoolcache/Python/3.9.18/x64/lib/python3.9/site-packages/sqlalchemy/engine/base.py", line 3293, in raw_connection
    return self.pool.connect()
  File "/opt/hostedtoolcache/Python/3.9.18/x64/lib/python3.9/site-packages/sqlalchemy/pool/base.py", line 452, in connect
    return _ConnectionFairy._checkout(self)
  File "/opt/hostedtoolcache/Python/3.9.18/x64/lib/python3.9/site-packages/sqlalchemy/pool/base.py", line 1269, in _checkout
    fairy = _ConnectionRecord.checkout(pool)
  File "/opt/hostedtoolcache/Python/3.9.18/x64/lib/python3.9/site-packages/sqlalchemy/pool/base.py", line 716, in checkout
    rec = pool._do_get()
  File "/opt/hostedtoolcache/Python/3.9.18/x64/lib/python3.9/site-packages/sqlalchemy/pool/impl.py", line 170, in _do_get
    self._dec_overflow()
  File "/opt/hostedtoolcache/Python/3.9.18/x64/lib/python3.9/site-packages/sqlalchemy/util/langhelpers.py", line 146, in __exit__
    raise exc_value.with_traceback(exc_tb)
  File "/opt/hostedtoolcache/Python/3.9.18/x64/lib/python3.9/site-packages/sqlalchemy/pool/impl.py", line 167, in _do_get
    return self._create_connection()
  File "/opt/hostedtoolcache/Python/3.9.18/x64/lib/python3.9/site-packages/sqlalchemy/pool/base.py", line 393, in _create_connection
    return _ConnectionRecord(self)
  File "/opt/hostedtoolcache/Python/3.9.18/x64/lib/python3.9/site-packages/sqlalchemy/pool/base.py", line 678, in __init__
    self.__connect()
  File "/opt/hostedtoolcache/Python/3.9.18/x64/lib/python3.9/site-packages/sqlalchemy/pool/base.py", line 903, in __connect
    pool.logger.debug("Error on connect(): %s", e)
  File "/opt/hostedtoolcache/Python/3.9.18/x64/lib/python3.9/site-packages/sqlalchemy/util/langhelpers.py", line 146, in __exit__
    raise exc_value.with_traceback(exc_tb)
  File "/opt/hostedtoolcache/Python/3.9.18/x64/lib/python3.9/site-packages/sqlalchemy/pool/base.py", line 898, in __connect
    self.dbapi_connection = connection = pool._invoke_creator(self)
  File "/opt/hostedtoolcache/Python/3.9.18/x64/lib/python3.9/site-packages/sqlalchemy/engine/create.py", line 645, in connect
    return dialect.connect(*cargs, **cparams)
  File "/opt/hostedtoolcache/Python/3.9.18/x64/lib/python3.9/site-packages/sqlalchemy/engine/default.py", line 616, in connect
    return self.loaded_dbapi.connect(*cargs, **cparams)
pyodbc.Error: ('01000', "[01000] [unixODBC][Driver Manager]Can't open lib 'SQL Server Native Client 10.0' : file not found (0) (SQLDriverConnect)")

The above exception was the direct cause of the following exception:

Traceback (most recent call last):
  File "/home/runner/work/spotify_daily_data_updates/spotify_daily_data_updates/main.py", line 69, in get_spotify_ids
    artist_ids = pd.read_sql(query, engine)['artist_id'].to_list()
  File "/opt/hostedtoolcache/Python/3.9.18/x64/lib/python3.9/site-packages/pandas/io/sql.py", line 652, in read_sql
    with pandasSQL_builder(con) as pandas_sql:
  File "/opt/hostedtoolcache/Python/3.9.18/x64/lib/python3.9/site-packages/pandas/io/sql.py", line 851, in pandasSQL_builder
    return SQLDatabase(con, schema, need_transaction)
  File "/opt/hostedtoolcache/Python/3.9.18/x64/lib/python3.9/site-packages/pandas/io/sql.py", line 1576, in __init__
    con = self.exit_stack.enter_context(con.connect())
  File "/opt/hostedtoolcache/Python/3.9.18/x64/lib/python3.9/site-packages/sqlalchemy/engine/base.py", line 3269, in connect
    return self._connection_cls(self)
  File "/opt/hostedtoolcache/Python/3.9.18/x64/lib/python3.9/site-packages/sqlalchemy/engine/base.py", line 147, in __init__
    Connection._handle_dbapi_exception_noconnection(
  File "/opt/hostedtoolcache/Python/3.9.18/x64/lib/python3.9/site-packages/sqlalchemy/engine/base.py", line 2431, in _handle_dbapi_exception_noconnection
    raise sqlalchemy_exception.with_traceback(exc_info[2]) from e
  File "/opt/hostedtoolcache/Python/3.9.18/x64/lib/python3.9/site-packages/sqlalchemy/engine/base.py", line 145, in __init__
    self._dbapi_connection = engine.raw_connection()
  File "/opt/hostedtoolcache/Python/3.9.18/x64/lib/python3.9/site-packages/sqlalchemy/engine/base.py", line 3293, in raw_connection
    return self.pool.connect()
  File "/opt/hostedtoolcache/Python/3.9.18/x64/lib/python3.9/site-packages/sqlalchemy/pool/base.py", line 452, in connect
    return _ConnectionFairy._checkout(self)
  File "/opt/hostedtoolcache/Python/3.9.18/x64/lib/python3.9/site-packages/sqlalchemy/pool/base.py", line 1269, in _checkout
    fairy = _ConnectionRecord.checkout(pool)
  File "/opt/hostedtoolcache/Python/3.9.18/x64/lib/python3.9/site-packages/sqlalchemy/pool/base.py", line 716, in checkout
    rec = pool._do_get()
  File "/opt/hostedtoolcache/Python/3.9.18/x64/lib/python3.9/site-packages/sqlalchemy/pool/impl.py", line 170, in _do_get
    self._dec_overflow()
  File "/opt/hostedtoolcache/Python/3.9.18/x64/lib/python3.9/site-packages/sqlalchemy/util/langhelpers.py", line 146, in __exit__
    raise exc_value.with_traceback(exc_tb)
  File "/opt/hostedtoolcache/Python/3.9.18/x64/lib/python3.9/site-packages/sqlalchemy/pool/impl.py", line 167, in _do_get
    return self._create_connection()
  File "/opt/hostedtoolcache/Python/3.9.18/x64/lib/python3.9/site-packages/sqlalchemy/pool/base.py", line 393, in _create_connection
    return _ConnectionRecord(self)
  File "/opt/hostedtoolcache/Python/3.9.18/x64/lib/python3.9/site-packages/sqlalchemy/pool/base.py", line 678, in __init__
    self.__connect()
  File "/opt/hostedtoolcache/Python/3.9.18/x64/lib/python3.9/site-packages/sqlalchemy/pool/base.py", line 903, in __connect
    pool.logger.debug("Error on connect(): %s", e)
  File "/opt/hostedtoolcache/Python/3.9.18/x64/lib/python3.9/site-packages/sqlalchemy/util/langhelpers.py", line 146, in __exit__
    raise exc_value.with_traceback(exc_tb)
  File "/opt/hostedtoolcache/Python/3.9.18/x64/lib/python3.9/site-packages/sqlalchemy/pool/base.py", line 898, in __connect
    self.dbapi_connection = connection = pool._invoke_creator(self)
  File "/opt/hostedtoolcache/Python/3.9.18/x64/lib/python3.9/site-packages/sqlalchemy/engine/create.py", line 645, in connect
    return dialect.connect(*cargs, **cparams)
  File "/opt/hostedtoolcache/Python/3.9.18/x64/lib/python3.9/site-packages/sqlalchemy/engine/default.py", line 616, in connect
    return self.loaded_dbapi.connect(*cargs, **cparams)
sqlalchemy.exc.DBAPIError: (pyodbc.Error) ('01000', "[01000] [unixODBC][Driver Manager]Can't open lib 'SQL Server Native Client 10.0' : file not found (0) (SQLDriverConnect)")
(Background on this error at: https://sqlalche.me/e/20/dbapi)
2023-12-30 23:39:19,491 - ERROR - An exception occurred: failed to get Spotify ids (Attempt 2/2)
Traceback (most recent call last):
  File "/opt/hostedtoolcache/Python/3.9.18/x64/lib/python3.9/site-packages/sqlalchemy/engine/base.py", line 145, in __init__
    self._dbapi_connection = engine.raw_connection()
  File "/opt/hostedtoolcache/Python/3.9.18/x64/lib/python3.9/site-packages/sqlalchemy/engine/base.py", line 3293, in raw_connection
    return self.pool.connect()
  File "/opt/hostedtoolcache/Python/3.9.18/x64/lib/python3.9/site-packages/sqlalchemy/pool/base.py", line 452, in connect
    return _ConnectionFairy._checkout(self)
  File "/opt/hostedtoolcache/Python/3.9.18/x64/lib/python3.9/site-packages/sqlalchemy/pool/base.py", line 1269, in _checkout
    fairy = _ConnectionRecord.checkout(pool)
  File "/opt/hostedtoolcache/Python/3.9.18/x64/lib/python3.9/site-packages/sqlalchemy/pool/base.py", line 716, in checkout
    rec = pool._do_get()
  File "/opt/hostedtoolcache/Python/3.9.18/x64/lib/python3.9/site-packages/sqlalchemy/pool/impl.py", line 170, in _do_get
    self._dec_overflow()
  File "/opt/hostedtoolcache/Python/3.9.18/x64/lib/python3.9/site-packages/sqlalchemy/util/langhelpers.py", line 146, in __exit__
    raise exc_value.with_traceback(exc_tb)
  File "/opt/hostedtoolcache/Python/3.9.18/x64/lib/python3.9/site-packages/sqlalchemy/pool/impl.py", line 167, in _do_get
    return self._create_connection()
  File "/opt/hostedtoolcache/Python/3.9.18/x64/lib/python3.9/site-packages/sqlalchemy/pool/base.py", line 393, in _create_connection
    return _ConnectionRecord(self)
  File "/opt/hostedtoolcache/Python/3.9.18/x64/lib/python3.9/site-packages/sqlalchemy/pool/base.py", line 678, in __init__
    self.__connect()
  File "/opt/hostedtoolcache/Python/3.9.18/x64/lib/python3.9/site-packages/sqlalchemy/pool/base.py", line 903, in __connect
    pool.logger.debug("Error on connect(): %s", e)
  File "/opt/hostedtoolcache/Python/3.9.18/x64/lib/python3.9/site-packages/sqlalchemy/util/langhelpers.py", line 146, in __exit__
    raise exc_value.with_traceback(exc_tb)
  File "/opt/hostedtoolcache/Python/3.9.18/x64/lib/python3.9/site-packages/sqlalchemy/pool/base.py", line 898, in __connect
    self.dbapi_connection = connection = pool._invoke_creator(self)
  File "/opt/hostedtoolcache/Python/3.9.18/x64/lib/python3.9/site-packages/sqlalchemy/engine/create.py", line 645, in connect
    return dialect.connect(*cargs, **cparams)
  File "/opt/hostedtoolcache/Python/3.9.18/x64/lib/python3.9/site-packages/sqlalchemy/engine/default.py", line 616, in connect
    return self.loaded_dbapi.connect(*cargs, **cparams)
pyodbc.Error: ('01000', "[01000] [unixODBC][Driver Manager]Can't open lib 'SQL Server Native Client 10.0' : file not found (0) (SQLDriverConnect)")

The above exception was the direct cause of the following exception:

Traceback (most recent call last):
  File "/home/runner/work/spotify_daily_data_updates/spotify_daily_data_updates/main.py", line 69, in get_spotify_ids
    artist_ids = pd.read_sql(query, engine)['artist_id'].to_list()
  File "/opt/hostedtoolcache/Python/3.9.18/x64/lib/python3.9/site-packages/pandas/io/sql.py", line 652, in read_sql
    with pandasSQL_builder(con) as pandas_sql:
  File "/opt/hostedtoolcache/Python/3.9.18/x64/lib/python3.9/site-packages/pandas/io/sql.py", line 851, in pandasSQL_builder
    return SQLDatabase(con, schema, need_transaction)
  File "/opt/hostedtoolcache/Python/3.9.18/x64/lib/python3.9/site-packages/pandas/io/sql.py", line 1576, in __init__
    con = self.exit_stack.enter_context(con.connect())
  File "/opt/hostedtoolcache/Python/3.9.18/x64/lib/python3.9/site-packages/sqlalchemy/engine/base.py", line 3269, in connect
    return self._connection_cls(self)
  File "/opt/hostedtoolcache/Python/3.9.18/x64/lib/python3.9/site-packages/sqlalchemy/engine/base.py", line 147, in __init__
    Connection._handle_dbapi_exception_noconnection(
  File "/opt/hostedtoolcache/Python/3.9.18/x64/lib/python3.9/site-packages/sqlalchemy/engine/base.py", line 2431, in _handle_dbapi_exception_noconnection
    raise sqlalchemy_exception.with_traceback(exc_info[2]) from e
  File "/opt/hostedtoolcache/Python/3.9.18/x64/lib/python3.9/site-packages/sqlalchemy/engine/base.py", line 145, in __init__
    self._dbapi_connection = engine.raw_connection()
  File "/opt/hostedtoolcache/Python/3.9.18/x64/lib/python3.9/site-packages/sqlalchemy/engine/base.py", line 3293, in raw_connection
    return self.pool.connect()
  File "/opt/hostedtoolcache/Python/3.9.18/x64/lib/python3.9/site-packages/sqlalchemy/pool/base.py", line 452, in connect
    return _ConnectionFairy._checkout(self)
  File "/opt/hostedtoolcache/Python/3.9.18/x64/lib/python3.9/site-packages/sqlalchemy/pool/base.py", line 1269, in _checkout
    fairy = _ConnectionRecord.checkout(pool)
  File "/opt/hostedtoolcache/Python/3.9.18/x64/lib/python3.9/site-packages/sqlalchemy/pool/base.py", line 716, in checkout
    rec = pool._do_get()
  File "/opt/hostedtoolcache/Python/3.9.18/x64/lib/python3.9/site-packages/sqlalchemy/pool/impl.py", line 170, in _do_get
    self._dec_overflow()
  File "/opt/hostedtoolcache/Python/3.9.18/x64/lib/python3.9/site-packages/sqlalchemy/util/langhelpers.py", line 146, in __exit__
    raise exc_value.with_traceback(exc_tb)
  File "/opt/hostedtoolcache/Python/3.9.18/x64/lib/python3.9/site-packages/sqlalchemy/pool/impl.py", line 167, in _do_get
    return self._create_connection()
  File "/opt/hostedtoolcache/Python/3.9.18/x64/lib/python3.9/site-packages/sqlalchemy/pool/base.py", line 393, in _create_connection
    return _ConnectionRecord(self)
  File "/opt/hostedtoolcache/Python/3.9.18/x64/lib/python3.9/site-packages/sqlalchemy/pool/base.py", line 678, in __init__
    self.__connect()
  File "/opt/hostedtoolcache/Python/3.9.18/x64/lib/python3.9/site-packages/sqlalchemy/pool/base.py", line 903, in __connect
    pool.logger.debug("Error on connect(): %s", e)
  File "/opt/hostedtoolcache/Python/3.9.18/x64/lib/python3.9/site-packages/sqlalchemy/util/langhelpers.py", line 146, in __exit__
    raise exc_value.with_traceback(exc_tb)
  File "/opt/hostedtoolcache/Python/3.9.18/x64/lib/python3.9/site-packages/sqlalchemy/pool/base.py", line 898, in __connect
    self.dbapi_connection = connection = pool._invoke_creator(self)
  File "/opt/hostedtoolcache/Python/3.9.18/x64/lib/python3.9/site-packages/sqlalchemy/engine/create.py", line 645, in connect
    return dialect.connect(*cargs, **cparams)
  File "/opt/hostedtoolcache/Python/3.9.18/x64/lib/python3.9/site-packages/sqlalchemy/engine/default.py", line 616, in connect
    return self.loaded_dbapi.connect(*cargs, **cparams)
sqlalchemy.exc.DBAPIError: (pyodbc.Error) ('01000', "[01000] [unixODBC][Driver Manager]Can't open lib 'SQL Server Native Client 10.0' : file not found (0) (SQLDriverConnect)")
(Background on this error at: https://sqlalche.me/e/20/dbapi)
2023-12-30 23:39:21,493 - ERROR - Failed to get Spotify ids  after 2 attempts.
2023-12-30 23:39:21,493 - ERROR - An exception occurred: Load data into DB
2023-12-30 23:44:42,020 - ERROR - An exception occurred: failed to get Spotify ids (Attempt 1/2)
Traceback (most recent call last):
  File "/opt/hostedtoolcache/Python/3.9.18/x64/lib/python3.9/site-packages/sqlalchemy/engine/base.py", line 145, in __init__
    self._dbapi_connection = engine.raw_connection()
  File "/opt/hostedtoolcache/Python/3.9.18/x64/lib/python3.9/site-packages/sqlalchemy/engine/base.py", line 3293, in raw_connection
    return self.pool.connect()
  File "/opt/hostedtoolcache/Python/3.9.18/x64/lib/python3.9/site-packages/sqlalchemy/pool/base.py", line 452, in connect
    return _ConnectionFairy._checkout(self)
  File "/opt/hostedtoolcache/Python/3.9.18/x64/lib/python3.9/site-packages/sqlalchemy/pool/base.py", line 1269, in _checkout
    fairy = _ConnectionRecord.checkout(pool)
  File "/opt/hostedtoolcache/Python/3.9.18/x64/lib/python3.9/site-packages/sqlalchemy/pool/base.py", line 716, in checkout
    rec = pool._do_get()
  File "/opt/hostedtoolcache/Python/3.9.18/x64/lib/python3.9/site-packages/sqlalchemy/pool/impl.py", line 170, in _do_get
    self._dec_overflow()
  File "/opt/hostedtoolcache/Python/3.9.18/x64/lib/python3.9/site-packages/sqlalchemy/util/langhelpers.py", line 146, in __exit__
    raise exc_value.with_traceback(exc_tb)
  File "/opt/hostedtoolcache/Python/3.9.18/x64/lib/python3.9/site-packages/sqlalchemy/pool/impl.py", line 167, in _do_get
    return self._create_connection()
  File "/opt/hostedtoolcache/Python/3.9.18/x64/lib/python3.9/site-packages/sqlalchemy/pool/base.py", line 393, in _create_connection
    return _ConnectionRecord(self)
  File "/opt/hostedtoolcache/Python/3.9.18/x64/lib/python3.9/site-packages/sqlalchemy/pool/base.py", line 678, in __init__
    self.__connect()
  File "/opt/hostedtoolcache/Python/3.9.18/x64/lib/python3.9/site-packages/sqlalchemy/pool/base.py", line 903, in __connect
    pool.logger.debug("Error on connect(): %s", e)
  File "/opt/hostedtoolcache/Python/3.9.18/x64/lib/python3.9/site-packages/sqlalchemy/util/langhelpers.py", line 146, in __exit__
    raise exc_value.with_traceback(exc_tb)
  File "/opt/hostedtoolcache/Python/3.9.18/x64/lib/python3.9/site-packages/sqlalchemy/pool/base.py", line 898, in __connect
    self.dbapi_connection = connection = pool._invoke_creator(self)
  File "/opt/hostedtoolcache/Python/3.9.18/x64/lib/python3.9/site-packages/sqlalchemy/engine/create.py", line 645, in connect
    return dialect.connect(*cargs, **cparams)
  File "/opt/hostedtoolcache/Python/3.9.18/x64/lib/python3.9/site-packages/sqlalchemy/engine/default.py", line 616, in connect
    return self.loaded_dbapi.connect(*cargs, **cparams)
pyodbc.Error: ('01000', "[01000] [unixODBC][Driver Manager]Can't open lib 'ODBC Driver 18 for SQL Server' : file not found (0) (SQLDriverConnect)")

The above exception was the direct cause of the following exception:

Traceback (most recent call last):
  File "/home/runner/work/spotify_daily_data_updates/spotify_daily_data_updates/main.py", line 69, in get_spotify_ids
    artist_ids = pd.read_sql(query, engine)['artist_id'].to_list()
  File "/opt/hostedtoolcache/Python/3.9.18/x64/lib/python3.9/site-packages/pandas/io/sql.py", line 652, in read_sql
    with pandasSQL_builder(con) as pandas_sql:
  File "/opt/hostedtoolcache/Python/3.9.18/x64/lib/python3.9/site-packages/pandas/io/sql.py", line 851, in pandasSQL_builder
    return SQLDatabase(con, schema, need_transaction)
  File "/opt/hostedtoolcache/Python/3.9.18/x64/lib/python3.9/site-packages/pandas/io/sql.py", line 1576, in __init__
    con = self.exit_stack.enter_context(con.connect())
  File "/opt/hostedtoolcache/Python/3.9.18/x64/lib/python3.9/site-packages/sqlalchemy/engine/base.py", line 3269, in connect
    return self._connection_cls(self)
  File "/opt/hostedtoolcache/Python/3.9.18/x64/lib/python3.9/site-packages/sqlalchemy/engine/base.py", line 147, in __init__
    Connection._handle_dbapi_exception_noconnection(
  File "/opt/hostedtoolcache/Python/3.9.18/x64/lib/python3.9/site-packages/sqlalchemy/engine/base.py", line 2431, in _handle_dbapi_exception_noconnection
    raise sqlalchemy_exception.with_traceback(exc_info[2]) from e
  File "/opt/hostedtoolcache/Python/3.9.18/x64/lib/python3.9/site-packages/sqlalchemy/engine/base.py", line 145, in __init__
    self._dbapi_connection = engine.raw_connection()
  File "/opt/hostedtoolcache/Python/3.9.18/x64/lib/python3.9/site-packages/sqlalchemy/engine/base.py", line 3293, in raw_connection
    return self.pool.connect()
  File "/opt/hostedtoolcache/Python/3.9.18/x64/lib/python3.9/site-packages/sqlalchemy/pool/base.py", line 452, in connect
    return _ConnectionFairy._checkout(self)
  File "/opt/hostedtoolcache/Python/3.9.18/x64/lib/python3.9/site-packages/sqlalchemy/pool/base.py", line 1269, in _checkout
    fairy = _ConnectionRecord.checkout(pool)
  File "/opt/hostedtoolcache/Python/3.9.18/x64/lib/python3.9/site-packages/sqlalchemy/pool/base.py", line 716, in checkout
    rec = pool._do_get()
  File "/opt/hostedtoolcache/Python/3.9.18/x64/lib/python3.9/site-packages/sqlalchemy/pool/impl.py", line 170, in _do_get
    self._dec_overflow()
  File "/opt/hostedtoolcache/Python/3.9.18/x64/lib/python3.9/site-packages/sqlalchemy/util/langhelpers.py", line 146, in __exit__
    raise exc_value.with_traceback(exc_tb)
  File "/opt/hostedtoolcache/Python/3.9.18/x64/lib/python3.9/site-packages/sqlalchemy/pool/impl.py", line 167, in _do_get
    return self._create_connection()
  File "/opt/hostedtoolcache/Python/3.9.18/x64/lib/python3.9/site-packages/sqlalchemy/pool/base.py", line 393, in _create_connection
    return _ConnectionRecord(self)
  File "/opt/hostedtoolcache/Python/3.9.18/x64/lib/python3.9/site-packages/sqlalchemy/pool/base.py", line 678, in __init__
    self.__connect()
  File "/opt/hostedtoolcache/Python/3.9.18/x64/lib/python3.9/site-packages/sqlalchemy/pool/base.py", line 903, in __connect
    pool.logger.debug("Error on connect(): %s", e)
  File "/opt/hostedtoolcache/Python/3.9.18/x64/lib/python3.9/site-packages/sqlalchemy/util/langhelpers.py", line 146, in __exit__
    raise exc_value.with_traceback(exc_tb)
  File "/opt/hostedtoolcache/Python/3.9.18/x64/lib/python3.9/site-packages/sqlalchemy/pool/base.py", line 898, in __connect
    self.dbapi_connection = connection = pool._invoke_creator(self)
  File "/opt/hostedtoolcache/Python/3.9.18/x64/lib/python3.9/site-packages/sqlalchemy/engine/create.py", line 645, in connect
    return dialect.connect(*cargs, **cparams)
  File "/opt/hostedtoolcache/Python/3.9.18/x64/lib/python3.9/site-packages/sqlalchemy/engine/default.py", line 616, in connect
    return self.loaded_dbapi.connect(*cargs, **cparams)
sqlalchemy.exc.DBAPIError: (pyodbc.Error) ('01000', "[01000] [unixODBC][Driver Manager]Can't open lib 'ODBC Driver 18 for SQL Server' : file not found (0) (SQLDriverConnect)")
(Background on this error at: https://sqlalche.me/e/20/dbapi)
2023-12-30 23:44:44,026 - ERROR - An exception occurred: failed to get Spotify ids (Attempt 2/2)
Traceback (most recent call last):
  File "/opt/hostedtoolcache/Python/3.9.18/x64/lib/python3.9/site-packages/sqlalchemy/engine/base.py", line 145, in __init__
    self._dbapi_connection = engine.raw_connection()
  File "/opt/hostedtoolcache/Python/3.9.18/x64/lib/python3.9/site-packages/sqlalchemy/engine/base.py", line 3293, in raw_connection
    return self.pool.connect()
  File "/opt/hostedtoolcache/Python/3.9.18/x64/lib/python3.9/site-packages/sqlalchemy/pool/base.py", line 452, in connect
    return _ConnectionFairy._checkout(self)
  File "/opt/hostedtoolcache/Python/3.9.18/x64/lib/python3.9/site-packages/sqlalchemy/pool/base.py", line 1269, in _checkout
    fairy = _ConnectionRecord.checkout(pool)
  File "/opt/hostedtoolcache/Python/3.9.18/x64/lib/python3.9/site-packages/sqlalchemy/pool/base.py", line 716, in checkout
    rec = pool._do_get()
  File "/opt/hostedtoolcache/Python/3.9.18/x64/lib/python3.9/site-packages/sqlalchemy/pool/impl.py", line 170, in _do_get
    self._dec_overflow()
  File "/opt/hostedtoolcache/Python/3.9.18/x64/lib/python3.9/site-packages/sqlalchemy/util/langhelpers.py", line 146, in __exit__
    raise exc_value.with_traceback(exc_tb)
  File "/opt/hostedtoolcache/Python/3.9.18/x64/lib/python3.9/site-packages/sqlalchemy/pool/impl.py", line 167, in _do_get
    return self._create_connection()
  File "/opt/hostedtoolcache/Python/3.9.18/x64/lib/python3.9/site-packages/sqlalchemy/pool/base.py", line 393, in _create_connection
    return _ConnectionRecord(self)
  File "/opt/hostedtoolcache/Python/3.9.18/x64/lib/python3.9/site-packages/sqlalchemy/pool/base.py", line 678, in __init__
    self.__connect()
  File "/opt/hostedtoolcache/Python/3.9.18/x64/lib/python3.9/site-packages/sqlalchemy/pool/base.py", line 903, in __connect
    pool.logger.debug("Error on connect(): %s", e)
  File "/opt/hostedtoolcache/Python/3.9.18/x64/lib/python3.9/site-packages/sqlalchemy/util/langhelpers.py", line 146, in __exit__
    raise exc_value.with_traceback(exc_tb)
  File "/opt/hostedtoolcache/Python/3.9.18/x64/lib/python3.9/site-packages/sqlalchemy/pool/base.py", line 898, in __connect
    self.dbapi_connection = connection = pool._invoke_creator(self)
  File "/opt/hostedtoolcache/Python/3.9.18/x64/lib/python3.9/site-packages/sqlalchemy/engine/create.py", line 645, in connect
    return dialect.connect(*cargs, **cparams)
  File "/opt/hostedtoolcache/Python/3.9.18/x64/lib/python3.9/site-packages/sqlalchemy/engine/default.py", line 616, in connect
    return self.loaded_dbapi.connect(*cargs, **cparams)
pyodbc.Error: ('01000', "[01000] [unixODBC][Driver Manager]Can't open lib 'ODBC Driver 18 for SQL Server' : file not found (0) (SQLDriverConnect)")

The above exception was the direct cause of the following exception:

Traceback (most recent call last):
  File "/home/runner/work/spotify_daily_data_updates/spotify_daily_data_updates/main.py", line 69, in get_spotify_ids
    artist_ids = pd.read_sql(query, engine)['artist_id'].to_list()
  File "/opt/hostedtoolcache/Python/3.9.18/x64/lib/python3.9/site-packages/pandas/io/sql.py", line 652, in read_sql
    with pandasSQL_builder(con) as pandas_sql:
  File "/opt/hostedtoolcache/Python/3.9.18/x64/lib/python3.9/site-packages/pandas/io/sql.py", line 851, in pandasSQL_builder
    return SQLDatabase(con, schema, need_transaction)
  File "/opt/hostedtoolcache/Python/3.9.18/x64/lib/python3.9/site-packages/pandas/io/sql.py", line 1576, in __init__
    con = self.exit_stack.enter_context(con.connect())
  File "/opt/hostedtoolcache/Python/3.9.18/x64/lib/python3.9/site-packages/sqlalchemy/engine/base.py", line 3269, in connect
    return self._connection_cls(self)
  File "/opt/hostedtoolcache/Python/3.9.18/x64/lib/python3.9/site-packages/sqlalchemy/engine/base.py", line 147, in __init__
    Connection._handle_dbapi_exception_noconnection(
  File "/opt/hostedtoolcache/Python/3.9.18/x64/lib/python3.9/site-packages/sqlalchemy/engine/base.py", line 2431, in _handle_dbapi_exception_noconnection
    raise sqlalchemy_exception.with_traceback(exc_info[2]) from e
  File "/opt/hostedtoolcache/Python/3.9.18/x64/lib/python3.9/site-packages/sqlalchemy/engine/base.py", line 145, in __init__
    self._dbapi_connection = engine.raw_connection()
  File "/opt/hostedtoolcache/Python/3.9.18/x64/lib/python3.9/site-packages/sqlalchemy/engine/base.py", line 3293, in raw_connection
    return self.pool.connect()
  File "/opt/hostedtoolcache/Python/3.9.18/x64/lib/python3.9/site-packages/sqlalchemy/pool/base.py", line 452, in connect
    return _ConnectionFairy._checkout(self)
  File "/opt/hostedtoolcache/Python/3.9.18/x64/lib/python3.9/site-packages/sqlalchemy/pool/base.py", line 1269, in _checkout
    fairy = _ConnectionRecord.checkout(pool)
  File "/opt/hostedtoolcache/Python/3.9.18/x64/lib/python3.9/site-packages/sqlalchemy/pool/base.py", line 716, in checkout
    rec = pool._do_get()
  File "/opt/hostedtoolcache/Python/3.9.18/x64/lib/python3.9/site-packages/sqlalchemy/pool/impl.py", line 170, in _do_get
    self._dec_overflow()
  File "/opt/hostedtoolcache/Python/3.9.18/x64/lib/python3.9/site-packages/sqlalchemy/util/langhelpers.py", line 146, in __exit__
    raise exc_value.with_traceback(exc_tb)
  File "/opt/hostedtoolcache/Python/3.9.18/x64/lib/python3.9/site-packages/sqlalchemy/pool/impl.py", line 167, in _do_get
    return self._create_connection()
  File "/opt/hostedtoolcache/Python/3.9.18/x64/lib/python3.9/site-packages/sqlalchemy/pool/base.py", line 393, in _create_connection
    return _ConnectionRecord(self)
  File "/opt/hostedtoolcache/Python/3.9.18/x64/lib/python3.9/site-packages/sqlalchemy/pool/base.py", line 678, in __init__
    self.__connect()
  File "/opt/hostedtoolcache/Python/3.9.18/x64/lib/python3.9/site-packages/sqlalchemy/pool/base.py", line 903, in __connect
    pool.logger.debug("Error on connect(): %s", e)
  File "/opt/hostedtoolcache/Python/3.9.18/x64/lib/python3.9/site-packages/sqlalchemy/util/langhelpers.py", line 146, in __exit__
    raise exc_value.with_traceback(exc_tb)
  File "/opt/hostedtoolcache/Python/3.9.18/x64/lib/python3.9/site-packages/sqlalchemy/pool/base.py", line 898, in __connect
    self.dbapi_connection = connection = pool._invoke_creator(self)
  File "/opt/hostedtoolcache/Python/3.9.18/x64/lib/python3.9/site-packages/sqlalchemy/engine/create.py", line 645, in connect
    return dialect.connect(*cargs, **cparams)
  File "/opt/hostedtoolcache/Python/3.9.18/x64/lib/python3.9/site-packages/sqlalchemy/engine/default.py", line 616, in connect
    return self.loaded_dbapi.connect(*cargs, **cparams)
sqlalchemy.exc.DBAPIError: (pyodbc.Error) ('01000', "[01000] [unixODBC][Driver Manager]Can't open lib 'ODBC Driver 18 for SQL Server' : file not found (0) (SQLDriverConnect)")
(Background on this error at: https://sqlalche.me/e/20/dbapi)
2023-12-30 23:44:46,028 - ERROR - Failed to get Spotify ids  after 2 attempts.
2023-12-30 23:44:46,028 - ERROR - An exception occurred: Load data into DB
2023-12-30 23:49:43,671 - ERROR - An exception occurred: failed to get Spotify ids (Attempt 1/2)
Traceback (most recent call last):
  File "/opt/hostedtoolcache/Python/3.9.18/x64/lib/python3.9/site-packages/sqlalchemy/engine/base.py", line 145, in __init__
    self._dbapi_connection = engine.raw_connection()
  File "/opt/hostedtoolcache/Python/3.9.18/x64/lib/python3.9/site-packages/sqlalchemy/engine/base.py", line 3293, in raw_connection
    return self.pool.connect()
  File "/opt/hostedtoolcache/Python/3.9.18/x64/lib/python3.9/site-packages/sqlalchemy/pool/base.py", line 452, in connect
    return _ConnectionFairy._checkout(self)
  File "/opt/hostedtoolcache/Python/3.9.18/x64/lib/python3.9/site-packages/sqlalchemy/pool/base.py", line 1269, in _checkout
    fairy = _ConnectionRecord.checkout(pool)
  File "/opt/hostedtoolcache/Python/3.9.18/x64/lib/python3.9/site-packages/sqlalchemy/pool/base.py", line 716, in checkout
    rec = pool._do_get()
  File "/opt/hostedtoolcache/Python/3.9.18/x64/lib/python3.9/site-packages/sqlalchemy/pool/impl.py", line 170, in _do_get
    self._dec_overflow()
  File "/opt/hostedtoolcache/Python/3.9.18/x64/lib/python3.9/site-packages/sqlalchemy/util/langhelpers.py", line 146, in __exit__
    raise exc_value.with_traceback(exc_tb)
  File "/opt/hostedtoolcache/Python/3.9.18/x64/lib/python3.9/site-packages/sqlalchemy/pool/impl.py", line 167, in _do_get
    return self._create_connection()
  File "/opt/hostedtoolcache/Python/3.9.18/x64/lib/python3.9/site-packages/sqlalchemy/pool/base.py", line 393, in _create_connection
    return _ConnectionRecord(self)
  File "/opt/hostedtoolcache/Python/3.9.18/x64/lib/python3.9/site-packages/sqlalchemy/pool/base.py", line 678, in __init__
    self.__connect()
  File "/opt/hostedtoolcache/Python/3.9.18/x64/lib/python3.9/site-packages/sqlalchemy/pool/base.py", line 903, in __connect
    pool.logger.debug("Error on connect(): %s", e)
  File "/opt/hostedtoolcache/Python/3.9.18/x64/lib/python3.9/site-packages/sqlalchemy/util/langhelpers.py", line 146, in __exit__
    raise exc_value.with_traceback(exc_tb)
  File "/opt/hostedtoolcache/Python/3.9.18/x64/lib/python3.9/site-packages/sqlalchemy/pool/base.py", line 898, in __connect
    self.dbapi_connection = connection = pool._invoke_creator(self)
  File "/opt/hostedtoolcache/Python/3.9.18/x64/lib/python3.9/site-packages/sqlalchemy/engine/create.py", line 645, in connect
    return dialect.connect(*cargs, **cparams)
  File "/opt/hostedtoolcache/Python/3.9.18/x64/lib/python3.9/site-packages/sqlalchemy/engine/default.py", line 616, in connect
    return self.loaded_dbapi.connect(*cargs, **cparams)
pyodbc.OperationalError: ('HYT00', '[HYT00] [Microsoft][ODBC Driver 18 for SQL Server]Login timeout expired (0) (SQLDriverConnect)')

The above exception was the direct cause of the following exception:

Traceback (most recent call last):
  File "/home/runner/work/spotify_daily_data_updates/spotify_daily_data_updates/main.py", line 69, in get_spotify_ids
    artist_ids = pd.read_sql(query, engine)['artist_id'].to_list()
  File "/opt/hostedtoolcache/Python/3.9.18/x64/lib/python3.9/site-packages/pandas/io/sql.py", line 652, in read_sql
    with pandasSQL_builder(con) as pandas_sql:
  File "/opt/hostedtoolcache/Python/3.9.18/x64/lib/python3.9/site-packages/pandas/io/sql.py", line 851, in pandasSQL_builder
    return SQLDatabase(con, schema, need_transaction)
  File "/opt/hostedtoolcache/Python/3.9.18/x64/lib/python3.9/site-packages/pandas/io/sql.py", line 1576, in __init__
    con = self.exit_stack.enter_context(con.connect())
  File "/opt/hostedtoolcache/Python/3.9.18/x64/lib/python3.9/site-packages/sqlalchemy/engine/base.py", line 3269, in connect
    return self._connection_cls(self)
  File "/opt/hostedtoolcache/Python/3.9.18/x64/lib/python3.9/site-packages/sqlalchemy/engine/base.py", line 147, in __init__
    Connection._handle_dbapi_exception_noconnection(
  File "/opt/hostedtoolcache/Python/3.9.18/x64/lib/python3.9/site-packages/sqlalchemy/engine/base.py", line 2431, in _handle_dbapi_exception_noconnection
    raise sqlalchemy_exception.with_traceback(exc_info[2]) from e
  File "/opt/hostedtoolcache/Python/3.9.18/x64/lib/python3.9/site-packages/sqlalchemy/engine/base.py", line 145, in __init__
    self._dbapi_connection = engine.raw_connection()
  File "/opt/hostedtoolcache/Python/3.9.18/x64/lib/python3.9/site-packages/sqlalchemy/engine/base.py", line 3293, in raw_connection
    return self.pool.connect()
  File "/opt/hostedtoolcache/Python/3.9.18/x64/lib/python3.9/site-packages/sqlalchemy/pool/base.py", line 452, in connect
    return _ConnectionFairy._checkout(self)
  File "/opt/hostedtoolcache/Python/3.9.18/x64/lib/python3.9/site-packages/sqlalchemy/pool/base.py", line 1269, in _checkout
    fairy = _ConnectionRecord.checkout(pool)
  File "/opt/hostedtoolcache/Python/3.9.18/x64/lib/python3.9/site-packages/sqlalchemy/pool/base.py", line 716, in checkout
    rec = pool._do_get()
  File "/opt/hostedtoolcache/Python/3.9.18/x64/lib/python3.9/site-packages/sqlalchemy/pool/impl.py", line 170, in _do_get
    self._dec_overflow()
  File "/opt/hostedtoolcache/Python/3.9.18/x64/lib/python3.9/site-packages/sqlalchemy/util/langhelpers.py", line 146, in __exit__
    raise exc_value.with_traceback(exc_tb)
  File "/opt/hostedtoolcache/Python/3.9.18/x64/lib/python3.9/site-packages/sqlalchemy/pool/impl.py", line 167, in _do_get
    return self._create_connection()
  File "/opt/hostedtoolcache/Python/3.9.18/x64/lib/python3.9/site-packages/sqlalchemy/pool/base.py", line 393, in _create_connection
    return _ConnectionRecord(self)
  File "/opt/hostedtoolcache/Python/3.9.18/x64/lib/python3.9/site-packages/sqlalchemy/pool/base.py", line 678, in __init__
    self.__connect()
  File "/opt/hostedtoolcache/Python/3.9.18/x64/lib/python3.9/site-packages/sqlalchemy/pool/base.py", line 903, in __connect
    pool.logger.debug("Error on connect(): %s", e)
  File "/opt/hostedtoolcache/Python/3.9.18/x64/lib/python3.9/site-packages/sqlalchemy/util/langhelpers.py", line 146, in __exit__
    raise exc_value.with_traceback(exc_tb)
  File "/opt/hostedtoolcache/Python/3.9.18/x64/lib/python3.9/site-packages/sqlalchemy/pool/base.py", line 898, in __connect
    self.dbapi_connection = connection = pool._invoke_creator(self)
  File "/opt/hostedtoolcache/Python/3.9.18/x64/lib/python3.9/site-packages/sqlalchemy/engine/create.py", line 645, in connect
    return dialect.connect(*cargs, **cparams)
  File "/opt/hostedtoolcache/Python/3.9.18/x64/lib/python3.9/site-packages/sqlalchemy/engine/default.py", line 616, in connect
    return self.loaded_dbapi.connect(*cargs, **cparams)
sqlalchemy.exc.OperationalError: (pyodbc.OperationalError) ('HYT00', '[HYT00] [Microsoft][ODBC Driver 18 for SQL Server]Login timeout expired (0) (SQLDriverConnect)')
(Background on this error at: https://sqlalche.me/e/20/e3q8)
2023-12-30 23:50:01,127 - ERROR - An exception occurred: failed to get Spotify ids (Attempt 2/2)
Traceback (most recent call last):
  File "/opt/hostedtoolcache/Python/3.9.18/x64/lib/python3.9/site-packages/sqlalchemy/engine/base.py", line 145, in __init__
    self._dbapi_connection = engine.raw_connection()
  File "/opt/hostedtoolcache/Python/3.9.18/x64/lib/python3.9/site-packages/sqlalchemy/engine/base.py", line 3293, in raw_connection
    return self.pool.connect()
  File "/opt/hostedtoolcache/Python/3.9.18/x64/lib/python3.9/site-packages/sqlalchemy/pool/base.py", line 452, in connect
    return _ConnectionFairy._checkout(self)
  File "/opt/hostedtoolcache/Python/3.9.18/x64/lib/python3.9/site-packages/sqlalchemy/pool/base.py", line 1269, in _checkout
    fairy = _ConnectionRecord.checkout(pool)
  File "/opt/hostedtoolcache/Python/3.9.18/x64/lib/python3.9/site-packages/sqlalchemy/pool/base.py", line 716, in checkout
    rec = pool._do_get()
  File "/opt/hostedtoolcache/Python/3.9.18/x64/lib/python3.9/site-packages/sqlalchemy/pool/impl.py", line 170, in _do_get
    self._dec_overflow()
  File "/opt/hostedtoolcache/Python/3.9.18/x64/lib/python3.9/site-packages/sqlalchemy/util/langhelpers.py", line 146, in __exit__
    raise exc_value.with_traceback(exc_tb)
  File "/opt/hostedtoolcache/Python/3.9.18/x64/lib/python3.9/site-packages/sqlalchemy/pool/impl.py", line 167, in _do_get
    return self._create_connection()
  File "/opt/hostedtoolcache/Python/3.9.18/x64/lib/python3.9/site-packages/sqlalchemy/pool/base.py", line 393, in _create_connection
    return _ConnectionRecord(self)
  File "/opt/hostedtoolcache/Python/3.9.18/x64/lib/python3.9/site-packages/sqlalchemy/pool/base.py", line 678, in __init__
    self.__connect()
  File "/opt/hostedtoolcache/Python/3.9.18/x64/lib/python3.9/site-packages/sqlalchemy/pool/base.py", line 903, in __connect
    pool.logger.debug("Error on connect(): %s", e)
  File "/opt/hostedtoolcache/Python/3.9.18/x64/lib/python3.9/site-packages/sqlalchemy/util/langhelpers.py", line 146, in __exit__
    raise exc_value.with_traceback(exc_tb)
  File "/opt/hostedtoolcache/Python/3.9.18/x64/lib/python3.9/site-packages/sqlalchemy/pool/base.py", line 898, in __connect
    self.dbapi_connection = connection = pool._invoke_creator(self)
  File "/opt/hostedtoolcache/Python/3.9.18/x64/lib/python3.9/site-packages/sqlalchemy/engine/create.py", line 645, in connect
    return dialect.connect(*cargs, **cparams)
  File "/opt/hostedtoolcache/Python/3.9.18/x64/lib/python3.9/site-packages/sqlalchemy/engine/default.py", line 616, in connect
    return self.loaded_dbapi.connect(*cargs, **cparams)
pyodbc.OperationalError: ('HYT00', '[HYT00] [Microsoft][ODBC Driver 18 for SQL Server]Login timeout expired (0) (SQLDriverConnect)')

The above exception was the direct cause of the following exception:

Traceback (most recent call last):
  File "/home/runner/work/spotify_daily_data_updates/spotify_daily_data_updates/main.py", line 69, in get_spotify_ids
    artist_ids = pd.read_sql(query, engine)['artist_id'].to_list()
  File "/opt/hostedtoolcache/Python/3.9.18/x64/lib/python3.9/site-packages/pandas/io/sql.py", line 652, in read_sql
    with pandasSQL_builder(con) as pandas_sql:
  File "/opt/hostedtoolcache/Python/3.9.18/x64/lib/python3.9/site-packages/pandas/io/sql.py", line 851, in pandasSQL_builder
    return SQLDatabase(con, schema, need_transaction)
  File "/opt/hostedtoolcache/Python/3.9.18/x64/lib/python3.9/site-packages/pandas/io/sql.py", line 1576, in __init__
    con = self.exit_stack.enter_context(con.connect())
  File "/opt/hostedtoolcache/Python/3.9.18/x64/lib/python3.9/site-packages/sqlalchemy/engine/base.py", line 3269, in connect
    return self._connection_cls(self)
  File "/opt/hostedtoolcache/Python/3.9.18/x64/lib/python3.9/site-packages/sqlalchemy/engine/base.py", line 147, in __init__
    Connection._handle_dbapi_exception_noconnection(
  File "/opt/hostedtoolcache/Python/3.9.18/x64/lib/python3.9/site-packages/sqlalchemy/engine/base.py", line 2431, in _handle_dbapi_exception_noconnection
    raise sqlalchemy_exception.with_traceback(exc_info[2]) from e
  File "/opt/hostedtoolcache/Python/3.9.18/x64/lib/python3.9/site-packages/sqlalchemy/engine/base.py", line 145, in __init__
    self._dbapi_connection = engine.raw_connection()
  File "/opt/hostedtoolcache/Python/3.9.18/x64/lib/python3.9/site-packages/sqlalchemy/engine/base.py", line 3293, in raw_connection
    return self.pool.connect()
  File "/opt/hostedtoolcache/Python/3.9.18/x64/lib/python3.9/site-packages/sqlalchemy/pool/base.py", line 452, in connect
    return _ConnectionFairy._checkout(self)
  File "/opt/hostedtoolcache/Python/3.9.18/x64/lib/python3.9/site-packages/sqlalchemy/pool/base.py", line 1269, in _checkout
    fairy = _ConnectionRecord.checkout(pool)
  File "/opt/hostedtoolcache/Python/3.9.18/x64/lib/python3.9/site-packages/sqlalchemy/pool/base.py", line 716, in checkout
    rec = pool._do_get()
  File "/opt/hostedtoolcache/Python/3.9.18/x64/lib/python3.9/site-packages/sqlalchemy/pool/impl.py", line 170, in _do_get
    self._dec_overflow()
  File "/opt/hostedtoolcache/Python/3.9.18/x64/lib/python3.9/site-packages/sqlalchemy/util/langhelpers.py", line 146, in __exit__
    raise exc_value.with_traceback(exc_tb)
  File "/opt/hostedtoolcache/Python/3.9.18/x64/lib/python3.9/site-packages/sqlalchemy/pool/impl.py", line 167, in _do_get
    return self._create_connection()
  File "/opt/hostedtoolcache/Python/3.9.18/x64/lib/python3.9/site-packages/sqlalchemy/pool/base.py", line 393, in _create_connection
    return _ConnectionRecord(self)
  File "/opt/hostedtoolcache/Python/3.9.18/x64/lib/python3.9/site-packages/sqlalchemy/pool/base.py", line 678, in __init__
    self.__connect()
  File "/opt/hostedtoolcache/Python/3.9.18/x64/lib/python3.9/site-packages/sqlalchemy/pool/base.py", line 903, in __connect
    pool.logger.debug("Error on connect(): %s", e)
  File "/opt/hostedtoolcache/Python/3.9.18/x64/lib/python3.9/site-packages/sqlalchemy/util/langhelpers.py", line 146, in __exit__
    raise exc_value.with_traceback(exc_tb)
  File "/opt/hostedtoolcache/Python/3.9.18/x64/lib/python3.9/site-packages/sqlalchemy/pool/base.py", line 898, in __connect
    self.dbapi_connection = connection = pool._invoke_creator(self)
  File "/opt/hostedtoolcache/Python/3.9.18/x64/lib/python3.9/site-packages/sqlalchemy/engine/create.py", line 645, in connect
    return dialect.connect(*cargs, **cparams)
  File "/opt/hostedtoolcache/Python/3.9.18/x64/lib/python3.9/site-packages/sqlalchemy/engine/default.py", line 616, in connect
    return self.loaded_dbapi.connect(*cargs, **cparams)
sqlalchemy.exc.OperationalError: (pyodbc.OperationalError) ('HYT00', '[HYT00] [Microsoft][ODBC Driver 18 for SQL Server]Login timeout expired (0) (SQLDriverConnect)')
(Background on this error at: https://sqlalche.me/e/20/e3q8)
2023-12-30 23:50:03,130 - ERROR - Failed to get Spotify ids  after 2 attempts.
2023-12-30 23:50:03,130 - ERROR - An exception occurred: Load data into DB
2023-12-31 01:55:49,191 - ERROR - An exception occurred: failed to get Spotify ids (Attempt 1/2)
Traceback (most recent call last):
  File "/opt/hostedtoolcache/Python/3.9.18/x64/lib/python3.9/site-packages/sqlalchemy/engine/base.py", line 145, in __init__
    self._dbapi_connection = engine.raw_connection()
  File "/opt/hostedtoolcache/Python/3.9.18/x64/lib/python3.9/site-packages/sqlalchemy/engine/base.py", line 3293, in raw_connection
    return self.pool.connect()
  File "/opt/hostedtoolcache/Python/3.9.18/x64/lib/python3.9/site-packages/sqlalchemy/pool/base.py", line 452, in connect
    return _ConnectionFairy._checkout(self)
  File "/opt/hostedtoolcache/Python/3.9.18/x64/lib/python3.9/site-packages/sqlalchemy/pool/base.py", line 1269, in _checkout
    fairy = _ConnectionRecord.checkout(pool)
  File "/opt/hostedtoolcache/Python/3.9.18/x64/lib/python3.9/site-packages/sqlalchemy/pool/base.py", line 716, in checkout
    rec = pool._do_get()
  File "/opt/hostedtoolcache/Python/3.9.18/x64/lib/python3.9/site-packages/sqlalchemy/pool/impl.py", line 170, in _do_get
    self._dec_overflow()
  File "/opt/hostedtoolcache/Python/3.9.18/x64/lib/python3.9/site-packages/sqlalchemy/util/langhelpers.py", line 146, in __exit__
    raise exc_value.with_traceback(exc_tb)
  File "/opt/hostedtoolcache/Python/3.9.18/x64/lib/python3.9/site-packages/sqlalchemy/pool/impl.py", line 167, in _do_get
    return self._create_connection()
  File "/opt/hostedtoolcache/Python/3.9.18/x64/lib/python3.9/site-packages/sqlalchemy/pool/base.py", line 393, in _create_connection
    return _ConnectionRecord(self)
  File "/opt/hostedtoolcache/Python/3.9.18/x64/lib/python3.9/site-packages/sqlalchemy/pool/base.py", line 678, in __init__
    self.__connect()
  File "/opt/hostedtoolcache/Python/3.9.18/x64/lib/python3.9/site-packages/sqlalchemy/pool/base.py", line 903, in __connect
    pool.logger.debug("Error on connect(): %s", e)
  File "/opt/hostedtoolcache/Python/3.9.18/x64/lib/python3.9/site-packages/sqlalchemy/util/langhelpers.py", line 146, in __exit__
    raise exc_value.with_traceback(exc_tb)
  File "/opt/hostedtoolcache/Python/3.9.18/x64/lib/python3.9/site-packages/sqlalchemy/pool/base.py", line 898, in __connect
    self.dbapi_connection = connection = pool._invoke_creator(self)
  File "/opt/hostedtoolcache/Python/3.9.18/x64/lib/python3.9/site-packages/sqlalchemy/engine/create.py", line 645, in connect
    return dialect.connect(*cargs, **cparams)
  File "/opt/hostedtoolcache/Python/3.9.18/x64/lib/python3.9/site-packages/sqlalchemy/engine/default.py", line 616, in connect
    return self.loaded_dbapi.connect(*cargs, **cparams)
pyodbc.OperationalError: ('HYT00', '[HYT00] [Microsoft][ODBC Driver 18 for SQL Server]Login timeout expired (0) (SQLDriverConnect)')

The above exception was the direct cause of the following exception:

Traceback (most recent call last):
  File "/home/runner/work/spotify_daily_data_updates/spotify_daily_data_updates/main.py", line 69, in get_spotify_ids
    artist_ids = pd.read_sql(query, engine)['artist_id'].to_list()
  File "/opt/hostedtoolcache/Python/3.9.18/x64/lib/python3.9/site-packages/pandas/io/sql.py", line 652, in read_sql
    with pandasSQL_builder(con) as pandas_sql:
  File "/opt/hostedtoolcache/Python/3.9.18/x64/lib/python3.9/site-packages/pandas/io/sql.py", line 851, in pandasSQL_builder
    return SQLDatabase(con, schema, need_transaction)
  File "/opt/hostedtoolcache/Python/3.9.18/x64/lib/python3.9/site-packages/pandas/io/sql.py", line 1576, in __init__
    con = self.exit_stack.enter_context(con.connect())
  File "/opt/hostedtoolcache/Python/3.9.18/x64/lib/python3.9/site-packages/sqlalchemy/engine/base.py", line 3269, in connect
    return self._connection_cls(self)
  File "/opt/hostedtoolcache/Python/3.9.18/x64/lib/python3.9/site-packages/sqlalchemy/engine/base.py", line 147, in __init__
    Connection._handle_dbapi_exception_noconnection(
  File "/opt/hostedtoolcache/Python/3.9.18/x64/lib/python3.9/site-packages/sqlalchemy/engine/base.py", line 2431, in _handle_dbapi_exception_noconnection
    raise sqlalchemy_exception.with_traceback(exc_info[2]) from e
  File "/opt/hostedtoolcache/Python/3.9.18/x64/lib/python3.9/site-packages/sqlalchemy/engine/base.py", line 145, in __init__
    self._dbapi_connection = engine.raw_connection()
  File "/opt/hostedtoolcache/Python/3.9.18/x64/lib/python3.9/site-packages/sqlalchemy/engine/base.py", line 3293, in raw_connection
    return self.pool.connect()
  File "/opt/hostedtoolcache/Python/3.9.18/x64/lib/python3.9/site-packages/sqlalchemy/pool/base.py", line 452, in connect
    return _ConnectionFairy._checkout(self)
  File "/opt/hostedtoolcache/Python/3.9.18/x64/lib/python3.9/site-packages/sqlalchemy/pool/base.py", line 1269, in _checkout
    fairy = _ConnectionRecord.checkout(pool)
  File "/opt/hostedtoolcache/Python/3.9.18/x64/lib/python3.9/site-packages/sqlalchemy/pool/base.py", line 716, in checkout
    rec = pool._do_get()
  File "/opt/hostedtoolcache/Python/3.9.18/x64/lib/python3.9/site-packages/sqlalchemy/pool/impl.py", line 170, in _do_get
    self._dec_overflow()
  File "/opt/hostedtoolcache/Python/3.9.18/x64/lib/python3.9/site-packages/sqlalchemy/util/langhelpers.py", line 146, in __exit__
    raise exc_value.with_traceback(exc_tb)
  File "/opt/hostedtoolcache/Python/3.9.18/x64/lib/python3.9/site-packages/sqlalchemy/pool/impl.py", line 167, in _do_get
    return self._create_connection()
  File "/opt/hostedtoolcache/Python/3.9.18/x64/lib/python3.9/site-packages/sqlalchemy/pool/base.py", line 393, in _create_connection
    return _ConnectionRecord(self)
  File "/opt/hostedtoolcache/Python/3.9.18/x64/lib/python3.9/site-packages/sqlalchemy/pool/base.py", line 678, in __init__
    self.__connect()
  File "/opt/hostedtoolcache/Python/3.9.18/x64/lib/python3.9/site-packages/sqlalchemy/pool/base.py", line 903, in __connect
    pool.logger.debug("Error on connect(): %s", e)
  File "/opt/hostedtoolcache/Python/3.9.18/x64/lib/python3.9/site-packages/sqlalchemy/util/langhelpers.py", line 146, in __exit__
    raise exc_value.with_traceback(exc_tb)
  File "/opt/hostedtoolcache/Python/3.9.18/x64/lib/python3.9/site-packages/sqlalchemy/pool/base.py", line 898, in __connect
    self.dbapi_connection = connection = pool._invoke_creator(self)
  File "/opt/hostedtoolcache/Python/3.9.18/x64/lib/python3.9/site-packages/sqlalchemy/engine/create.py", line 645, in connect
    return dialect.connect(*cargs, **cparams)
  File "/opt/hostedtoolcache/Python/3.9.18/x64/lib/python3.9/site-packages/sqlalchemy/engine/default.py", line 616, in connect
    return self.loaded_dbapi.connect(*cargs, **cparams)
sqlalchemy.exc.OperationalError: (pyodbc.OperationalError) ('HYT00', '[HYT00] [Microsoft][ODBC Driver 18 for SQL Server]Login timeout expired (0) (SQLDriverConnect)')
(Background on this error at: https://sqlalche.me/e/20/e3q8)
2023-12-31 01:56:06,658 - ERROR - An exception occurred: failed to get Spotify ids (Attempt 2/2)
Traceback (most recent call last):
  File "/opt/hostedtoolcache/Python/3.9.18/x64/lib/python3.9/site-packages/sqlalchemy/engine/base.py", line 145, in __init__
    self._dbapi_connection = engine.raw_connection()
  File "/opt/hostedtoolcache/Python/3.9.18/x64/lib/python3.9/site-packages/sqlalchemy/engine/base.py", line 3293, in raw_connection
    return self.pool.connect()
  File "/opt/hostedtoolcache/Python/3.9.18/x64/lib/python3.9/site-packages/sqlalchemy/pool/base.py", line 452, in connect
    return _ConnectionFairy._checkout(self)
  File "/opt/hostedtoolcache/Python/3.9.18/x64/lib/python3.9/site-packages/sqlalchemy/pool/base.py", line 1269, in _checkout
    fairy = _ConnectionRecord.checkout(pool)
  File "/opt/hostedtoolcache/Python/3.9.18/x64/lib/python3.9/site-packages/sqlalchemy/pool/base.py", line 716, in checkout
    rec = pool._do_get()
  File "/opt/hostedtoolcache/Python/3.9.18/x64/lib/python3.9/site-packages/sqlalchemy/pool/impl.py", line 170, in _do_get
    self._dec_overflow()
  File "/opt/hostedtoolcache/Python/3.9.18/x64/lib/python3.9/site-packages/sqlalchemy/util/langhelpers.py", line 146, in __exit__
    raise exc_value.with_traceback(exc_tb)
  File "/opt/hostedtoolcache/Python/3.9.18/x64/lib/python3.9/site-packages/sqlalchemy/pool/impl.py", line 167, in _do_get
    return self._create_connection()
  File "/opt/hostedtoolcache/Python/3.9.18/x64/lib/python3.9/site-packages/sqlalchemy/pool/base.py", line 393, in _create_connection
    return _ConnectionRecord(self)
  File "/opt/hostedtoolcache/Python/3.9.18/x64/lib/python3.9/site-packages/sqlalchemy/pool/base.py", line 678, in __init__
    self.__connect()
  File "/opt/hostedtoolcache/Python/3.9.18/x64/lib/python3.9/site-packages/sqlalchemy/pool/base.py", line 903, in __connect
    pool.logger.debug("Error on connect(): %s", e)
  File "/opt/hostedtoolcache/Python/3.9.18/x64/lib/python3.9/site-packages/sqlalchemy/util/langhelpers.py", line 146, in __exit__
    raise exc_value.with_traceback(exc_tb)
  File "/opt/hostedtoolcache/Python/3.9.18/x64/lib/python3.9/site-packages/sqlalchemy/pool/base.py", line 898, in __connect
    self.dbapi_connection = connection = pool._invoke_creator(self)
  File "/opt/hostedtoolcache/Python/3.9.18/x64/lib/python3.9/site-packages/sqlalchemy/engine/create.py", line 645, in connect
    return dialect.connect(*cargs, **cparams)
  File "/opt/hostedtoolcache/Python/3.9.18/x64/lib/python3.9/site-packages/sqlalchemy/engine/default.py", line 616, in connect
    return self.loaded_dbapi.connect(*cargs, **cparams)
pyodbc.OperationalError: ('HYT00', '[HYT00] [Microsoft][ODBC Driver 18 for SQL Server]Login timeout expired (0) (SQLDriverConnect)')

The above exception was the direct cause of the following exception:

Traceback (most recent call last):
  File "/home/runner/work/spotify_daily_data_updates/spotify_daily_data_updates/main.py", line 69, in get_spotify_ids
    artist_ids = pd.read_sql(query, engine)['artist_id'].to_list()
  File "/opt/hostedtoolcache/Python/3.9.18/x64/lib/python3.9/site-packages/pandas/io/sql.py", line 652, in read_sql
    with pandasSQL_builder(con) as pandas_sql:
  File "/opt/hostedtoolcache/Python/3.9.18/x64/lib/python3.9/site-packages/pandas/io/sql.py", line 851, in pandasSQL_builder
    return SQLDatabase(con, schema, need_transaction)
  File "/opt/hostedtoolcache/Python/3.9.18/x64/lib/python3.9/site-packages/pandas/io/sql.py", line 1576, in __init__
    con = self.exit_stack.enter_context(con.connect())
  File "/opt/hostedtoolcache/Python/3.9.18/x64/lib/python3.9/site-packages/sqlalchemy/engine/base.py", line 3269, in connect
    return self._connection_cls(self)
  File "/opt/hostedtoolcache/Python/3.9.18/x64/lib/python3.9/site-packages/sqlalchemy/engine/base.py", line 147, in __init__
    Connection._handle_dbapi_exception_noconnection(
  File "/opt/hostedtoolcache/Python/3.9.18/x64/lib/python3.9/site-packages/sqlalchemy/engine/base.py", line 2431, in _handle_dbapi_exception_noconnection
    raise sqlalchemy_exception.with_traceback(exc_info[2]) from e
  File "/opt/hostedtoolcache/Python/3.9.18/x64/lib/python3.9/site-packages/sqlalchemy/engine/base.py", line 145, in __init__
    self._dbapi_connection = engine.raw_connection()
  File "/opt/hostedtoolcache/Python/3.9.18/x64/lib/python3.9/site-packages/sqlalchemy/engine/base.py", line 3293, in raw_connection
    return self.pool.connect()
  File "/opt/hostedtoolcache/Python/3.9.18/x64/lib/python3.9/site-packages/sqlalchemy/pool/base.py", line 452, in connect
    return _ConnectionFairy._checkout(self)
  File "/opt/hostedtoolcache/Python/3.9.18/x64/lib/python3.9/site-packages/sqlalchemy/pool/base.py", line 1269, in _checkout
    fairy = _ConnectionRecord.checkout(pool)
  File "/opt/hostedtoolcache/Python/3.9.18/x64/lib/python3.9/site-packages/sqlalchemy/pool/base.py", line 716, in checkout
    rec = pool._do_get()
  File "/opt/hostedtoolcache/Python/3.9.18/x64/lib/python3.9/site-packages/sqlalchemy/pool/impl.py", line 170, in _do_get
    self._dec_overflow()
  File "/opt/hostedtoolcache/Python/3.9.18/x64/lib/python3.9/site-packages/sqlalchemy/util/langhelpers.py", line 146, in __exit__
    raise exc_value.with_traceback(exc_tb)
  File "/opt/hostedtoolcache/Python/3.9.18/x64/lib/python3.9/site-packages/sqlalchemy/pool/impl.py", line 167, in _do_get
    return self._create_connection()
  File "/opt/hostedtoolcache/Python/3.9.18/x64/lib/python3.9/site-packages/sqlalchemy/pool/base.py", line 393, in _create_connection
    return _ConnectionRecord(self)
  File "/opt/hostedtoolcache/Python/3.9.18/x64/lib/python3.9/site-packages/sqlalchemy/pool/base.py", line 678, in __init__
    self.__connect()
  File "/opt/hostedtoolcache/Python/3.9.18/x64/lib/python3.9/site-packages/sqlalchemy/pool/base.py", line 903, in __connect
    pool.logger.debug("Error on connect(): %s", e)
  File "/opt/hostedtoolcache/Python/3.9.18/x64/lib/python3.9/site-packages/sqlalchemy/util/langhelpers.py", line 146, in __exit__
    raise exc_value.with_traceback(exc_tb)
  File "/opt/hostedtoolcache/Python/3.9.18/x64/lib/python3.9/site-packages/sqlalchemy/pool/base.py", line 898, in __connect
    self.dbapi_connection = connection = pool._invoke_creator(self)
  File "/opt/hostedtoolcache/Python/3.9.18/x64/lib/python3.9/site-packages/sqlalchemy/engine/create.py", line 645, in connect
    return dialect.connect(*cargs, **cparams)
  File "/opt/hostedtoolcache/Python/3.9.18/x64/lib/python3.9/site-packages/sqlalchemy/engine/default.py", line 616, in connect
    return self.loaded_dbapi.connect(*cargs, **cparams)
sqlalchemy.exc.OperationalError: (pyodbc.OperationalError) ('HYT00', '[HYT00] [Microsoft][ODBC Driver 18 for SQL Server]Login timeout expired (0) (SQLDriverConnect)')
(Background on this error at: https://sqlalche.me/e/20/e3q8)
2023-12-31 01:56:08,661 - ERROR - Failed to get Spotify ids  after 2 attempts.
2023-12-31 01:56:08,661 - ERROR - An exception occurred: Load data into DB
2023-12-31 15:02:11,730 - ERROR - An exception occurred: failed to get Spotify ids (Attempt 1/2)
Traceback (most recent call last):
  File "/opt/hostedtoolcache/Python/3.9.18/x64/lib/python3.9/site-packages/sqlalchemy/engine/base.py", line 145, in __init__
    self._dbapi_connection = engine.raw_connection()
  File "/opt/hostedtoolcache/Python/3.9.18/x64/lib/python3.9/site-packages/sqlalchemy/engine/base.py", line 3293, in raw_connection
    return self.pool.connect()
  File "/opt/hostedtoolcache/Python/3.9.18/x64/lib/python3.9/site-packages/sqlalchemy/pool/base.py", line 452, in connect
    return _ConnectionFairy._checkout(self)
  File "/opt/hostedtoolcache/Python/3.9.18/x64/lib/python3.9/site-packages/sqlalchemy/pool/base.py", line 1269, in _checkout
    fairy = _ConnectionRecord.checkout(pool)
  File "/opt/hostedtoolcache/Python/3.9.18/x64/lib/python3.9/site-packages/sqlalchemy/pool/base.py", line 716, in checkout
    rec = pool._do_get()
  File "/opt/hostedtoolcache/Python/3.9.18/x64/lib/python3.9/site-packages/sqlalchemy/pool/impl.py", line 170, in _do_get
    self._dec_overflow()
  File "/opt/hostedtoolcache/Python/3.9.18/x64/lib/python3.9/site-packages/sqlalchemy/util/langhelpers.py", line 146, in __exit__
    raise exc_value.with_traceback(exc_tb)
  File "/opt/hostedtoolcache/Python/3.9.18/x64/lib/python3.9/site-packages/sqlalchemy/pool/impl.py", line 167, in _do_get
    return self._create_connection()
  File "/opt/hostedtoolcache/Python/3.9.18/x64/lib/python3.9/site-packages/sqlalchemy/pool/base.py", line 393, in _create_connection
    return _ConnectionRecord(self)
  File "/opt/hostedtoolcache/Python/3.9.18/x64/lib/python3.9/site-packages/sqlalchemy/pool/base.py", line 678, in __init__
    self.__connect()
  File "/opt/hostedtoolcache/Python/3.9.18/x64/lib/python3.9/site-packages/sqlalchemy/pool/base.py", line 903, in __connect
    pool.logger.debug("Error on connect(): %s", e)
  File "/opt/hostedtoolcache/Python/3.9.18/x64/lib/python3.9/site-packages/sqlalchemy/util/langhelpers.py", line 146, in __exit__
    raise exc_value.with_traceback(exc_tb)
  File "/opt/hostedtoolcache/Python/3.9.18/x64/lib/python3.9/site-packages/sqlalchemy/pool/base.py", line 898, in __connect
    self.dbapi_connection = connection = pool._invoke_creator(self)
  File "/opt/hostedtoolcache/Python/3.9.18/x64/lib/python3.9/site-packages/sqlalchemy/engine/create.py", line 645, in connect
    return dialect.connect(*cargs, **cparams)
  File "/opt/hostedtoolcache/Python/3.9.18/x64/lib/python3.9/site-packages/sqlalchemy/engine/default.py", line 616, in connect
    return self.loaded_dbapi.connect(*cargs, **cparams)
pyodbc.OperationalError: ('HYT00', '[HYT00] [Microsoft][ODBC Driver 18 for SQL Server]Login timeout expired (0) (SQLDriverConnect)')

The above exception was the direct cause of the following exception:

Traceback (most recent call last):
  File "/home/runner/work/spotify_daily_data_updates/spotify_daily_data_updates/main.py", line 71, in get_spotify_ids
    artist_ids = pd.read_sql(query, engine)['artist_id'].to_list()
  File "/opt/hostedtoolcache/Python/3.9.18/x64/lib/python3.9/site-packages/pandas/io/sql.py", line 652, in read_sql
    with pandasSQL_builder(con) as pandas_sql:
  File "/opt/hostedtoolcache/Python/3.9.18/x64/lib/python3.9/site-packages/pandas/io/sql.py", line 851, in pandasSQL_builder
    return SQLDatabase(con, schema, need_transaction)
  File "/opt/hostedtoolcache/Python/3.9.18/x64/lib/python3.9/site-packages/pandas/io/sql.py", line 1576, in __init__
    con = self.exit_stack.enter_context(con.connect())
  File "/opt/hostedtoolcache/Python/3.9.18/x64/lib/python3.9/site-packages/sqlalchemy/engine/base.py", line 3269, in connect
    return self._connection_cls(self)
  File "/opt/hostedtoolcache/Python/3.9.18/x64/lib/python3.9/site-packages/sqlalchemy/engine/base.py", line 147, in __init__
    Connection._handle_dbapi_exception_noconnection(
  File "/opt/hostedtoolcache/Python/3.9.18/x64/lib/python3.9/site-packages/sqlalchemy/engine/base.py", line 2431, in _handle_dbapi_exception_noconnection
    raise sqlalchemy_exception.with_traceback(exc_info[2]) from e
  File "/opt/hostedtoolcache/Python/3.9.18/x64/lib/python3.9/site-packages/sqlalchemy/engine/base.py", line 145, in __init__
    self._dbapi_connection = engine.raw_connection()
  File "/opt/hostedtoolcache/Python/3.9.18/x64/lib/python3.9/site-packages/sqlalchemy/engine/base.py", line 3293, in raw_connection
    return self.pool.connect()
  File "/opt/hostedtoolcache/Python/3.9.18/x64/lib/python3.9/site-packages/sqlalchemy/pool/base.py", line 452, in connect
    return _ConnectionFairy._checkout(self)
  File "/opt/hostedtoolcache/Python/3.9.18/x64/lib/python3.9/site-packages/sqlalchemy/pool/base.py", line 1269, in _checkout
    fairy = _ConnectionRecord.checkout(pool)
  File "/opt/hostedtoolcache/Python/3.9.18/x64/lib/python3.9/site-packages/sqlalchemy/pool/base.py", line 716, in checkout
    rec = pool._do_get()
  File "/opt/hostedtoolcache/Python/3.9.18/x64/lib/python3.9/site-packages/sqlalchemy/pool/impl.py", line 170, in _do_get
    self._dec_overflow()
  File "/opt/hostedtoolcache/Python/3.9.18/x64/lib/python3.9/site-packages/sqlalchemy/util/langhelpers.py", line 146, in __exit__
    raise exc_value.with_traceback(exc_tb)
  File "/opt/hostedtoolcache/Python/3.9.18/x64/lib/python3.9/site-packages/sqlalchemy/pool/impl.py", line 167, in _do_get
    return self._create_connection()
  File "/opt/hostedtoolcache/Python/3.9.18/x64/lib/python3.9/site-packages/sqlalchemy/pool/base.py", line 393, in _create_connection
    return _ConnectionRecord(self)
  File "/opt/hostedtoolcache/Python/3.9.18/x64/lib/python3.9/site-packages/sqlalchemy/pool/base.py", line 678, in __init__
    self.__connect()
  File "/opt/hostedtoolcache/Python/3.9.18/x64/lib/python3.9/site-packages/sqlalchemy/pool/base.py", line 903, in __connect
    pool.logger.debug("Error on connect(): %s", e)
  File "/opt/hostedtoolcache/Python/3.9.18/x64/lib/python3.9/site-packages/sqlalchemy/util/langhelpers.py", line 146, in __exit__
    raise exc_value.with_traceback(exc_tb)
  File "/opt/hostedtoolcache/Python/3.9.18/x64/lib/python3.9/site-packages/sqlalchemy/pool/base.py", line 898, in __connect
    self.dbapi_connection = connection = pool._invoke_creator(self)
  File "/opt/hostedtoolcache/Python/3.9.18/x64/lib/python3.9/site-packages/sqlalchemy/engine/create.py", line 645, in connect
    return dialect.connect(*cargs, **cparams)
  File "/opt/hostedtoolcache/Python/3.9.18/x64/lib/python3.9/site-packages/sqlalchemy/engine/default.py", line 616, in connect
    return self.loaded_dbapi.connect(*cargs, **cparams)
sqlalchemy.exc.OperationalError: (pyodbc.OperationalError) ('HYT00', '[HYT00] [Microsoft][ODBC Driver 18 for SQL Server]Login timeout expired (0) (SQLDriverConnect)')
(Background on this error at: https://sqlalche.me/e/20/e3q8)
2023-12-31 15:02:28,850 - ERROR - An exception occurred: failed to get Spotify ids (Attempt 2/2)
Traceback (most recent call last):
  File "/opt/hostedtoolcache/Python/3.9.18/x64/lib/python3.9/site-packages/sqlalchemy/engine/base.py", line 145, in __init__
    self._dbapi_connection = engine.raw_connection()
  File "/opt/hostedtoolcache/Python/3.9.18/x64/lib/python3.9/site-packages/sqlalchemy/engine/base.py", line 3293, in raw_connection
    return self.pool.connect()
  File "/opt/hostedtoolcache/Python/3.9.18/x64/lib/python3.9/site-packages/sqlalchemy/pool/base.py", line 452, in connect
    return _ConnectionFairy._checkout(self)
  File "/opt/hostedtoolcache/Python/3.9.18/x64/lib/python3.9/site-packages/sqlalchemy/pool/base.py", line 1269, in _checkout
    fairy = _ConnectionRecord.checkout(pool)
  File "/opt/hostedtoolcache/Python/3.9.18/x64/lib/python3.9/site-packages/sqlalchemy/pool/base.py", line 716, in checkout
    rec = pool._do_get()
  File "/opt/hostedtoolcache/Python/3.9.18/x64/lib/python3.9/site-packages/sqlalchemy/pool/impl.py", line 170, in _do_get
    self._dec_overflow()
  File "/opt/hostedtoolcache/Python/3.9.18/x64/lib/python3.9/site-packages/sqlalchemy/util/langhelpers.py", line 146, in __exit__
    raise exc_value.with_traceback(exc_tb)
  File "/opt/hostedtoolcache/Python/3.9.18/x64/lib/python3.9/site-packages/sqlalchemy/pool/impl.py", line 167, in _do_get
    return self._create_connection()
  File "/opt/hostedtoolcache/Python/3.9.18/x64/lib/python3.9/site-packages/sqlalchemy/pool/base.py", line 393, in _create_connection
    return _ConnectionRecord(self)
  File "/opt/hostedtoolcache/Python/3.9.18/x64/lib/python3.9/site-packages/sqlalchemy/pool/base.py", line 678, in __init__
    self.__connect()
  File "/opt/hostedtoolcache/Python/3.9.18/x64/lib/python3.9/site-packages/sqlalchemy/pool/base.py", line 903, in __connect
    pool.logger.debug("Error on connect(): %s", e)
  File "/opt/hostedtoolcache/Python/3.9.18/x64/lib/python3.9/site-packages/sqlalchemy/util/langhelpers.py", line 146, in __exit__
    raise exc_value.with_traceback(exc_tb)
  File "/opt/hostedtoolcache/Python/3.9.18/x64/lib/python3.9/site-packages/sqlalchemy/pool/base.py", line 898, in __connect
    self.dbapi_connection = connection = pool._invoke_creator(self)
  File "/opt/hostedtoolcache/Python/3.9.18/x64/lib/python3.9/site-packages/sqlalchemy/engine/create.py", line 645, in connect
    return dialect.connect(*cargs, **cparams)
  File "/opt/hostedtoolcache/Python/3.9.18/x64/lib/python3.9/site-packages/sqlalchemy/engine/default.py", line 616, in connect
    return self.loaded_dbapi.connect(*cargs, **cparams)
pyodbc.OperationalError: ('HYT00', '[HYT00] [Microsoft][ODBC Driver 18 for SQL Server]Login timeout expired (0) (SQLDriverConnect)')

The above exception was the direct cause of the following exception:

Traceback (most recent call last):
  File "/home/runner/work/spotify_daily_data_updates/spotify_daily_data_updates/main.py", line 71, in get_spotify_ids
    artist_ids = pd.read_sql(query, engine)['artist_id'].to_list()
  File "/opt/hostedtoolcache/Python/3.9.18/x64/lib/python3.9/site-packages/pandas/io/sql.py", line 652, in read_sql
    with pandasSQL_builder(con) as pandas_sql:
  File "/opt/hostedtoolcache/Python/3.9.18/x64/lib/python3.9/site-packages/pandas/io/sql.py", line 851, in pandasSQL_builder
    return SQLDatabase(con, schema, need_transaction)
  File "/opt/hostedtoolcache/Python/3.9.18/x64/lib/python3.9/site-packages/pandas/io/sql.py", line 1576, in __init__
    con = self.exit_stack.enter_context(con.connect())
  File "/opt/hostedtoolcache/Python/3.9.18/x64/lib/python3.9/site-packages/sqlalchemy/engine/base.py", line 3269, in connect
    return self._connection_cls(self)
  File "/opt/hostedtoolcache/Python/3.9.18/x64/lib/python3.9/site-packages/sqlalchemy/engine/base.py", line 147, in __init__
    Connection._handle_dbapi_exception_noconnection(
  File "/opt/hostedtoolcache/Python/3.9.18/x64/lib/python3.9/site-packages/sqlalchemy/engine/base.py", line 2431, in _handle_dbapi_exception_noconnection
    raise sqlalchemy_exception.with_traceback(exc_info[2]) from e
  File "/opt/hostedtoolcache/Python/3.9.18/x64/lib/python3.9/site-packages/sqlalchemy/engine/base.py", line 145, in __init__
    self._dbapi_connection = engine.raw_connection()
  File "/opt/hostedtoolcache/Python/3.9.18/x64/lib/python3.9/site-packages/sqlalchemy/engine/base.py", line 3293, in raw_connection
    return self.pool.connect()
  File "/opt/hostedtoolcache/Python/3.9.18/x64/lib/python3.9/site-packages/sqlalchemy/pool/base.py", line 452, in connect
    return _ConnectionFairy._checkout(self)
  File "/opt/hostedtoolcache/Python/3.9.18/x64/lib/python3.9/site-packages/sqlalchemy/pool/base.py", line 1269, in _checkout
    fairy = _ConnectionRecord.checkout(pool)
  File "/opt/hostedtoolcache/Python/3.9.18/x64/lib/python3.9/site-packages/sqlalchemy/pool/base.py", line 716, in checkout
    rec = pool._do_get()
  File "/opt/hostedtoolcache/Python/3.9.18/x64/lib/python3.9/site-packages/sqlalchemy/pool/impl.py", line 170, in _do_get
    self._dec_overflow()
  File "/opt/hostedtoolcache/Python/3.9.18/x64/lib/python3.9/site-packages/sqlalchemy/util/langhelpers.py", line 146, in __exit__
    raise exc_value.with_traceback(exc_tb)
  File "/opt/hostedtoolcache/Python/3.9.18/x64/lib/python3.9/site-packages/sqlalchemy/pool/impl.py", line 167, in _do_get
    return self._create_connection()
  File "/opt/hostedtoolcache/Python/3.9.18/x64/lib/python3.9/site-packages/sqlalchemy/pool/base.py", line 393, in _create_connection
    return _ConnectionRecord(self)
  File "/opt/hostedtoolcache/Python/3.9.18/x64/lib/python3.9/site-packages/sqlalchemy/pool/base.py", line 678, in __init__
    self.__connect()
  File "/opt/hostedtoolcache/Python/3.9.18/x64/lib/python3.9/site-packages/sqlalchemy/pool/base.py", line 903, in __connect
    pool.logger.debug("Error on connect(): %s", e)
  File "/opt/hostedtoolcache/Python/3.9.18/x64/lib/python3.9/site-packages/sqlalchemy/util/langhelpers.py", line 146, in __exit__
    raise exc_value.with_traceback(exc_tb)
  File "/opt/hostedtoolcache/Python/3.9.18/x64/lib/python3.9/site-packages/sqlalchemy/pool/base.py", line 898, in __connect
    self.dbapi_connection = connection = pool._invoke_creator(self)
  File "/opt/hostedtoolcache/Python/3.9.18/x64/lib/python3.9/site-packages/sqlalchemy/engine/create.py", line 645, in connect
    return dialect.connect(*cargs, **cparams)
  File "/opt/hostedtoolcache/Python/3.9.18/x64/lib/python3.9/site-packages/sqlalchemy/engine/default.py", line 616, in connect
    return self.loaded_dbapi.connect(*cargs, **cparams)
sqlalchemy.exc.OperationalError: (pyodbc.OperationalError) ('HYT00', '[HYT00] [Microsoft][ODBC Driver 18 for SQL Server]Login timeout expired (0) (SQLDriverConnect)')
(Background on this error at: https://sqlalche.me/e/20/e3q8)
2023-12-31 15:02:30,852 - ERROR - Failed to get Spotify ids  after 2 attempts.
2023-12-31 15:02:30,852 - ERROR - An exception occurred: Load data into DB
2023-12-31 15:05:20,106 - ERROR - An exception occurred: failed to get Spotify ids (Attempt 1/2)
Traceback (most recent call last):
  File "/opt/hostedtoolcache/Python/3.9.18/x64/lib/python3.9/site-packages/sqlalchemy/engine/base.py", line 145, in __init__
    self._dbapi_connection = engine.raw_connection()
  File "/opt/hostedtoolcache/Python/3.9.18/x64/lib/python3.9/site-packages/sqlalchemy/engine/base.py", line 3293, in raw_connection
    return self.pool.connect()
  File "/opt/hostedtoolcache/Python/3.9.18/x64/lib/python3.9/site-packages/sqlalchemy/pool/base.py", line 452, in connect
    return _ConnectionFairy._checkout(self)
  File "/opt/hostedtoolcache/Python/3.9.18/x64/lib/python3.9/site-packages/sqlalchemy/pool/base.py", line 1269, in _checkout
    fairy = _ConnectionRecord.checkout(pool)
  File "/opt/hostedtoolcache/Python/3.9.18/x64/lib/python3.9/site-packages/sqlalchemy/pool/base.py", line 716, in checkout
    rec = pool._do_get()
  File "/opt/hostedtoolcache/Python/3.9.18/x64/lib/python3.9/site-packages/sqlalchemy/pool/impl.py", line 170, in _do_get
    self._dec_overflow()
  File "/opt/hostedtoolcache/Python/3.9.18/x64/lib/python3.9/site-packages/sqlalchemy/util/langhelpers.py", line 146, in __exit__
    raise exc_value.with_traceback(exc_tb)
  File "/opt/hostedtoolcache/Python/3.9.18/x64/lib/python3.9/site-packages/sqlalchemy/pool/impl.py", line 167, in _do_get
    return self._create_connection()
  File "/opt/hostedtoolcache/Python/3.9.18/x64/lib/python3.9/site-packages/sqlalchemy/pool/base.py", line 393, in _create_connection
    return _ConnectionRecord(self)
  File "/opt/hostedtoolcache/Python/3.9.18/x64/lib/python3.9/site-packages/sqlalchemy/pool/base.py", line 678, in __init__
    self.__connect()
  File "/opt/hostedtoolcache/Python/3.9.18/x64/lib/python3.9/site-packages/sqlalchemy/pool/base.py", line 903, in __connect
    pool.logger.debug("Error on connect(): %s", e)
  File "/opt/hostedtoolcache/Python/3.9.18/x64/lib/python3.9/site-packages/sqlalchemy/util/langhelpers.py", line 146, in __exit__
    raise exc_value.with_traceback(exc_tb)
  File "/opt/hostedtoolcache/Python/3.9.18/x64/lib/python3.9/site-packages/sqlalchemy/pool/base.py", line 898, in __connect
    self.dbapi_connection = connection = pool._invoke_creator(self)
  File "/opt/hostedtoolcache/Python/3.9.18/x64/lib/python3.9/site-packages/sqlalchemy/engine/create.py", line 645, in connect
    return dialect.connect(*cargs, **cparams)
  File "/opt/hostedtoolcache/Python/3.9.18/x64/lib/python3.9/site-packages/sqlalchemy/engine/default.py", line 616, in connect
    return self.loaded_dbapi.connect(*cargs, **cparams)
pyodbc.OperationalError: ('HYT00', '[HYT00] [Microsoft][ODBC Driver 18 for SQL Server]Login timeout expired (0) (SQLDriverConnect)')

The above exception was the direct cause of the following exception:

Traceback (most recent call last):
  File "/home/runner/work/spotify_daily_data_updates/spotify_daily_data_updates/main.py", line 70, in get_spotify_ids
    artist_ids = pd.read_sql(query, engine)['artist_id'].to_list()
  File "/opt/hostedtoolcache/Python/3.9.18/x64/lib/python3.9/site-packages/pandas/io/sql.py", line 652, in read_sql
    with pandasSQL_builder(con) as pandas_sql:
  File "/opt/hostedtoolcache/Python/3.9.18/x64/lib/python3.9/site-packages/pandas/io/sql.py", line 851, in pandasSQL_builder
    return SQLDatabase(con, schema, need_transaction)
  File "/opt/hostedtoolcache/Python/3.9.18/x64/lib/python3.9/site-packages/pandas/io/sql.py", line 1576, in __init__
    con = self.exit_stack.enter_context(con.connect())
  File "/opt/hostedtoolcache/Python/3.9.18/x64/lib/python3.9/site-packages/sqlalchemy/engine/base.py", line 3269, in connect
    return self._connection_cls(self)
  File "/opt/hostedtoolcache/Python/3.9.18/x64/lib/python3.9/site-packages/sqlalchemy/engine/base.py", line 147, in __init__
    Connection._handle_dbapi_exception_noconnection(
  File "/opt/hostedtoolcache/Python/3.9.18/x64/lib/python3.9/site-packages/sqlalchemy/engine/base.py", line 2431, in _handle_dbapi_exception_noconnection
    raise sqlalchemy_exception.with_traceback(exc_info[2]) from e
  File "/opt/hostedtoolcache/Python/3.9.18/x64/lib/python3.9/site-packages/sqlalchemy/engine/base.py", line 145, in __init__
    self._dbapi_connection = engine.raw_connection()
  File "/opt/hostedtoolcache/Python/3.9.18/x64/lib/python3.9/site-packages/sqlalchemy/engine/base.py", line 3293, in raw_connection
    return self.pool.connect()
  File "/opt/hostedtoolcache/Python/3.9.18/x64/lib/python3.9/site-packages/sqlalchemy/pool/base.py", line 452, in connect
    return _ConnectionFairy._checkout(self)
  File "/opt/hostedtoolcache/Python/3.9.18/x64/lib/python3.9/site-packages/sqlalchemy/pool/base.py", line 1269, in _checkout
    fairy = _ConnectionRecord.checkout(pool)
  File "/opt/hostedtoolcache/Python/3.9.18/x64/lib/python3.9/site-packages/sqlalchemy/pool/base.py", line 716, in checkout
    rec = pool._do_get()
  File "/opt/hostedtoolcache/Python/3.9.18/x64/lib/python3.9/site-packages/sqlalchemy/pool/impl.py", line 170, in _do_get
    self._dec_overflow()
  File "/opt/hostedtoolcache/Python/3.9.18/x64/lib/python3.9/site-packages/sqlalchemy/util/langhelpers.py", line 146, in __exit__
    raise exc_value.with_traceback(exc_tb)
  File "/opt/hostedtoolcache/Python/3.9.18/x64/lib/python3.9/site-packages/sqlalchemy/pool/impl.py", line 167, in _do_get
    return self._create_connection()
  File "/opt/hostedtoolcache/Python/3.9.18/x64/lib/python3.9/site-packages/sqlalchemy/pool/base.py", line 393, in _create_connection
    return _ConnectionRecord(self)
  File "/opt/hostedtoolcache/Python/3.9.18/x64/lib/python3.9/site-packages/sqlalchemy/pool/base.py", line 678, in __init__
    self.__connect()
  File "/opt/hostedtoolcache/Python/3.9.18/x64/lib/python3.9/site-packages/sqlalchemy/pool/base.py", line 903, in __connect
    pool.logger.debug("Error on connect(): %s", e)
  File "/opt/hostedtoolcache/Python/3.9.18/x64/lib/python3.9/site-packages/sqlalchemy/util/langhelpers.py", line 146, in __exit__
    raise exc_value.with_traceback(exc_tb)
  File "/opt/hostedtoolcache/Python/3.9.18/x64/lib/python3.9/site-packages/sqlalchemy/pool/base.py", line 898, in __connect
    self.dbapi_connection = connection = pool._invoke_creator(self)
  File "/opt/hostedtoolcache/Python/3.9.18/x64/lib/python3.9/site-packages/sqlalchemy/engine/create.py", line 645, in connect
    return dialect.connect(*cargs, **cparams)
  File "/opt/hostedtoolcache/Python/3.9.18/x64/lib/python3.9/site-packages/sqlalchemy/engine/default.py", line 616, in connect
    return self.loaded_dbapi.connect(*cargs, **cparams)
sqlalchemy.exc.OperationalError: (pyodbc.OperationalError) ('HYT00', '[HYT00] [Microsoft][ODBC Driver 18 for SQL Server]Login timeout expired (0) (SQLDriverConnect)')
(Background on this error at: https://sqlalche.me/e/20/e3q8)
2023-12-31 15:05:37,223 - ERROR - An exception occurred: failed to get Spotify ids (Attempt 2/2)
Traceback (most recent call last):
  File "/opt/hostedtoolcache/Python/3.9.18/x64/lib/python3.9/site-packages/sqlalchemy/engine/base.py", line 145, in __init__
    self._dbapi_connection = engine.raw_connection()
  File "/opt/hostedtoolcache/Python/3.9.18/x64/lib/python3.9/site-packages/sqlalchemy/engine/base.py", line 3293, in raw_connection
    return self.pool.connect()
  File "/opt/hostedtoolcache/Python/3.9.18/x64/lib/python3.9/site-packages/sqlalchemy/pool/base.py", line 452, in connect
    return _ConnectionFairy._checkout(self)
  File "/opt/hostedtoolcache/Python/3.9.18/x64/lib/python3.9/site-packages/sqlalchemy/pool/base.py", line 1269, in _checkout
    fairy = _ConnectionRecord.checkout(pool)
  File "/opt/hostedtoolcache/Python/3.9.18/x64/lib/python3.9/site-packages/sqlalchemy/pool/base.py", line 716, in checkout
    rec = pool._do_get()
  File "/opt/hostedtoolcache/Python/3.9.18/x64/lib/python3.9/site-packages/sqlalchemy/pool/impl.py", line 170, in _do_get
    self._dec_overflow()
  File "/opt/hostedtoolcache/Python/3.9.18/x64/lib/python3.9/site-packages/sqlalchemy/util/langhelpers.py", line 146, in __exit__
    raise exc_value.with_traceback(exc_tb)
  File "/opt/hostedtoolcache/Python/3.9.18/x64/lib/python3.9/site-packages/sqlalchemy/pool/impl.py", line 167, in _do_get
    return self._create_connection()
  File "/opt/hostedtoolcache/Python/3.9.18/x64/lib/python3.9/site-packages/sqlalchemy/pool/base.py", line 393, in _create_connection
    return _ConnectionRecord(self)
  File "/opt/hostedtoolcache/Python/3.9.18/x64/lib/python3.9/site-packages/sqlalchemy/pool/base.py", line 678, in __init__
    self.__connect()
  File "/opt/hostedtoolcache/Python/3.9.18/x64/lib/python3.9/site-packages/sqlalchemy/pool/base.py", line 903, in __connect
    pool.logger.debug("Error on connect(): %s", e)
  File "/opt/hostedtoolcache/Python/3.9.18/x64/lib/python3.9/site-packages/sqlalchemy/util/langhelpers.py", line 146, in __exit__
    raise exc_value.with_traceback(exc_tb)
  File "/opt/hostedtoolcache/Python/3.9.18/x64/lib/python3.9/site-packages/sqlalchemy/pool/base.py", line 898, in __connect
    self.dbapi_connection = connection = pool._invoke_creator(self)
  File "/opt/hostedtoolcache/Python/3.9.18/x64/lib/python3.9/site-packages/sqlalchemy/engine/create.py", line 645, in connect
    return dialect.connect(*cargs, **cparams)
  File "/opt/hostedtoolcache/Python/3.9.18/x64/lib/python3.9/site-packages/sqlalchemy/engine/default.py", line 616, in connect
    return self.loaded_dbapi.connect(*cargs, **cparams)
pyodbc.OperationalError: ('HYT00', '[HYT00] [Microsoft][ODBC Driver 18 for SQL Server]Login timeout expired (0) (SQLDriverConnect)')

The above exception was the direct cause of the following exception:

Traceback (most recent call last):
  File "/home/runner/work/spotify_daily_data_updates/spotify_daily_data_updates/main.py", line 70, in get_spotify_ids
    artist_ids = pd.read_sql(query, engine)['artist_id'].to_list()
  File "/opt/hostedtoolcache/Python/3.9.18/x64/lib/python3.9/site-packages/pandas/io/sql.py", line 652, in read_sql
    with pandasSQL_builder(con) as pandas_sql:
  File "/opt/hostedtoolcache/Python/3.9.18/x64/lib/python3.9/site-packages/pandas/io/sql.py", line 851, in pandasSQL_builder
    return SQLDatabase(con, schema, need_transaction)
  File "/opt/hostedtoolcache/Python/3.9.18/x64/lib/python3.9/site-packages/pandas/io/sql.py", line 1576, in __init__
    con = self.exit_stack.enter_context(con.connect())
  File "/opt/hostedtoolcache/Python/3.9.18/x64/lib/python3.9/site-packages/sqlalchemy/engine/base.py", line 3269, in connect
    return self._connection_cls(self)
  File "/opt/hostedtoolcache/Python/3.9.18/x64/lib/python3.9/site-packages/sqlalchemy/engine/base.py", line 147, in __init__
    Connection._handle_dbapi_exception_noconnection(
  File "/opt/hostedtoolcache/Python/3.9.18/x64/lib/python3.9/site-packages/sqlalchemy/engine/base.py", line 2431, in _handle_dbapi_exception_noconnection
    raise sqlalchemy_exception.with_traceback(exc_info[2]) from e
  File "/opt/hostedtoolcache/Python/3.9.18/x64/lib/python3.9/site-packages/sqlalchemy/engine/base.py", line 145, in __init__
    self._dbapi_connection = engine.raw_connection()
  File "/opt/hostedtoolcache/Python/3.9.18/x64/lib/python3.9/site-packages/sqlalchemy/engine/base.py", line 3293, in raw_connection
    return self.pool.connect()
  File "/opt/hostedtoolcache/Python/3.9.18/x64/lib/python3.9/site-packages/sqlalchemy/pool/base.py", line 452, in connect
    return _ConnectionFairy._checkout(self)
  File "/opt/hostedtoolcache/Python/3.9.18/x64/lib/python3.9/site-packages/sqlalchemy/pool/base.py", line 1269, in _checkout
    fairy = _ConnectionRecord.checkout(pool)
  File "/opt/hostedtoolcache/Python/3.9.18/x64/lib/python3.9/site-packages/sqlalchemy/pool/base.py", line 716, in checkout
    rec = pool._do_get()
  File "/opt/hostedtoolcache/Python/3.9.18/x64/lib/python3.9/site-packages/sqlalchemy/pool/impl.py", line 170, in _do_get
    self._dec_overflow()
  File "/opt/hostedtoolcache/Python/3.9.18/x64/lib/python3.9/site-packages/sqlalchemy/util/langhelpers.py", line 146, in __exit__
    raise exc_value.with_traceback(exc_tb)
  File "/opt/hostedtoolcache/Python/3.9.18/x64/lib/python3.9/site-packages/sqlalchemy/pool/impl.py", line 167, in _do_get
    return self._create_connection()
  File "/opt/hostedtoolcache/Python/3.9.18/x64/lib/python3.9/site-packages/sqlalchemy/pool/base.py", line 393, in _create_connection
    return _ConnectionRecord(self)
  File "/opt/hostedtoolcache/Python/3.9.18/x64/lib/python3.9/site-packages/sqlalchemy/pool/base.py", line 678, in __init__
    self.__connect()
  File "/opt/hostedtoolcache/Python/3.9.18/x64/lib/python3.9/site-packages/sqlalchemy/pool/base.py", line 903, in __connect
    pool.logger.debug("Error on connect(): %s", e)
  File "/opt/hostedtoolcache/Python/3.9.18/x64/lib/python3.9/site-packages/sqlalchemy/util/langhelpers.py", line 146, in __exit__
    raise exc_value.with_traceback(exc_tb)
  File "/opt/hostedtoolcache/Python/3.9.18/x64/lib/python3.9/site-packages/sqlalchemy/pool/base.py", line 898, in __connect
    self.dbapi_connection = connection = pool._invoke_creator(self)
  File "/opt/hostedtoolcache/Python/3.9.18/x64/lib/python3.9/site-packages/sqlalchemy/engine/create.py", line 645, in connect
    return dialect.connect(*cargs, **cparams)
  File "/opt/hostedtoolcache/Python/3.9.18/x64/lib/python3.9/site-packages/sqlalchemy/engine/default.py", line 616, in connect
    return self.loaded_dbapi.connect(*cargs, **cparams)
sqlalchemy.exc.OperationalError: (pyodbc.OperationalError) ('HYT00', '[HYT00] [Microsoft][ODBC Driver 18 for SQL Server]Login timeout expired (0) (SQLDriverConnect)')
(Background on this error at: https://sqlalche.me/e/20/e3q8)
2023-12-31 15:05:39,226 - ERROR - Failed to get Spotify ids  after 2 attempts.
2023-12-31 15:05:39,226 - ERROR - An exception occurred: Load data into DB
2023-12-31 15:12:59,890 - ERROR - An exception occurred: failed to get Spotify ids (Attempt 1/2)
Traceback (most recent call last):
  File "/opt/hostedtoolcache/Python/3.9.18/x64/lib/python3.9/site-packages/sqlalchemy/engine/base.py", line 145, in __init__
    self._dbapi_connection = engine.raw_connection()
  File "/opt/hostedtoolcache/Python/3.9.18/x64/lib/python3.9/site-packages/sqlalchemy/engine/base.py", line 3293, in raw_connection
    return self.pool.connect()
  File "/opt/hostedtoolcache/Python/3.9.18/x64/lib/python3.9/site-packages/sqlalchemy/pool/base.py", line 452, in connect
    return _ConnectionFairy._checkout(self)
  File "/opt/hostedtoolcache/Python/3.9.18/x64/lib/python3.9/site-packages/sqlalchemy/pool/base.py", line 1269, in _checkout
    fairy = _ConnectionRecord.checkout(pool)
  File "/opt/hostedtoolcache/Python/3.9.18/x64/lib/python3.9/site-packages/sqlalchemy/pool/base.py", line 716, in checkout
    rec = pool._do_get()
  File "/opt/hostedtoolcache/Python/3.9.18/x64/lib/python3.9/site-packages/sqlalchemy/pool/impl.py", line 170, in _do_get
    self._dec_overflow()
  File "/opt/hostedtoolcache/Python/3.9.18/x64/lib/python3.9/site-packages/sqlalchemy/util/langhelpers.py", line 146, in __exit__
    raise exc_value.with_traceback(exc_tb)
  File "/opt/hostedtoolcache/Python/3.9.18/x64/lib/python3.9/site-packages/sqlalchemy/pool/impl.py", line 167, in _do_get
    return self._create_connection()
  File "/opt/hostedtoolcache/Python/3.9.18/x64/lib/python3.9/site-packages/sqlalchemy/pool/base.py", line 393, in _create_connection
    return _ConnectionRecord(self)
  File "/opt/hostedtoolcache/Python/3.9.18/x64/lib/python3.9/site-packages/sqlalchemy/pool/base.py", line 678, in __init__
    self.__connect()
  File "/opt/hostedtoolcache/Python/3.9.18/x64/lib/python3.9/site-packages/sqlalchemy/pool/base.py", line 903, in __connect
    pool.logger.debug("Error on connect(): %s", e)
  File "/opt/hostedtoolcache/Python/3.9.18/x64/lib/python3.9/site-packages/sqlalchemy/util/langhelpers.py", line 146, in __exit__
    raise exc_value.with_traceback(exc_tb)
  File "/opt/hostedtoolcache/Python/3.9.18/x64/lib/python3.9/site-packages/sqlalchemy/pool/base.py", line 898, in __connect
    self.dbapi_connection = connection = pool._invoke_creator(self)
  File "/opt/hostedtoolcache/Python/3.9.18/x64/lib/python3.9/site-packages/sqlalchemy/engine/create.py", line 645, in connect
    return dialect.connect(*cargs, **cparams)
  File "/opt/hostedtoolcache/Python/3.9.18/x64/lib/python3.9/site-packages/sqlalchemy/engine/default.py", line 616, in connect
    return self.loaded_dbapi.connect(*cargs, **cparams)
pyodbc.OperationalError: ('HYT00', '[HYT00] [Microsoft][ODBC Driver 18 for SQL Server]Login timeout expired (0) (SQLDriverConnect)')

The above exception was the direct cause of the following exception:

Traceback (most recent call last):
  File "/home/runner/work/spotify_daily_data_updates/spotify_daily_data_updates/main.py", line 71, in get_spotify_ids
    artist_ids = pd.read_sql(query, engine)['artist_id'].to_list()
  File "/opt/hostedtoolcache/Python/3.9.18/x64/lib/python3.9/site-packages/pandas/io/sql.py", line 652, in read_sql
    with pandasSQL_builder(con) as pandas_sql:
  File "/opt/hostedtoolcache/Python/3.9.18/x64/lib/python3.9/site-packages/pandas/io/sql.py", line 851, in pandasSQL_builder
    return SQLDatabase(con, schema, need_transaction)
  File "/opt/hostedtoolcache/Python/3.9.18/x64/lib/python3.9/site-packages/pandas/io/sql.py", line 1576, in __init__
    con = self.exit_stack.enter_context(con.connect())
  File "/opt/hostedtoolcache/Python/3.9.18/x64/lib/python3.9/site-packages/sqlalchemy/engine/base.py", line 3269, in connect
    return self._connection_cls(self)
  File "/opt/hostedtoolcache/Python/3.9.18/x64/lib/python3.9/site-packages/sqlalchemy/engine/base.py", line 147, in __init__
    Connection._handle_dbapi_exception_noconnection(
  File "/opt/hostedtoolcache/Python/3.9.18/x64/lib/python3.9/site-packages/sqlalchemy/engine/base.py", line 2431, in _handle_dbapi_exception_noconnection
    raise sqlalchemy_exception.with_traceback(exc_info[2]) from e
  File "/opt/hostedtoolcache/Python/3.9.18/x64/lib/python3.9/site-packages/sqlalchemy/engine/base.py", line 145, in __init__
    self._dbapi_connection = engine.raw_connection()
  File "/opt/hostedtoolcache/Python/3.9.18/x64/lib/python3.9/site-packages/sqlalchemy/engine/base.py", line 3293, in raw_connection
    return self.pool.connect()
  File "/opt/hostedtoolcache/Python/3.9.18/x64/lib/python3.9/site-packages/sqlalchemy/pool/base.py", line 452, in connect
    return _ConnectionFairy._checkout(self)
  File "/opt/hostedtoolcache/Python/3.9.18/x64/lib/python3.9/site-packages/sqlalchemy/pool/base.py", line 1269, in _checkout
    fairy = _ConnectionRecord.checkout(pool)
  File "/opt/hostedtoolcache/Python/3.9.18/x64/lib/python3.9/site-packages/sqlalchemy/pool/base.py", line 716, in checkout
    rec = pool._do_get()
  File "/opt/hostedtoolcache/Python/3.9.18/x64/lib/python3.9/site-packages/sqlalchemy/pool/impl.py", line 170, in _do_get
    self._dec_overflow()
  File "/opt/hostedtoolcache/Python/3.9.18/x64/lib/python3.9/site-packages/sqlalchemy/util/langhelpers.py", line 146, in __exit__
    raise exc_value.with_traceback(exc_tb)
  File "/opt/hostedtoolcache/Python/3.9.18/x64/lib/python3.9/site-packages/sqlalchemy/pool/impl.py", line 167, in _do_get
    return self._create_connection()
  File "/opt/hostedtoolcache/Python/3.9.18/x64/lib/python3.9/site-packages/sqlalchemy/pool/base.py", line 393, in _create_connection
    return _ConnectionRecord(self)
  File "/opt/hostedtoolcache/Python/3.9.18/x64/lib/python3.9/site-packages/sqlalchemy/pool/base.py", line 678, in __init__
    self.__connect()
  File "/opt/hostedtoolcache/Python/3.9.18/x64/lib/python3.9/site-packages/sqlalchemy/pool/base.py", line 903, in __connect
    pool.logger.debug("Error on connect(): %s", e)
  File "/opt/hostedtoolcache/Python/3.9.18/x64/lib/python3.9/site-packages/sqlalchemy/util/langhelpers.py", line 146, in __exit__
    raise exc_value.with_traceback(exc_tb)
  File "/opt/hostedtoolcache/Python/3.9.18/x64/lib/python3.9/site-packages/sqlalchemy/pool/base.py", line 898, in __connect
    self.dbapi_connection = connection = pool._invoke_creator(self)
  File "/opt/hostedtoolcache/Python/3.9.18/x64/lib/python3.9/site-packages/sqlalchemy/engine/create.py", line 645, in connect
    return dialect.connect(*cargs, **cparams)
  File "/opt/hostedtoolcache/Python/3.9.18/x64/lib/python3.9/site-packages/sqlalchemy/engine/default.py", line 616, in connect
    return self.loaded_dbapi.connect(*cargs, **cparams)
sqlalchemy.exc.OperationalError: (pyodbc.OperationalError) ('HYT00', '[HYT00] [Microsoft][ODBC Driver 18 for SQL Server]Login timeout expired (0) (SQLDriverConnect)')
(Background on this error at: https://sqlalche.me/e/20/e3q8)
2023-12-31 15:13:17,011 - ERROR - An exception occurred: failed to get Spotify ids (Attempt 2/2)
Traceback (most recent call last):
  File "/opt/hostedtoolcache/Python/3.9.18/x64/lib/python3.9/site-packages/sqlalchemy/engine/base.py", line 145, in __init__
    self._dbapi_connection = engine.raw_connection()
  File "/opt/hostedtoolcache/Python/3.9.18/x64/lib/python3.9/site-packages/sqlalchemy/engine/base.py", line 3293, in raw_connection
    return self.pool.connect()
  File "/opt/hostedtoolcache/Python/3.9.18/x64/lib/python3.9/site-packages/sqlalchemy/pool/base.py", line 452, in connect
    return _ConnectionFairy._checkout(self)
  File "/opt/hostedtoolcache/Python/3.9.18/x64/lib/python3.9/site-packages/sqlalchemy/pool/base.py", line 1269, in _checkout
    fairy = _ConnectionRecord.checkout(pool)
  File "/opt/hostedtoolcache/Python/3.9.18/x64/lib/python3.9/site-packages/sqlalchemy/pool/base.py", line 716, in checkout
    rec = pool._do_get()
  File "/opt/hostedtoolcache/Python/3.9.18/x64/lib/python3.9/site-packages/sqlalchemy/pool/impl.py", line 170, in _do_get
    self._dec_overflow()
  File "/opt/hostedtoolcache/Python/3.9.18/x64/lib/python3.9/site-packages/sqlalchemy/util/langhelpers.py", line 146, in __exit__
    raise exc_value.with_traceback(exc_tb)
  File "/opt/hostedtoolcache/Python/3.9.18/x64/lib/python3.9/site-packages/sqlalchemy/pool/impl.py", line 167, in _do_get
    return self._create_connection()
  File "/opt/hostedtoolcache/Python/3.9.18/x64/lib/python3.9/site-packages/sqlalchemy/pool/base.py", line 393, in _create_connection
    return _ConnectionRecord(self)
  File "/opt/hostedtoolcache/Python/3.9.18/x64/lib/python3.9/site-packages/sqlalchemy/pool/base.py", line 678, in __init__
    self.__connect()
  File "/opt/hostedtoolcache/Python/3.9.18/x64/lib/python3.9/site-packages/sqlalchemy/pool/base.py", line 903, in __connect
    pool.logger.debug("Error on connect(): %s", e)
  File "/opt/hostedtoolcache/Python/3.9.18/x64/lib/python3.9/site-packages/sqlalchemy/util/langhelpers.py", line 146, in __exit__
    raise exc_value.with_traceback(exc_tb)
  File "/opt/hostedtoolcache/Python/3.9.18/x64/lib/python3.9/site-packages/sqlalchemy/pool/base.py", line 898, in __connect
    self.dbapi_connection = connection = pool._invoke_creator(self)
  File "/opt/hostedtoolcache/Python/3.9.18/x64/lib/python3.9/site-packages/sqlalchemy/engine/create.py", line 645, in connect
    return dialect.connect(*cargs, **cparams)
  File "/opt/hostedtoolcache/Python/3.9.18/x64/lib/python3.9/site-packages/sqlalchemy/engine/default.py", line 616, in connect
    return self.loaded_dbapi.connect(*cargs, **cparams)
pyodbc.OperationalError: ('HYT00', '[HYT00] [Microsoft][ODBC Driver 18 for SQL Server]Login timeout expired (0) (SQLDriverConnect)')

The above exception was the direct cause of the following exception:

Traceback (most recent call last):
  File "/home/runner/work/spotify_daily_data_updates/spotify_daily_data_updates/main.py", line 71, in get_spotify_ids
    artist_ids = pd.read_sql(query, engine)['artist_id'].to_list()
  File "/opt/hostedtoolcache/Python/3.9.18/x64/lib/python3.9/site-packages/pandas/io/sql.py", line 652, in read_sql
    with pandasSQL_builder(con) as pandas_sql:
  File "/opt/hostedtoolcache/Python/3.9.18/x64/lib/python3.9/site-packages/pandas/io/sql.py", line 851, in pandasSQL_builder
    return SQLDatabase(con, schema, need_transaction)
  File "/opt/hostedtoolcache/Python/3.9.18/x64/lib/python3.9/site-packages/pandas/io/sql.py", line 1576, in __init__
    con = self.exit_stack.enter_context(con.connect())
  File "/opt/hostedtoolcache/Python/3.9.18/x64/lib/python3.9/site-packages/sqlalchemy/engine/base.py", line 3269, in connect
    return self._connection_cls(self)
  File "/opt/hostedtoolcache/Python/3.9.18/x64/lib/python3.9/site-packages/sqlalchemy/engine/base.py", line 147, in __init__
    Connection._handle_dbapi_exception_noconnection(
  File "/opt/hostedtoolcache/Python/3.9.18/x64/lib/python3.9/site-packages/sqlalchemy/engine/base.py", line 2431, in _handle_dbapi_exception_noconnection
    raise sqlalchemy_exception.with_traceback(exc_info[2]) from e
  File "/opt/hostedtoolcache/Python/3.9.18/x64/lib/python3.9/site-packages/sqlalchemy/engine/base.py", line 145, in __init__
    self._dbapi_connection = engine.raw_connection()
  File "/opt/hostedtoolcache/Python/3.9.18/x64/lib/python3.9/site-packages/sqlalchemy/engine/base.py", line 3293, in raw_connection
    return self.pool.connect()
  File "/opt/hostedtoolcache/Python/3.9.18/x64/lib/python3.9/site-packages/sqlalchemy/pool/base.py", line 452, in connect
    return _ConnectionFairy._checkout(self)
  File "/opt/hostedtoolcache/Python/3.9.18/x64/lib/python3.9/site-packages/sqlalchemy/pool/base.py", line 1269, in _checkout
    fairy = _ConnectionRecord.checkout(pool)
  File "/opt/hostedtoolcache/Python/3.9.18/x64/lib/python3.9/site-packages/sqlalchemy/pool/base.py", line 716, in checkout
    rec = pool._do_get()
  File "/opt/hostedtoolcache/Python/3.9.18/x64/lib/python3.9/site-packages/sqlalchemy/pool/impl.py", line 170, in _do_get
    self._dec_overflow()
  File "/opt/hostedtoolcache/Python/3.9.18/x64/lib/python3.9/site-packages/sqlalchemy/util/langhelpers.py", line 146, in __exit__
    raise exc_value.with_traceback(exc_tb)
  File "/opt/hostedtoolcache/Python/3.9.18/x64/lib/python3.9/site-packages/sqlalchemy/pool/impl.py", line 167, in _do_get
    return self._create_connection()
  File "/opt/hostedtoolcache/Python/3.9.18/x64/lib/python3.9/site-packages/sqlalchemy/pool/base.py", line 393, in _create_connection
    return _ConnectionRecord(self)
  File "/opt/hostedtoolcache/Python/3.9.18/x64/lib/python3.9/site-packages/sqlalchemy/pool/base.py", line 678, in __init__
    self.__connect()
  File "/opt/hostedtoolcache/Python/3.9.18/x64/lib/python3.9/site-packages/sqlalchemy/pool/base.py", line 903, in __connect
    pool.logger.debug("Error on connect(): %s", e)
  File "/opt/hostedtoolcache/Python/3.9.18/x64/lib/python3.9/site-packages/sqlalchemy/util/langhelpers.py", line 146, in __exit__
    raise exc_value.with_traceback(exc_tb)
  File "/opt/hostedtoolcache/Python/3.9.18/x64/lib/python3.9/site-packages/sqlalchemy/pool/base.py", line 898, in __connect
    self.dbapi_connection = connection = pool._invoke_creator(self)
  File "/opt/hostedtoolcache/Python/3.9.18/x64/lib/python3.9/site-packages/sqlalchemy/engine/create.py", line 645, in connect
    return dialect.connect(*cargs, **cparams)
  File "/opt/hostedtoolcache/Python/3.9.18/x64/lib/python3.9/site-packages/sqlalchemy/engine/default.py", line 616, in connect
    return self.loaded_dbapi.connect(*cargs, **cparams)
sqlalchemy.exc.OperationalError: (pyodbc.OperationalError) ('HYT00', '[HYT00] [Microsoft][ODBC Driver 18 for SQL Server]Login timeout expired (0) (SQLDriverConnect)')
(Background on this error at: https://sqlalche.me/e/20/e3q8)
2023-12-31 15:13:19,013 - ERROR - Failed to get Spotify ids  after 2 attempts.
2023-12-31 15:13:19,013 - ERROR - An exception occurred: Load data into DB
2023-12-31 15:18:29,414 - ERROR - An exception occurred: failed to get Spotify ids (Attempt 1/2)
Traceback (most recent call last):
  File "/opt/hostedtoolcache/Python/3.9.18/x64/lib/python3.9/site-packages/sqlalchemy/engine/base.py", line 145, in __init__
    self._dbapi_connection = engine.raw_connection()
  File "/opt/hostedtoolcache/Python/3.9.18/x64/lib/python3.9/site-packages/sqlalchemy/engine/base.py", line 3293, in raw_connection
    return self.pool.connect()
  File "/opt/hostedtoolcache/Python/3.9.18/x64/lib/python3.9/site-packages/sqlalchemy/pool/base.py", line 452, in connect
    return _ConnectionFairy._checkout(self)
  File "/opt/hostedtoolcache/Python/3.9.18/x64/lib/python3.9/site-packages/sqlalchemy/pool/base.py", line 1269, in _checkout
    fairy = _ConnectionRecord.checkout(pool)
  File "/opt/hostedtoolcache/Python/3.9.18/x64/lib/python3.9/site-packages/sqlalchemy/pool/base.py", line 716, in checkout
    rec = pool._do_get()
  File "/opt/hostedtoolcache/Python/3.9.18/x64/lib/python3.9/site-packages/sqlalchemy/pool/impl.py", line 170, in _do_get
    self._dec_overflow()
  File "/opt/hostedtoolcache/Python/3.9.18/x64/lib/python3.9/site-packages/sqlalchemy/util/langhelpers.py", line 146, in __exit__
    raise exc_value.with_traceback(exc_tb)
  File "/opt/hostedtoolcache/Python/3.9.18/x64/lib/python3.9/site-packages/sqlalchemy/pool/impl.py", line 167, in _do_get
    return self._create_connection()
  File "/opt/hostedtoolcache/Python/3.9.18/x64/lib/python3.9/site-packages/sqlalchemy/pool/base.py", line 393, in _create_connection
    return _ConnectionRecord(self)
  File "/opt/hostedtoolcache/Python/3.9.18/x64/lib/python3.9/site-packages/sqlalchemy/pool/base.py", line 678, in __init__
    self.__connect()
  File "/opt/hostedtoolcache/Python/3.9.18/x64/lib/python3.9/site-packages/sqlalchemy/pool/base.py", line 903, in __connect
    pool.logger.debug("Error on connect(): %s", e)
  File "/opt/hostedtoolcache/Python/3.9.18/x64/lib/python3.9/site-packages/sqlalchemy/util/langhelpers.py", line 146, in __exit__
    raise exc_value.with_traceback(exc_tb)
  File "/opt/hostedtoolcache/Python/3.9.18/x64/lib/python3.9/site-packages/sqlalchemy/pool/base.py", line 898, in __connect
    self.dbapi_connection = connection = pool._invoke_creator(self)
  File "/opt/hostedtoolcache/Python/3.9.18/x64/lib/python3.9/site-packages/sqlalchemy/engine/create.py", line 645, in connect
    return dialect.connect(*cargs, **cparams)
  File "/opt/hostedtoolcache/Python/3.9.18/x64/lib/python3.9/site-packages/sqlalchemy/engine/default.py", line 616, in connect
    return self.loaded_dbapi.connect(*cargs, **cparams)
pyodbc.OperationalError: ('HYT00', '[HYT00] [Microsoft][ODBC Driver 18 for SQL Server]Login timeout expired (0) (SQLDriverConnect)')

The above exception was the direct cause of the following exception:

Traceback (most recent call last):
  File "/home/runner/work/spotify_daily_data_updates/spotify_daily_data_updates/main.py", line 69, in get_spotify_ids
    artist_ids = pd.read_sql(query, engine)['artist_id'].to_list()
  File "/opt/hostedtoolcache/Python/3.9.18/x64/lib/python3.9/site-packages/pandas/io/sql.py", line 652, in read_sql
    with pandasSQL_builder(con) as pandas_sql:
  File "/opt/hostedtoolcache/Python/3.9.18/x64/lib/python3.9/site-packages/pandas/io/sql.py", line 851, in pandasSQL_builder
    return SQLDatabase(con, schema, need_transaction)
  File "/opt/hostedtoolcache/Python/3.9.18/x64/lib/python3.9/site-packages/pandas/io/sql.py", line 1576, in __init__
    con = self.exit_stack.enter_context(con.connect())
  File "/opt/hostedtoolcache/Python/3.9.18/x64/lib/python3.9/site-packages/sqlalchemy/engine/base.py", line 3269, in connect
    return self._connection_cls(self)
  File "/opt/hostedtoolcache/Python/3.9.18/x64/lib/python3.9/site-packages/sqlalchemy/engine/base.py", line 147, in __init__
    Connection._handle_dbapi_exception_noconnection(
  File "/opt/hostedtoolcache/Python/3.9.18/x64/lib/python3.9/site-packages/sqlalchemy/engine/base.py", line 2431, in _handle_dbapi_exception_noconnection
    raise sqlalchemy_exception.with_traceback(exc_info[2]) from e
  File "/opt/hostedtoolcache/Python/3.9.18/x64/lib/python3.9/site-packages/sqlalchemy/engine/base.py", line 145, in __init__
    self._dbapi_connection = engine.raw_connection()
  File "/opt/hostedtoolcache/Python/3.9.18/x64/lib/python3.9/site-packages/sqlalchemy/engine/base.py", line 3293, in raw_connection
    return self.pool.connect()
  File "/opt/hostedtoolcache/Python/3.9.18/x64/lib/python3.9/site-packages/sqlalchemy/pool/base.py", line 452, in connect
    return _ConnectionFairy._checkout(self)
  File "/opt/hostedtoolcache/Python/3.9.18/x64/lib/python3.9/site-packages/sqlalchemy/pool/base.py", line 1269, in _checkout
    fairy = _ConnectionRecord.checkout(pool)
  File "/opt/hostedtoolcache/Python/3.9.18/x64/lib/python3.9/site-packages/sqlalchemy/pool/base.py", line 716, in checkout
    rec = pool._do_get()
  File "/opt/hostedtoolcache/Python/3.9.18/x64/lib/python3.9/site-packages/sqlalchemy/pool/impl.py", line 170, in _do_get
    self._dec_overflow()
  File "/opt/hostedtoolcache/Python/3.9.18/x64/lib/python3.9/site-packages/sqlalchemy/util/langhelpers.py", line 146, in __exit__
    raise exc_value.with_traceback(exc_tb)
  File "/opt/hostedtoolcache/Python/3.9.18/x64/lib/python3.9/site-packages/sqlalchemy/pool/impl.py", line 167, in _do_get
    return self._create_connection()
  File "/opt/hostedtoolcache/Python/3.9.18/x64/lib/python3.9/site-packages/sqlalchemy/pool/base.py", line 393, in _create_connection
    return _ConnectionRecord(self)
  File "/opt/hostedtoolcache/Python/3.9.18/x64/lib/python3.9/site-packages/sqlalchemy/pool/base.py", line 678, in __init__
    self.__connect()
  File "/opt/hostedtoolcache/Python/3.9.18/x64/lib/python3.9/site-packages/sqlalchemy/pool/base.py", line 903, in __connect
    pool.logger.debug("Error on connect(): %s", e)
  File "/opt/hostedtoolcache/Python/3.9.18/x64/lib/python3.9/site-packages/sqlalchemy/util/langhelpers.py", line 146, in __exit__
    raise exc_value.with_traceback(exc_tb)
  File "/opt/hostedtoolcache/Python/3.9.18/x64/lib/python3.9/site-packages/sqlalchemy/pool/base.py", line 898, in __connect
    self.dbapi_connection = connection = pool._invoke_creator(self)
  File "/opt/hostedtoolcache/Python/3.9.18/x64/lib/python3.9/site-packages/sqlalchemy/engine/create.py", line 645, in connect
    return dialect.connect(*cargs, **cparams)
  File "/opt/hostedtoolcache/Python/3.9.18/x64/lib/python3.9/site-packages/sqlalchemy/engine/default.py", line 616, in connect
    return self.loaded_dbapi.connect(*cargs, **cparams)
sqlalchemy.exc.OperationalError: (pyodbc.OperationalError) ('HYT00', '[HYT00] [Microsoft][ODBC Driver 18 for SQL Server]Login timeout expired (0) (SQLDriverConnect)')
(Background on this error at: https://sqlalche.me/e/20/e3q8)
2023-12-31 15:18:46,439 - ERROR - An exception occurred: failed to get Spotify ids (Attempt 2/2)
Traceback (most recent call last):
  File "/opt/hostedtoolcache/Python/3.9.18/x64/lib/python3.9/site-packages/sqlalchemy/engine/base.py", line 145, in __init__
    self._dbapi_connection = engine.raw_connection()
  File "/opt/hostedtoolcache/Python/3.9.18/x64/lib/python3.9/site-packages/sqlalchemy/engine/base.py", line 3293, in raw_connection
    return self.pool.connect()
  File "/opt/hostedtoolcache/Python/3.9.18/x64/lib/python3.9/site-packages/sqlalchemy/pool/base.py", line 452, in connect
    return _ConnectionFairy._checkout(self)
  File "/opt/hostedtoolcache/Python/3.9.18/x64/lib/python3.9/site-packages/sqlalchemy/pool/base.py", line 1269, in _checkout
    fairy = _ConnectionRecord.checkout(pool)
  File "/opt/hostedtoolcache/Python/3.9.18/x64/lib/python3.9/site-packages/sqlalchemy/pool/base.py", line 716, in checkout
    rec = pool._do_get()
  File "/opt/hostedtoolcache/Python/3.9.18/x64/lib/python3.9/site-packages/sqlalchemy/pool/impl.py", line 170, in _do_get
    self._dec_overflow()
  File "/opt/hostedtoolcache/Python/3.9.18/x64/lib/python3.9/site-packages/sqlalchemy/util/langhelpers.py", line 146, in __exit__
    raise exc_value.with_traceback(exc_tb)
  File "/opt/hostedtoolcache/Python/3.9.18/x64/lib/python3.9/site-packages/sqlalchemy/pool/impl.py", line 167, in _do_get
    return self._create_connection()
  File "/opt/hostedtoolcache/Python/3.9.18/x64/lib/python3.9/site-packages/sqlalchemy/pool/base.py", line 393, in _create_connection
    return _ConnectionRecord(self)
  File "/opt/hostedtoolcache/Python/3.9.18/x64/lib/python3.9/site-packages/sqlalchemy/pool/base.py", line 678, in __init__
    self.__connect()
  File "/opt/hostedtoolcache/Python/3.9.18/x64/lib/python3.9/site-packages/sqlalchemy/pool/base.py", line 903, in __connect
    pool.logger.debug("Error on connect(): %s", e)
  File "/opt/hostedtoolcache/Python/3.9.18/x64/lib/python3.9/site-packages/sqlalchemy/util/langhelpers.py", line 146, in __exit__
    raise exc_value.with_traceback(exc_tb)
  File "/opt/hostedtoolcache/Python/3.9.18/x64/lib/python3.9/site-packages/sqlalchemy/pool/base.py", line 898, in __connect
    self.dbapi_connection = connection = pool._invoke_creator(self)
  File "/opt/hostedtoolcache/Python/3.9.18/x64/lib/python3.9/site-packages/sqlalchemy/engine/create.py", line 645, in connect
    return dialect.connect(*cargs, **cparams)
  File "/opt/hostedtoolcache/Python/3.9.18/x64/lib/python3.9/site-packages/sqlalchemy/engine/default.py", line 616, in connect
    return self.loaded_dbapi.connect(*cargs, **cparams)
pyodbc.OperationalError: ('HYT00', '[HYT00] [Microsoft][ODBC Driver 18 for SQL Server]Login timeout expired (0) (SQLDriverConnect)')

The above exception was the direct cause of the following exception:

Traceback (most recent call last):
  File "/home/runner/work/spotify_daily_data_updates/spotify_daily_data_updates/main.py", line 69, in get_spotify_ids
    artist_ids = pd.read_sql(query, engine)['artist_id'].to_list()
  File "/opt/hostedtoolcache/Python/3.9.18/x64/lib/python3.9/site-packages/pandas/io/sql.py", line 652, in read_sql
    with pandasSQL_builder(con) as pandas_sql:
  File "/opt/hostedtoolcache/Python/3.9.18/x64/lib/python3.9/site-packages/pandas/io/sql.py", line 851, in pandasSQL_builder
    return SQLDatabase(con, schema, need_transaction)
  File "/opt/hostedtoolcache/Python/3.9.18/x64/lib/python3.9/site-packages/pandas/io/sql.py", line 1576, in __init__
    con = self.exit_stack.enter_context(con.connect())
  File "/opt/hostedtoolcache/Python/3.9.18/x64/lib/python3.9/site-packages/sqlalchemy/engine/base.py", line 3269, in connect
    return self._connection_cls(self)
  File "/opt/hostedtoolcache/Python/3.9.18/x64/lib/python3.9/site-packages/sqlalchemy/engine/base.py", line 147, in __init__
    Connection._handle_dbapi_exception_noconnection(
  File "/opt/hostedtoolcache/Python/3.9.18/x64/lib/python3.9/site-packages/sqlalchemy/engine/base.py", line 2431, in _handle_dbapi_exception_noconnection
    raise sqlalchemy_exception.with_traceback(exc_info[2]) from e
  File "/opt/hostedtoolcache/Python/3.9.18/x64/lib/python3.9/site-packages/sqlalchemy/engine/base.py", line 145, in __init__
    self._dbapi_connection = engine.raw_connection()
  File "/opt/hostedtoolcache/Python/3.9.18/x64/lib/python3.9/site-packages/sqlalchemy/engine/base.py", line 3293, in raw_connection
    return self.pool.connect()
  File "/opt/hostedtoolcache/Python/3.9.18/x64/lib/python3.9/site-packages/sqlalchemy/pool/base.py", line 452, in connect
    return _ConnectionFairy._checkout(self)
  File "/opt/hostedtoolcache/Python/3.9.18/x64/lib/python3.9/site-packages/sqlalchemy/pool/base.py", line 1269, in _checkout
    fairy = _ConnectionRecord.checkout(pool)
  File "/opt/hostedtoolcache/Python/3.9.18/x64/lib/python3.9/site-packages/sqlalchemy/pool/base.py", line 716, in checkout
    rec = pool._do_get()
  File "/opt/hostedtoolcache/Python/3.9.18/x64/lib/python3.9/site-packages/sqlalchemy/pool/impl.py", line 170, in _do_get
    self._dec_overflow()
  File "/opt/hostedtoolcache/Python/3.9.18/x64/lib/python3.9/site-packages/sqlalchemy/util/langhelpers.py", line 146, in __exit__
    raise exc_value.with_traceback(exc_tb)
  File "/opt/hostedtoolcache/Python/3.9.18/x64/lib/python3.9/site-packages/sqlalchemy/pool/impl.py", line 167, in _do_get
    return self._create_connection()
  File "/opt/hostedtoolcache/Python/3.9.18/x64/lib/python3.9/site-packages/sqlalchemy/pool/base.py", line 393, in _create_connection
    return _ConnectionRecord(self)
  File "/opt/hostedtoolcache/Python/3.9.18/x64/lib/python3.9/site-packages/sqlalchemy/pool/base.py", line 678, in __init__
    self.__connect()
  File "/opt/hostedtoolcache/Python/3.9.18/x64/lib/python3.9/site-packages/sqlalchemy/pool/base.py", line 903, in __connect
    pool.logger.debug("Error on connect(): %s", e)
  File "/opt/hostedtoolcache/Python/3.9.18/x64/lib/python3.9/site-packages/sqlalchemy/util/langhelpers.py", line 146, in __exit__
    raise exc_value.with_traceback(exc_tb)
  File "/opt/hostedtoolcache/Python/3.9.18/x64/lib/python3.9/site-packages/sqlalchemy/pool/base.py", line 898, in __connect
    self.dbapi_connection = connection = pool._invoke_creator(self)
  File "/opt/hostedtoolcache/Python/3.9.18/x64/lib/python3.9/site-packages/sqlalchemy/engine/create.py", line 645, in connect
    return dialect.connect(*cargs, **cparams)
  File "/opt/hostedtoolcache/Python/3.9.18/x64/lib/python3.9/site-packages/sqlalchemy/engine/default.py", line 616, in connect
    return self.loaded_dbapi.connect(*cargs, **cparams)
sqlalchemy.exc.OperationalError: (pyodbc.OperationalError) ('HYT00', '[HYT00] [Microsoft][ODBC Driver 18 for SQL Server]Login timeout expired (0) (SQLDriverConnect)')
(Background on this error at: https://sqlalche.me/e/20/e3q8)
2023-12-31 15:18:48,442 - ERROR - Failed to get Spotify ids  after 2 attempts.
2023-12-31 15:18:48,442 - ERROR - An exception occurred: Load data into DB
2023-12-31 15:20:57,688 - ERROR - An exception occurred: failed to get Spotify ids (Attempt 1/2)
Traceback (most recent call last):
  File "/opt/hostedtoolcache/Python/3.9.18/x64/lib/python3.9/site-packages/sqlalchemy/engine/base.py", line 145, in __init__
    self._dbapi_connection = engine.raw_connection()
  File "/opt/hostedtoolcache/Python/3.9.18/x64/lib/python3.9/site-packages/sqlalchemy/engine/base.py", line 3293, in raw_connection
    return self.pool.connect()
  File "/opt/hostedtoolcache/Python/3.9.18/x64/lib/python3.9/site-packages/sqlalchemy/pool/base.py", line 452, in connect
    return _ConnectionFairy._checkout(self)
  File "/opt/hostedtoolcache/Python/3.9.18/x64/lib/python3.9/site-packages/sqlalchemy/pool/base.py", line 1269, in _checkout
    fairy = _ConnectionRecord.checkout(pool)
  File "/opt/hostedtoolcache/Python/3.9.18/x64/lib/python3.9/site-packages/sqlalchemy/pool/base.py", line 716, in checkout
    rec = pool._do_get()
  File "/opt/hostedtoolcache/Python/3.9.18/x64/lib/python3.9/site-packages/sqlalchemy/pool/impl.py", line 170, in _do_get
    self._dec_overflow()
  File "/opt/hostedtoolcache/Python/3.9.18/x64/lib/python3.9/site-packages/sqlalchemy/util/langhelpers.py", line 146, in __exit__
    raise exc_value.with_traceback(exc_tb)
  File "/opt/hostedtoolcache/Python/3.9.18/x64/lib/python3.9/site-packages/sqlalchemy/pool/impl.py", line 167, in _do_get
    return self._create_connection()
  File "/opt/hostedtoolcache/Python/3.9.18/x64/lib/python3.9/site-packages/sqlalchemy/pool/base.py", line 393, in _create_connection
    return _ConnectionRecord(self)
  File "/opt/hostedtoolcache/Python/3.9.18/x64/lib/python3.9/site-packages/sqlalchemy/pool/base.py", line 678, in __init__
    self.__connect()
  File "/opt/hostedtoolcache/Python/3.9.18/x64/lib/python3.9/site-packages/sqlalchemy/pool/base.py", line 903, in __connect
    pool.logger.debug("Error on connect(): %s", e)
  File "/opt/hostedtoolcache/Python/3.9.18/x64/lib/python3.9/site-packages/sqlalchemy/util/langhelpers.py", line 146, in __exit__
    raise exc_value.with_traceback(exc_tb)
  File "/opt/hostedtoolcache/Python/3.9.18/x64/lib/python3.9/site-packages/sqlalchemy/pool/base.py", line 898, in __connect
    self.dbapi_connection = connection = pool._invoke_creator(self)
  File "/opt/hostedtoolcache/Python/3.9.18/x64/lib/python3.9/site-packages/sqlalchemy/engine/create.py", line 645, in connect
    return dialect.connect(*cargs, **cparams)
  File "/opt/hostedtoolcache/Python/3.9.18/x64/lib/python3.9/site-packages/sqlalchemy/engine/default.py", line 616, in connect
    return self.loaded_dbapi.connect(*cargs, **cparams)
pyodbc.OperationalError: ('HYT00', '[HYT00] [Microsoft][ODBC Driver 18 for SQL Server]Login timeout expired (0) (SQLDriverConnect)')

The above exception was the direct cause of the following exception:

Traceback (most recent call last):
  File "/home/runner/work/spotify_daily_data_updates/spotify_daily_data_updates/main.py", line 69, in get_spotify_ids
    artist_ids = pd.read_sql(query, engine)['artist_id'].to_list()
  File "/opt/hostedtoolcache/Python/3.9.18/x64/lib/python3.9/site-packages/pandas/io/sql.py", line 652, in read_sql
    with pandasSQL_builder(con) as pandas_sql:
  File "/opt/hostedtoolcache/Python/3.9.18/x64/lib/python3.9/site-packages/pandas/io/sql.py", line 851, in pandasSQL_builder
    return SQLDatabase(con, schema, need_transaction)
  File "/opt/hostedtoolcache/Python/3.9.18/x64/lib/python3.9/site-packages/pandas/io/sql.py", line 1576, in __init__
    con = self.exit_stack.enter_context(con.connect())
  File "/opt/hostedtoolcache/Python/3.9.18/x64/lib/python3.9/site-packages/sqlalchemy/engine/base.py", line 3269, in connect
    return self._connection_cls(self)
  File "/opt/hostedtoolcache/Python/3.9.18/x64/lib/python3.9/site-packages/sqlalchemy/engine/base.py", line 147, in __init__
    Connection._handle_dbapi_exception_noconnection(
  File "/opt/hostedtoolcache/Python/3.9.18/x64/lib/python3.9/site-packages/sqlalchemy/engine/base.py", line 2431, in _handle_dbapi_exception_noconnection
    raise sqlalchemy_exception.with_traceback(exc_info[2]) from e
  File "/opt/hostedtoolcache/Python/3.9.18/x64/lib/python3.9/site-packages/sqlalchemy/engine/base.py", line 145, in __init__
    self._dbapi_connection = engine.raw_connection()
  File "/opt/hostedtoolcache/Python/3.9.18/x64/lib/python3.9/site-packages/sqlalchemy/engine/base.py", line 3293, in raw_connection
    return self.pool.connect()
  File "/opt/hostedtoolcache/Python/3.9.18/x64/lib/python3.9/site-packages/sqlalchemy/pool/base.py", line 452, in connect
    return _ConnectionFairy._checkout(self)
  File "/opt/hostedtoolcache/Python/3.9.18/x64/lib/python3.9/site-packages/sqlalchemy/pool/base.py", line 1269, in _checkout
    fairy = _ConnectionRecord.checkout(pool)
  File "/opt/hostedtoolcache/Python/3.9.18/x64/lib/python3.9/site-packages/sqlalchemy/pool/base.py", line 716, in checkout
    rec = pool._do_get()
  File "/opt/hostedtoolcache/Python/3.9.18/x64/lib/python3.9/site-packages/sqlalchemy/pool/impl.py", line 170, in _do_get
    self._dec_overflow()
  File "/opt/hostedtoolcache/Python/3.9.18/x64/lib/python3.9/site-packages/sqlalchemy/util/langhelpers.py", line 146, in __exit__
    raise exc_value.with_traceback(exc_tb)
  File "/opt/hostedtoolcache/Python/3.9.18/x64/lib/python3.9/site-packages/sqlalchemy/pool/impl.py", line 167, in _do_get
    return self._create_connection()
  File "/opt/hostedtoolcache/Python/3.9.18/x64/lib/python3.9/site-packages/sqlalchemy/pool/base.py", line 393, in _create_connection
    return _ConnectionRecord(self)
  File "/opt/hostedtoolcache/Python/3.9.18/x64/lib/python3.9/site-packages/sqlalchemy/pool/base.py", line 678, in __init__
    self.__connect()
  File "/opt/hostedtoolcache/Python/3.9.18/x64/lib/python3.9/site-packages/sqlalchemy/pool/base.py", line 903, in __connect
    pool.logger.debug("Error on connect(): %s", e)
  File "/opt/hostedtoolcache/Python/3.9.18/x64/lib/python3.9/site-packages/sqlalchemy/util/langhelpers.py", line 146, in __exit__
    raise exc_value.with_traceback(exc_tb)
  File "/opt/hostedtoolcache/Python/3.9.18/x64/lib/python3.9/site-packages/sqlalchemy/pool/base.py", line 898, in __connect
    self.dbapi_connection = connection = pool._invoke_creator(self)
  File "/opt/hostedtoolcache/Python/3.9.18/x64/lib/python3.9/site-packages/sqlalchemy/engine/create.py", line 645, in connect
    return dialect.connect(*cargs, **cparams)
  File "/opt/hostedtoolcache/Python/3.9.18/x64/lib/python3.9/site-packages/sqlalchemy/engine/default.py", line 616, in connect
    return self.loaded_dbapi.connect(*cargs, **cparams)
sqlalchemy.exc.OperationalError: (pyodbc.OperationalError) ('HYT00', '[HYT00] [Microsoft][ODBC Driver 18 for SQL Server]Login timeout expired (0) (SQLDriverConnect)')
(Background on this error at: https://sqlalche.me/e/20/e3q8)
2023-12-31 15:21:15,021 - ERROR - An exception occurred: failed to get Spotify ids (Attempt 2/2)
Traceback (most recent call last):
  File "/opt/hostedtoolcache/Python/3.9.18/x64/lib/python3.9/site-packages/sqlalchemy/engine/base.py", line 145, in __init__
    self._dbapi_connection = engine.raw_connection()
  File "/opt/hostedtoolcache/Python/3.9.18/x64/lib/python3.9/site-packages/sqlalchemy/engine/base.py", line 3293, in raw_connection
    return self.pool.connect()
  File "/opt/hostedtoolcache/Python/3.9.18/x64/lib/python3.9/site-packages/sqlalchemy/pool/base.py", line 452, in connect
    return _ConnectionFairy._checkout(self)
  File "/opt/hostedtoolcache/Python/3.9.18/x64/lib/python3.9/site-packages/sqlalchemy/pool/base.py", line 1269, in _checkout
    fairy = _ConnectionRecord.checkout(pool)
  File "/opt/hostedtoolcache/Python/3.9.18/x64/lib/python3.9/site-packages/sqlalchemy/pool/base.py", line 716, in checkout
    rec = pool._do_get()
  File "/opt/hostedtoolcache/Python/3.9.18/x64/lib/python3.9/site-packages/sqlalchemy/pool/impl.py", line 170, in _do_get
    self._dec_overflow()
  File "/opt/hostedtoolcache/Python/3.9.18/x64/lib/python3.9/site-packages/sqlalchemy/util/langhelpers.py", line 146, in __exit__
    raise exc_value.with_traceback(exc_tb)
  File "/opt/hostedtoolcache/Python/3.9.18/x64/lib/python3.9/site-packages/sqlalchemy/pool/impl.py", line 167, in _do_get
    return self._create_connection()
  File "/opt/hostedtoolcache/Python/3.9.18/x64/lib/python3.9/site-packages/sqlalchemy/pool/base.py", line 393, in _create_connection
    return _ConnectionRecord(self)
  File "/opt/hostedtoolcache/Python/3.9.18/x64/lib/python3.9/site-packages/sqlalchemy/pool/base.py", line 678, in __init__
    self.__connect()
  File "/opt/hostedtoolcache/Python/3.9.18/x64/lib/python3.9/site-packages/sqlalchemy/pool/base.py", line 903, in __connect
    pool.logger.debug("Error on connect(): %s", e)
  File "/opt/hostedtoolcache/Python/3.9.18/x64/lib/python3.9/site-packages/sqlalchemy/util/langhelpers.py", line 146, in __exit__
    raise exc_value.with_traceback(exc_tb)
  File "/opt/hostedtoolcache/Python/3.9.18/x64/lib/python3.9/site-packages/sqlalchemy/pool/base.py", line 898, in __connect
    self.dbapi_connection = connection = pool._invoke_creator(self)
  File "/opt/hostedtoolcache/Python/3.9.18/x64/lib/python3.9/site-packages/sqlalchemy/engine/create.py", line 645, in connect
    return dialect.connect(*cargs, **cparams)
  File "/opt/hostedtoolcache/Python/3.9.18/x64/lib/python3.9/site-packages/sqlalchemy/engine/default.py", line 616, in connect
    return self.loaded_dbapi.connect(*cargs, **cparams)
pyodbc.OperationalError: ('HYT00', '[HYT00] [Microsoft][ODBC Driver 18 for SQL Server]Login timeout expired (0) (SQLDriverConnect)')

The above exception was the direct cause of the following exception:

Traceback (most recent call last):
  File "/home/runner/work/spotify_daily_data_updates/spotify_daily_data_updates/main.py", line 69, in get_spotify_ids
    artist_ids = pd.read_sql(query, engine)['artist_id'].to_list()
  File "/opt/hostedtoolcache/Python/3.9.18/x64/lib/python3.9/site-packages/pandas/io/sql.py", line 652, in read_sql
    with pandasSQL_builder(con) as pandas_sql:
  File "/opt/hostedtoolcache/Python/3.9.18/x64/lib/python3.9/site-packages/pandas/io/sql.py", line 851, in pandasSQL_builder
    return SQLDatabase(con, schema, need_transaction)
  File "/opt/hostedtoolcache/Python/3.9.18/x64/lib/python3.9/site-packages/pandas/io/sql.py", line 1576, in __init__
    con = self.exit_stack.enter_context(con.connect())
  File "/opt/hostedtoolcache/Python/3.9.18/x64/lib/python3.9/site-packages/sqlalchemy/engine/base.py", line 3269, in connect
    return self._connection_cls(self)
  File "/opt/hostedtoolcache/Python/3.9.18/x64/lib/python3.9/site-packages/sqlalchemy/engine/base.py", line 147, in __init__
    Connection._handle_dbapi_exception_noconnection(
  File "/opt/hostedtoolcache/Python/3.9.18/x64/lib/python3.9/site-packages/sqlalchemy/engine/base.py", line 2431, in _handle_dbapi_exception_noconnection
    raise sqlalchemy_exception.with_traceback(exc_info[2]) from e
  File "/opt/hostedtoolcache/Python/3.9.18/x64/lib/python3.9/site-packages/sqlalchemy/engine/base.py", line 145, in __init__
    self._dbapi_connection = engine.raw_connection()
  File "/opt/hostedtoolcache/Python/3.9.18/x64/lib/python3.9/site-packages/sqlalchemy/engine/base.py", line 3293, in raw_connection
    return self.pool.connect()
  File "/opt/hostedtoolcache/Python/3.9.18/x64/lib/python3.9/site-packages/sqlalchemy/pool/base.py", line 452, in connect
    return _ConnectionFairy._checkout(self)
  File "/opt/hostedtoolcache/Python/3.9.18/x64/lib/python3.9/site-packages/sqlalchemy/pool/base.py", line 1269, in _checkout
    fairy = _ConnectionRecord.checkout(pool)
  File "/opt/hostedtoolcache/Python/3.9.18/x64/lib/python3.9/site-packages/sqlalchemy/pool/base.py", line 716, in checkout
    rec = pool._do_get()
  File "/opt/hostedtoolcache/Python/3.9.18/x64/lib/python3.9/site-packages/sqlalchemy/pool/impl.py", line 170, in _do_get
    self._dec_overflow()
  File "/opt/hostedtoolcache/Python/3.9.18/x64/lib/python3.9/site-packages/sqlalchemy/util/langhelpers.py", line 146, in __exit__
    raise exc_value.with_traceback(exc_tb)
  File "/opt/hostedtoolcache/Python/3.9.18/x64/lib/python3.9/site-packages/sqlalchemy/pool/impl.py", line 167, in _do_get
    return self._create_connection()
  File "/opt/hostedtoolcache/Python/3.9.18/x64/lib/python3.9/site-packages/sqlalchemy/pool/base.py", line 393, in _create_connection
    return _ConnectionRecord(self)
  File "/opt/hostedtoolcache/Python/3.9.18/x64/lib/python3.9/site-packages/sqlalchemy/pool/base.py", line 678, in __init__
    self.__connect()
  File "/opt/hostedtoolcache/Python/3.9.18/x64/lib/python3.9/site-packages/sqlalchemy/pool/base.py", line 903, in __connect
    pool.logger.debug("Error on connect(): %s", e)
  File "/opt/hostedtoolcache/Python/3.9.18/x64/lib/python3.9/site-packages/sqlalchemy/util/langhelpers.py", line 146, in __exit__
    raise exc_value.with_traceback(exc_tb)
  File "/opt/hostedtoolcache/Python/3.9.18/x64/lib/python3.9/site-packages/sqlalchemy/pool/base.py", line 898, in __connect
    self.dbapi_connection = connection = pool._invoke_creator(self)
  File "/opt/hostedtoolcache/Python/3.9.18/x64/lib/python3.9/site-packages/sqlalchemy/engine/create.py", line 645, in connect
    return dialect.connect(*cargs, **cparams)
  File "/opt/hostedtoolcache/Python/3.9.18/x64/lib/python3.9/site-packages/sqlalchemy/engine/default.py", line 616, in connect
    return self.loaded_dbapi.connect(*cargs, **cparams)
sqlalchemy.exc.OperationalError: (pyodbc.OperationalError) ('HYT00', '[HYT00] [Microsoft][ODBC Driver 18 for SQL Server]Login timeout expired (0) (SQLDriverConnect)')
(Background on this error at: https://sqlalche.me/e/20/e3q8)
2023-12-31 15:21:17,023 - ERROR - Failed to get Spotify ids  after 2 attempts.
2023-12-31 15:21:17,023 - ERROR - An exception occurred: Load data into DB
2023-12-31 19:15:23,259 - ERROR - An exception occurred CONNETCTION FAILED
Traceback (most recent call last):
  File "/opt/hostedtoolcache/Python/3.9.18/x64/lib/python3.9/site-packages/sqlalchemy/engine/base.py", line 145, in __init__
    self._dbapi_connection = engine.raw_connection()
  File "/opt/hostedtoolcache/Python/3.9.18/x64/lib/python3.9/site-packages/sqlalchemy/engine/base.py", line 3293, in raw_connection
    return self.pool.connect()
  File "/opt/hostedtoolcache/Python/3.9.18/x64/lib/python3.9/site-packages/sqlalchemy/pool/base.py", line 452, in connect
    return _ConnectionFairy._checkout(self)
  File "/opt/hostedtoolcache/Python/3.9.18/x64/lib/python3.9/site-packages/sqlalchemy/pool/base.py", line 1269, in _checkout
    fairy = _ConnectionRecord.checkout(pool)
  File "/opt/hostedtoolcache/Python/3.9.18/x64/lib/python3.9/site-packages/sqlalchemy/pool/base.py", line 716, in checkout
    rec = pool._do_get()
  File "/opt/hostedtoolcache/Python/3.9.18/x64/lib/python3.9/site-packages/sqlalchemy/pool/impl.py", line 170, in _do_get
    self._dec_overflow()
  File "/opt/hostedtoolcache/Python/3.9.18/x64/lib/python3.9/site-packages/sqlalchemy/util/langhelpers.py", line 146, in __exit__
    raise exc_value.with_traceback(exc_tb)
  File "/opt/hostedtoolcache/Python/3.9.18/x64/lib/python3.9/site-packages/sqlalchemy/pool/impl.py", line 167, in _do_get
    return self._create_connection()
  File "/opt/hostedtoolcache/Python/3.9.18/x64/lib/python3.9/site-packages/sqlalchemy/pool/base.py", line 393, in _create_connection
    return _ConnectionRecord(self)
  File "/opt/hostedtoolcache/Python/3.9.18/x64/lib/python3.9/site-packages/sqlalchemy/pool/base.py", line 678, in __init__
    self.__connect()
  File "/opt/hostedtoolcache/Python/3.9.18/x64/lib/python3.9/site-packages/sqlalchemy/pool/base.py", line 903, in __connect
    pool.logger.debug("Error on connect(): %s", e)
  File "/opt/hostedtoolcache/Python/3.9.18/x64/lib/python3.9/site-packages/sqlalchemy/util/langhelpers.py", line 146, in __exit__
    raise exc_value.with_traceback(exc_tb)
  File "/opt/hostedtoolcache/Python/3.9.18/x64/lib/python3.9/site-packages/sqlalchemy/pool/base.py", line 898, in __connect
    self.dbapi_connection = connection = pool._invoke_creator(self)
  File "/opt/hostedtoolcache/Python/3.9.18/x64/lib/python3.9/site-packages/sqlalchemy/engine/create.py", line 645, in connect
    return dialect.connect(*cargs, **cparams)
  File "/opt/hostedtoolcache/Python/3.9.18/x64/lib/python3.9/site-packages/sqlalchemy/engine/default.py", line 616, in connect
    return self.loaded_dbapi.connect(*cargs, **cparams)
pyodbc.OperationalError: ('HYT00', '[HYT00] [Microsoft][ODBC Driver 18 for SQL Server]Login timeout expired (0) (SQLDriverConnect)')

The above exception was the direct cause of the following exception:

Traceback (most recent call last):
  File "/home/runner/work/spotify_daily_data_updates/spotify_daily_data_updates/main.py", line 125, in <module>
    artist_ids = pd.read_sql(query, engine)['artist_id'].to_list()
  File "/opt/hostedtoolcache/Python/3.9.18/x64/lib/python3.9/site-packages/pandas/io/sql.py", line 652, in read_sql
    with pandasSQL_builder(con) as pandas_sql:
  File "/opt/hostedtoolcache/Python/3.9.18/x64/lib/python3.9/site-packages/pandas/io/sql.py", line 851, in pandasSQL_builder
    return SQLDatabase(con, schema, need_transaction)
  File "/opt/hostedtoolcache/Python/3.9.18/x64/lib/python3.9/site-packages/pandas/io/sql.py", line 1576, in __init__
    con = self.exit_stack.enter_context(con.connect())
  File "/opt/hostedtoolcache/Python/3.9.18/x64/lib/python3.9/site-packages/sqlalchemy/engine/base.py", line 3269, in connect
    return self._connection_cls(self)
  File "/opt/hostedtoolcache/Python/3.9.18/x64/lib/python3.9/site-packages/sqlalchemy/engine/base.py", line 147, in __init__
    Connection._handle_dbapi_exception_noconnection(
  File "/opt/hostedtoolcache/Python/3.9.18/x64/lib/python3.9/site-packages/sqlalchemy/engine/base.py", line 2431, in _handle_dbapi_exception_noconnection
    raise sqlalchemy_exception.with_traceback(exc_info[2]) from e
  File "/opt/hostedtoolcache/Python/3.9.18/x64/lib/python3.9/site-packages/sqlalchemy/engine/base.py", line 145, in __init__
    self._dbapi_connection = engine.raw_connection()
  File "/opt/hostedtoolcache/Python/3.9.18/x64/lib/python3.9/site-packages/sqlalchemy/engine/base.py", line 3293, in raw_connection
    return self.pool.connect()
  File "/opt/hostedtoolcache/Python/3.9.18/x64/lib/python3.9/site-packages/sqlalchemy/pool/base.py", line 452, in connect
    return _ConnectionFairy._checkout(self)
  File "/opt/hostedtoolcache/Python/3.9.18/x64/lib/python3.9/site-packages/sqlalchemy/pool/base.py", line 1269, in _checkout
    fairy = _ConnectionRecord.checkout(pool)
  File "/opt/hostedtoolcache/Python/3.9.18/x64/lib/python3.9/site-packages/sqlalchemy/pool/base.py", line 716, in checkout
    rec = pool._do_get()
  File "/opt/hostedtoolcache/Python/3.9.18/x64/lib/python3.9/site-packages/sqlalchemy/pool/impl.py", line 170, in _do_get
    self._dec_overflow()
  File "/opt/hostedtoolcache/Python/3.9.18/x64/lib/python3.9/site-packages/sqlalchemy/util/langhelpers.py", line 146, in __exit__
    raise exc_value.with_traceback(exc_tb)
  File "/opt/hostedtoolcache/Python/3.9.18/x64/lib/python3.9/site-packages/sqlalchemy/pool/impl.py", line 167, in _do_get
    return self._create_connection()
  File "/opt/hostedtoolcache/Python/3.9.18/x64/lib/python3.9/site-packages/sqlalchemy/pool/base.py", line 393, in _create_connection
    return _ConnectionRecord(self)
  File "/opt/hostedtoolcache/Python/3.9.18/x64/lib/python3.9/site-packages/sqlalchemy/pool/base.py", line 678, in __init__
    self.__connect()
  File "/opt/hostedtoolcache/Python/3.9.18/x64/lib/python3.9/site-packages/sqlalchemy/pool/base.py", line 903, in __connect
    pool.logger.debug("Error on connect(): %s", e)
  File "/opt/hostedtoolcache/Python/3.9.18/x64/lib/python3.9/site-packages/sqlalchemy/util/langhelpers.py", line 146, in __exit__
    raise exc_value.with_traceback(exc_tb)
  File "/opt/hostedtoolcache/Python/3.9.18/x64/lib/python3.9/site-packages/sqlalchemy/pool/base.py", line 898, in __connect
    self.dbapi_connection = connection = pool._invoke_creator(self)
  File "/opt/hostedtoolcache/Python/3.9.18/x64/lib/python3.9/site-packages/sqlalchemy/engine/create.py", line 645, in connect
    return dialect.connect(*cargs, **cparams)
  File "/opt/hostedtoolcache/Python/3.9.18/x64/lib/python3.9/site-packages/sqlalchemy/engine/default.py", line 616, in connect
    return self.loaded_dbapi.connect(*cargs, **cparams)
sqlalchemy.exc.OperationalError: (pyodbc.OperationalError) ('HYT00', '[HYT00] [Microsoft][ODBC Driver 18 for SQL Server]Login timeout expired (0) (SQLDriverConnect)')
(Background on this error at: https://sqlalche.me/e/20/e3q8)
2024-01-01 04:10:34,229 - ERROR - An exception occurred CONNETCTION FAILED
Traceback (most recent call last):
  File "/opt/hostedtoolcache/Python/3.9.18/x64/lib/python3.9/site-packages/sqlalchemy/engine/base.py", line 145, in __init__
    self._dbapi_connection = engine.raw_connection()
  File "/opt/hostedtoolcache/Python/3.9.18/x64/lib/python3.9/site-packages/sqlalchemy/engine/base.py", line 3293, in raw_connection
    return self.pool.connect()
  File "/opt/hostedtoolcache/Python/3.9.18/x64/lib/python3.9/site-packages/sqlalchemy/pool/base.py", line 452, in connect
    return _ConnectionFairy._checkout(self)
  File "/opt/hostedtoolcache/Python/3.9.18/x64/lib/python3.9/site-packages/sqlalchemy/pool/base.py", line 1269, in _checkout
    fairy = _ConnectionRecord.checkout(pool)
  File "/opt/hostedtoolcache/Python/3.9.18/x64/lib/python3.9/site-packages/sqlalchemy/pool/base.py", line 716, in checkout
    rec = pool._do_get()
  File "/opt/hostedtoolcache/Python/3.9.18/x64/lib/python3.9/site-packages/sqlalchemy/pool/impl.py", line 170, in _do_get
    self._dec_overflow()
  File "/opt/hostedtoolcache/Python/3.9.18/x64/lib/python3.9/site-packages/sqlalchemy/util/langhelpers.py", line 146, in __exit__
    raise exc_value.with_traceback(exc_tb)
  File "/opt/hostedtoolcache/Python/3.9.18/x64/lib/python3.9/site-packages/sqlalchemy/pool/impl.py", line 167, in _do_get
    return self._create_connection()
  File "/opt/hostedtoolcache/Python/3.9.18/x64/lib/python3.9/site-packages/sqlalchemy/pool/base.py", line 393, in _create_connection
    return _ConnectionRecord(self)
  File "/opt/hostedtoolcache/Python/3.9.18/x64/lib/python3.9/site-packages/sqlalchemy/pool/base.py", line 678, in __init__
    self.__connect()
  File "/opt/hostedtoolcache/Python/3.9.18/x64/lib/python3.9/site-packages/sqlalchemy/pool/base.py", line 903, in __connect
    pool.logger.debug("Error on connect(): %s", e)
  File "/opt/hostedtoolcache/Python/3.9.18/x64/lib/python3.9/site-packages/sqlalchemy/util/langhelpers.py", line 146, in __exit__
    raise exc_value.with_traceback(exc_tb)
  File "/opt/hostedtoolcache/Python/3.9.18/x64/lib/python3.9/site-packages/sqlalchemy/pool/base.py", line 898, in __connect
    self.dbapi_connection = connection = pool._invoke_creator(self)
  File "/opt/hostedtoolcache/Python/3.9.18/x64/lib/python3.9/site-packages/sqlalchemy/engine/create.py", line 645, in connect
    return dialect.connect(*cargs, **cparams)
  File "/opt/hostedtoolcache/Python/3.9.18/x64/lib/python3.9/site-packages/sqlalchemy/engine/default.py", line 616, in connect
    return self.loaded_dbapi.connect(*cargs, **cparams)
pyodbc.OperationalError: ('HYT00', '[HYT00] [Microsoft][ODBC Driver 18 for SQL Server]Login timeout expired (0) (SQLDriverConnect)')

The above exception was the direct cause of the following exception:

Traceback (most recent call last):
  File "/home/runner/work/spotify_daily_data_updates/spotify_daily_data_updates/main.py", line 125, in <module>
    artist_ids = pd.read_sql_query(query, engine)['artist_id'].to_list()
  File "/opt/hostedtoolcache/Python/3.9.18/x64/lib/python3.9/site-packages/pandas/io/sql.py", line 485, in read_sql_query
    with pandasSQL_builder(con) as pandas_sql:
  File "/opt/hostedtoolcache/Python/3.9.18/x64/lib/python3.9/site-packages/pandas/io/sql.py", line 851, in pandasSQL_builder
    return SQLDatabase(con, schema, need_transaction)
  File "/opt/hostedtoolcache/Python/3.9.18/x64/lib/python3.9/site-packages/pandas/io/sql.py", line 1576, in __init__
    con = self.exit_stack.enter_context(con.connect())
  File "/opt/hostedtoolcache/Python/3.9.18/x64/lib/python3.9/site-packages/sqlalchemy/engine/base.py", line 3269, in connect
    return self._connection_cls(self)
  File "/opt/hostedtoolcache/Python/3.9.18/x64/lib/python3.9/site-packages/sqlalchemy/engine/base.py", line 147, in __init__
    Connection._handle_dbapi_exception_noconnection(
  File "/opt/hostedtoolcache/Python/3.9.18/x64/lib/python3.9/site-packages/sqlalchemy/engine/base.py", line 2431, in _handle_dbapi_exception_noconnection
    raise sqlalchemy_exception.with_traceback(exc_info[2]) from e
  File "/opt/hostedtoolcache/Python/3.9.18/x64/lib/python3.9/site-packages/sqlalchemy/engine/base.py", line 145, in __init__
    self._dbapi_connection = engine.raw_connection()
  File "/opt/hostedtoolcache/Python/3.9.18/x64/lib/python3.9/site-packages/sqlalchemy/engine/base.py", line 3293, in raw_connection
    return self.pool.connect()
  File "/opt/hostedtoolcache/Python/3.9.18/x64/lib/python3.9/site-packages/sqlalchemy/pool/base.py", line 452, in connect
    return _ConnectionFairy._checkout(self)
  File "/opt/hostedtoolcache/Python/3.9.18/x64/lib/python3.9/site-packages/sqlalchemy/pool/base.py", line 1269, in _checkout
    fairy = _ConnectionRecord.checkout(pool)
  File "/opt/hostedtoolcache/Python/3.9.18/x64/lib/python3.9/site-packages/sqlalchemy/pool/base.py", line 716, in checkout
    rec = pool._do_get()
  File "/opt/hostedtoolcache/Python/3.9.18/x64/lib/python3.9/site-packages/sqlalchemy/pool/impl.py", line 170, in _do_get
    self._dec_overflow()
  File "/opt/hostedtoolcache/Python/3.9.18/x64/lib/python3.9/site-packages/sqlalchemy/util/langhelpers.py", line 146, in __exit__
    raise exc_value.with_traceback(exc_tb)
  File "/opt/hostedtoolcache/Python/3.9.18/x64/lib/python3.9/site-packages/sqlalchemy/pool/impl.py", line 167, in _do_get
    return self._create_connection()
  File "/opt/hostedtoolcache/Python/3.9.18/x64/lib/python3.9/site-packages/sqlalchemy/pool/base.py", line 393, in _create_connection
    return _ConnectionRecord(self)
  File "/opt/hostedtoolcache/Python/3.9.18/x64/lib/python3.9/site-packages/sqlalchemy/pool/base.py", line 678, in __init__
    self.__connect()
  File "/opt/hostedtoolcache/Python/3.9.18/x64/lib/python3.9/site-packages/sqlalchemy/pool/base.py", line 903, in __connect
    pool.logger.debug("Error on connect(): %s", e)
  File "/opt/hostedtoolcache/Python/3.9.18/x64/lib/python3.9/site-packages/sqlalchemy/util/langhelpers.py", line 146, in __exit__
    raise exc_value.with_traceback(exc_tb)
  File "/opt/hostedtoolcache/Python/3.9.18/x64/lib/python3.9/site-packages/sqlalchemy/pool/base.py", line 898, in __connect
    self.dbapi_connection = connection = pool._invoke_creator(self)
  File "/opt/hostedtoolcache/Python/3.9.18/x64/lib/python3.9/site-packages/sqlalchemy/engine/create.py", line 645, in connect
    return dialect.connect(*cargs, **cparams)
  File "/opt/hostedtoolcache/Python/3.9.18/x64/lib/python3.9/site-packages/sqlalchemy/engine/default.py", line 616, in connect
    return self.loaded_dbapi.connect(*cargs, **cparams)
sqlalchemy.exc.OperationalError: (pyodbc.OperationalError) ('HYT00', '[HYT00] [Microsoft][ODBC Driver 18 for SQL Server]Login timeout expired (0) (SQLDriverConnect)')
(Background on this error at: https://sqlalche.me/e/20/e3q8)
2024-01-01 04:15:20,823 - ERROR - An exception occurred CONNETCTION FAILED
Traceback (most recent call last):
  File "/home/runner/work/spotify_daily_data_updates/spotify_daily_data_updates/main.py", line 127, in <module>
    engine.dispose()
NameError: name 'engine' is not defined
2024-01-01 04:17:24,948 - INFO - Code test pass
NoneType: None
2024-01-02 02:19:54,882 - ERROR - An exception occurred: connect with DB failed (Attempt 1/5)
Traceback (most recent call last):
  File "/home/runner/work/spotify_daily_data_updates/spotify_daily_data_updates/main.py", line 48, in database_connection
    conn = odbc.connect(connection_string)
NameError: name 'odbc' is not defined
2024-01-02 02:19:59,888 - ERROR - An exception occurred: connect with DB failed (Attempt 2/5)
Traceback (most recent call last):
  File "/home/runner/work/spotify_daily_data_updates/spotify_daily_data_updates/main.py", line 48, in database_connection
    conn = odbc.connect(connection_string)
NameError: name 'odbc' is not defined
2024-01-02 02:20:04,893 - ERROR - An exception occurred: connect with DB failed (Attempt 3/5)
Traceback (most recent call last):
  File "/home/runner/work/spotify_daily_data_updates/spotify_daily_data_updates/main.py", line 48, in database_connection
    conn = odbc.connect(connection_string)
NameError: name 'odbc' is not defined
2024-01-02 02:20:09,898 - ERROR - An exception occurred: connect with DB failed (Attempt 4/5)
Traceback (most recent call last):
  File "/home/runner/work/spotify_daily_data_updates/spotify_daily_data_updates/main.py", line 48, in database_connection
    conn = odbc.connect(connection_string)
NameError: name 'odbc' is not defined
2024-01-02 02:20:14,901 - ERROR - An exception occurred: connect with DB failed (Attempt 5/5)
Traceback (most recent call last):
  File "/home/runner/work/spotify_daily_data_updates/spotify_daily_data_updates/main.py", line 48, in database_connection
    conn = odbc.connect(connection_string)
NameError: name 'odbc' is not defined
2024-01-02 02:20:19,906 - ERROR - Failed to connect to the database after 5 attempts.
2024-01-02 02:20:19,922 - ERROR - An exception occurred: failed to get Spotify ids (Attempt 1/2)
Traceback (most recent call last):
  File "/home/runner/work/spotify_daily_data_updates/spotify_daily_data_updates/main.py", line 85, in get_spotify_ids
    artist_ids = pd.read_sql(query, engine)['artist_id'].to_list()
  File "/opt/hostedtoolcache/Python/3.9.18/x64/lib/python3.9/site-packages/pandas/io/sql.py", line 654, in read_sql
    return pandas_sql.read_query(
  File "/opt/hostedtoolcache/Python/3.9.18/x64/lib/python3.9/site-packages/pandas/io/sql.py", line 2326, in read_query
    cursor = self.execute(sql, params)
  File "/opt/hostedtoolcache/Python/3.9.18/x64/lib/python3.9/site-packages/pandas/io/sql.py", line 2260, in execute
    cur = self.con.cursor()
AttributeError: 'NoneType' object has no attribute 'cursor'
2024-01-02 02:20:21,925 - ERROR - An exception occurred: failed to get Spotify ids (Attempt 2/2)
Traceback (most recent call last):
  File "/home/runner/work/spotify_daily_data_updates/spotify_daily_data_updates/main.py", line 85, in get_spotify_ids
    artist_ids = pd.read_sql(query, engine)['artist_id'].to_list()
  File "/opt/hostedtoolcache/Python/3.9.18/x64/lib/python3.9/site-packages/pandas/io/sql.py", line 654, in read_sql
    return pandas_sql.read_query(
  File "/opt/hostedtoolcache/Python/3.9.18/x64/lib/python3.9/site-packages/pandas/io/sql.py", line 2326, in read_query
    cursor = self.execute(sql, params)
  File "/opt/hostedtoolcache/Python/3.9.18/x64/lib/python3.9/site-packages/pandas/io/sql.py", line 2260, in execute
    cur = self.con.cursor()
AttributeError: 'NoneType' object has no attribute 'cursor'
2024-01-02 02:20:23,927 - ERROR - Failed to get Spotify ids  after 2 attempts.
